Workbook
Name age: Model!$I$3:$N$3
Name CR: Model!$B$5
Name Ehalf: Model!#REF!
Name Eo: Model!$B$10
Name EPRhist: Model!$B$20
Name EPRo: Model!$B$3
Name fanom: Model!$AS$14:$AS$54
Name fec: Model!$I$7:$N$7
Name Ffuture: Model!$B$21
Name Fhist: Model!$B$19
Name Ftest: Model!$B$13
Name HistS: Model!$E$7
Name Lhist: Model!$I$10:$N$10
Name LHT: Model!$E$9
Name Lo: Model!$I$8:$N$8
Name mat: Model!$I$6:$N$6
Name Mden: Model!$B$11
Name MeMin: Model!$B$6
Name MeUnf: Model!$B$4
Name Mhatch: Model!$B$23
Name Mo: Model!$I$4:$N$4
Name Mobase: Model!#REF!
Name Mseal: Model!$B$22
Name MSSLNRKWq: Model!$B$25
Name Mtemp: Model!$B$24
Name Ninit: Model!#REF!
Name RelmYr: Model!$O$14:$O$55
Name RetroF: Model!$E$3
Name Rhist: Model!$F$13
Name RhistSobs: Model!$F$12
Name Rinit: Model!$B$14
Name Ro: Model!$B$9
Name Smolt0: Model!$B$8
Name So: Model!$B$8
Name Sosearch: Model!$E$8
Name SPRhist: Model!$I$9:$N$9
Name SPRo: Model!$B$7
Name Ssfanom: Model!$B$47
Name Ssrecanom: Model!$B$46
Name Ssspawn: Model!$B$45
Name Sstotal: Model!$B$51
Name Ssum: Model!$B$12
Name stockcode: Model!$B$27
Name UseRetro: Model!$E$2
Name varanom: Model!$B$49
Name varfanom: Model!$B$50
Name varlnS: Model!$B$48
Name vul: Model!$I$5:$N$5
Name YPR: Model!$B$28

Sheet Model
A1: MODEL PARAMETER AND STATISTICAL ESTIMATION COLUMNS | H1: AGE STRUCTURE ACCOUNTING COLUMNS: RECRUITMENT AND SURVIVAL | P1: RECRUITMENT ANOMALY AND AGE MORTALITY COLUMNS | Z1: PREDICTED SPAWNERS AT AGE COLUMNS | AE1: PREDICTEED CATCH AT AGE COLUMNS | AM1: MORTALITY COVARIATE COLUMNS | AR1: SPAWNER DATA | AW1: PREDICTION OF CODED WIRE TAG POPULATION, ESCAPEMENT, AND CATCHES AT AGE | BM1: Predicted recaptures organized across columns by number of years after release, for release year on the row
A2: Basic derived population parameters | D2: UseRetro | E2: FALSE | F2: retroyield | G2: =SUM(AE14:AI58) -> 1056343.9 | H2: yr after spawning | I2: 1 | J2: 2 | K2: 3 | L2: 4 | M2: 5 | N2: 6 | P2: mean mortality anomaly | S2: =AVERAGE(P14:P51) -> -0.029905259 | AM2: (see "stressors" tab)
A3: EPRo | B3: =SUMPRODUCT(Lo,fec,mat)*Ssum -> 35.635156 | C3: unfished eggs per smolt | D3: RetroF | E3: 0.3 | H3: Ocean age | I3: 0 | J3: 1 | K3: 2 | L3: 3 | M3: 4 | N3: 5 | BA3: t+1 | BB3: t+2 | BC3: t+3 | BD3: t+4 | BE3: t+5
A4: MeUnf | B4: =-LN(1/EPRo) -> 3.5733327 | C4: Unfished egg-smolt mortality rate | D4: unfished egg-smolt survival | H4: Mo | I4: 2.8 | J4: 0.3 | K4: 0.3 | L4: 0.3 | M4: 0.3 | N4: 0.3 | P4: baseline mortality rates at age | AZ4: mean esc | BA4: =AVERAGE(BA19:BA54) -> 39.351222 | BB4: =AVERAGE(BB19:BB54) -> 44.644335 | BC4: =AVERAGE(BC19:BC54) -> 86.18088 | BD4: =AVERAGE(BD19:BD54) -> 2.9057471 | BE4: =AVERAGE(BE19:BE54) -> 0.017844508
A5: ln(CR) | B5: 1.0426336 | C5: Ricker a (decrease in egg-smolt M at low spawner densities) | F5: =EXP(CR) -> 2.836678 | H5: vul | I5: 0 | J5: 0.1 | K5: 1 | L5: 1 | M5: 1 | N5: 1 | O5: need to estimate from CWT data | AZ5: Catch 85-93 | BA5: =AVERAGE(BF19:BF27) -> 17.97209 | BB5: =AVERAGE(BG19:BG54) -> 69.356074 | BC5: =AVERAGE(BH19:BH54) -> 31.605445 | BD5: =AVERAGE(BI19:BI54) -> 0.99175214 | BE5: =AVERAGE(BJ19:BJ54) -> 0.0058741778
A6: MeMin | B6: =MeUnf-CR -> 2.530699 | C6: Minimum egg-smolt mortality low pop | D6: maximum egg-smolt surv | E6: =EXP(-MeMin) -> 0.079603355 | H6: mat | I6: 0 | J6: 0.11 | K6: 0.23 | L6: 0.947 | M6: 0.99 | N6: 1 | O6: need to estimate from CWT data | AZ6: Catch 2000-2020 | BA6: =AVERAGE(BF34:BF54) -> 8.5170682 | BB6: =AVERAGE(BG34:BG54) -> 51.901801 | BC6: =AVERAGE(BH34:BH54) -> 25.514444 | BD6: =AVERAGE(BI34:BI54) -> 0.85975434 | BE6: =AVERAGE(BJ34:BJ54) -> 0.0054400508
A7: SPRo | B7: =SUMPRODUCT(Lo,mat)*Ssum -> 0.023078932 | C7: Unfished spawners per smolt | D7: hisorical Sbar | E7: =AVERAGE(AR14:AR59)/10000 -> 3.1215195 | F7: 10000's | H7: fec | I7: 0 | J7: 0 | K7: 1500 | L7: 2000 | M7: 2500 | N7: 3000 | O7: mean fecundity at age | AN7: 1. seal N from age model fit to Olesiuk seal data
A8: So | B8: =10000*E8 -> 41847.116 | C8: Unfished total spawners | D8: Sosearch | E8: 4.1847116 | H8: Lo | I8: 1 | J8: =I8*EXP(-I4)*(1-I6) -> 0.060810063 | K8: =J8*EXP(-J4)*(1-J6) -> 0.04009379 | L8: =K8*EXP(-K4)*(1-K6) -> 0.022870702 | M8: =L8*EXP(-L4)*(1-L6) -> 0.00089798073 | N8: =M8*EXP(-M4)*(1-M6) -> 6.6524049e-06 | O8: derived survivorship to age | AN8: 2. SOG hatchery releases from DFO
A9: Ro | B9: =B8/SPRo -> 1813217.2 | C9: Unfished smolts | D9: LHT | E9: 2 | F9: freshwater type | H9: SPRhist | I9: =I10*EXP(-I5*Fhist)*I6*Ssum -> 0 | J9: =J10*EXP(-J5*Fhist)*J6*Ssum -> 0.0038948483 | K9: =K10*EXP(-K5*Fhist)*K6*Ssum -> 0.0039777641 | L9: =L10*EXP(-L5*Fhist)*L6*Ssum -> 0.0069211012 | M9: =M10*EXP(-M5*Fhist)*M6*Ssum -> 0.00021045517 | N9: =N10*EXP(-N5*Fhist)*N6*Ssum -> 1.1666691e-06 | O9: historical base spawners per smolt | AN9: 3. Sea surface temperature from Chrome, Entrance DFO data
A10: Eo | B10: =Ro*EPRo -> 64614277 | C10: Unfished annual egg production | F10: 2=x.2 type | H10: Lhist | I10: 1 | J10: =I10*EXP(-I4-I5*Fhist)*(1-I6) -> 0.060810063 | K10: =J10*EXP(-J4-J5*Fhist)*(1-J6) -> 0.03890884 | L10: =K10*EXP(-K4-K5*Fhist)*(1-K6) -> 0.01644229 | M10: =L10*EXP(-L4-L5*Fhist)*(1-L6) -> 0.00047825718 | N10: =M10*EXP(-M4-M5*Fhist)*(1-M6) -> 2.624731e-06
A11: Mden | B11: =(MeUnf-MeMin)/Eo -> 1.6136273e-08 | C11: Ricker model "b" (density) parameter | H11: Harrison mat | I11: 0 | J11: 0.11 | K11: 0.23 | L11: 0.947 | M11: 1 | N11: 1 | AU11: Prediction of coded wire tagged fish alive at age over time and predicted escapements and catches of those tagged fish
A12: Ssum | B12: 0.6 | C12: Summer survival from June-spawning time | E12: RhistSobs | F12: =AR14/SUM(SPRhist) -> 1207841.4 | I12: late spring/early summer Numbers at year,age | Q12: total mortality rates by life stage-age | Y12: fishing rate | AA12: Predicted spawners at age | AF12: Predicted catches at age | AM12: PSC U | AN12: Mortality covariates | AV12: Predicted tags alive | BA12: Predicted escapement tags at age | BF12: Predicted tag catches at age | BN12: Predicted recaptures in catch by year after release | BS12: Predicted recapture in escapement by years after release | BX12: VPA check using model predictions
A13: Ftest | B13: 0.3 | C13: Test Fishing mortality rate, fully vulnerable ages | E13: Rhist | F13: =(LN(EPRhist)-MeMin)/(Mden*EPRhist) -> 1468112.3 | G13: Year | H13: Eggs | I13: Age 0 (smolt)N | J13: age 1 N | K13: age 2 N | L13: age 3 N | M13: age 4 N | N13: age 5 N | O13: RelmYr | P13: Ricker anomaly | Q13: M egg-smolt | R13: M0 | S13: M1 | T13: M2 | U13: M3 | V13: M4 | W13: M5 | X13: BY M | Y13: F | Z13: S age 1 | AA13: S age 2 | AB13: S age 3 | AC13: S age 4 | AD13: S age 5 | AE13: C age 1 | AF13: C age 2 | AG13: C age 3 | AH13: C age 4 | AI13: C age 5 | AJ13: Year | AK13: Catch | AL13: Spawners | AM13: C/(C+E) | AN13: seal N | AO13: hatchery rel | AP13: Temperature | AQ13: QSSL+NRKW | AR13: Obs Spawn | AS13: Fanom | AT13: Rel yr | AU13: Tot Releases | AV13: N1 | AW13: N2 | AX13: N3 | AY13: N4 | AZ13: N5 | BA13: S 1 | BB13: S 2 | BC13: S 3 | BD13: S 4 | BE13: S 5 | BF13: C 1 | BG13: C 2 | BH13: C 3 | BI13: C 4 | BJ13: C 5 | BK13: BY | BL13: Pred BYER | BM13: Release yr | BN13: C t+1 | BO13: C t+2 | BP13: C t+3 | BQ13: C t+4 | BR13: C t+5 | BS13: E t+1 | BT13: E t+2 | BU13: E t+3 | BV13: E t+4 | BW13: E t+5 | BX13: N1 | BY13: N2 | BZ13: N3 | CA13: N4 | CB13: N5 | CC13: MSR
A14: Rinit | B14: 0.3 | C14: first year ratio of recruitment to Ro | E14: Rhist/Ro | F14: =MAX(0,F13/Ro) -> 0.80967264 | G14: 1979 | H14: =EPRhist*I14 -> 24565666 | I14: =RhistSobs*I10 -> 1207841.4 | J14: =RhistSobs*J10 -> 73448.913 | K14: =RhistSobs*K10 -> 46995.708 | L14: =RhistSobs*L10 -> 19859.679 | M14: =RhistSobs*M10 -> 577.65883 | N14: =RhistSobs*N10 -> 3.1702589 | O14: 0.97066113 | P14: =O14-1 -> -0.029338868 | Q14: =MeMin+Mden*H14+P14 -> 2.8977585 | R14: =I$4+Mseal*AN14/40+Mhatch*AO14/30+Mtemp*(AP14-14.5) -> 2.8 | S14: =J$4 -> 0.3 | T14: =K$4+MSSLNRKWq*AQ14 -> 0.3 | U14: =L$4+MSSLNRKWq*AQ14 -> 0.3 | V14: =M$4 -> 0.3 | W14: =N$4 -> 0.3 | X14: =Q14+R15+S16+T17+U18+V19 -> 6.8977585 | Y14: =Fhist -> 0.3 | Z14: =Ssum*J14*EXP(-J$5*$Y14)*J$6 -> 4704.3592 | AA14: =Ssum*K14*EXP(-K$5*$Y14)*K$6 -> 4804.5082 | AB14: =Ssum*L14*EXP(-L$5*$Y14)*L$6 -> 8359.5927 | AC14: =Ssum*M14*EXP(-M$5*$Y14)*M$6 -> 254.19647 | AD14: =Ssum*N14*EXP(-N$5*$Y14)*N$6 -> 1.4091513 | AE14: =(1-EXP(-J$5*$Y14))*J14 -> 2170.7434 | AF14: =(1-EXP(-K$5*$Y14))*K14 -> 12180.431 | AG14: =(1-EXP(-L$5*$Y14))*L14 -> 5147.2671 | AH14: =(1-EXP(-M$5*$Y14))*M14 -> 149.71864 | AI14: =(1-EXP(-N$5*$Y14))*N14 -> 0.82167333 | AJ14: =G14 -> 1979 | AK14: =SUM(AE14:AI14) -> 19648.982 | AL14: =SUM(Z14:AD14) -> 18124.066 | AM14: =AK14/(AK14+AL14) -> 0.52018524 | AN14: 7.4626219 | AO14: 6.93055 | AP14: 14.487 | AQ14: =stressors!U9/stressors!U$49 -> 0.28238272 | AR14: =CHOOSE(stockcode,Esc!F29,Esc!G29,Esc!H29,Esc!I29,Esc!J29,Esc!K29,Esc!L29,Esc!M29,Esc!N28,Esc!O28,Esc!P28) -> 18124.066 | AS14: 0 | AT14: =AJ14 -> 1979 | AU14: 10000 | AW14: 0 | AX14: 0 | AY14: 0 | AZ14: 0 | BA14: =AV14*Z14/J14 -> 0 | BB14: =AW14*AA14/K14 -> 0 | BC14: =AX14*AB14/L14 -> 0 | BD14: =AY14*AC14/M14 -> 0 | BE14: =AZ14*AD14/N14 -> 0 | BF14: =AV14*AE14/J14 -> 0 | BG14: =AW14*AF14/K14 -> 0 | BH14: =AX14*AG14/L14 -> 0 | BI14: =AY14*AH14/M14 -> 0 | BJ14: =AZ14*AI14/N14 -> 0 | BK14: =AT14-2 -> 1977 | BL14: =(AE14+AF15+AG16+AH17+AI18)/(AE14+AF15+AG16+AH17+AI18+Z14+AA15+AB16+AC17+AD18) -> 0.52018524 | BM14: =AT14 -> 1979 | BN14: =BF15 -> 17.97209 | BO14: =BG16 -> 100.84462 | BP14: =BH17 -> 42.615421 | BQ14: =BI18 -> 1.2395555 | BR14: =BJ19 -> 0.0068028246 | BS14: =BA15 -> 38.948483 | BT14: =BB16 -> 39.777641 | BU14: =BC17 -> 69.211012 | BV14: =BD18 -> 2.1045517 | BW14: =BE19 -> 0.011666691 | BX14: =BY14*EXP(J$4)+BN14+BS14/Ssum -> 608.10063 | BY14: =BZ14*EXP(K$4)+BO14+BT14/Ssum -> 389.0884 | BZ14: =CA14*EXP(L$4)+BP14+BU14/Ssum -> 164.4229 | CA14: =CB14*EXP(M$4)+BQ14+BV14/Ssum -> 4.7825718 | CB14: =BR14+BW14/Ssum -> 0.02624731 | CC14: =BX14/AU14 -> 0.060810063
A15: MSR | B15: =So/Ro -> 0.023078932 | C15: calculated marine survival rate (also SPRo) | G15: 1980 | H15: =SUMPRODUCT(J$7:N$7,Z15:AD15) -> 24565666 | I15: =H14*EXP(-Q14) -> 1354715.3 | J15: =I14*EXP(-R14-I$5*$Y14)*(1-I$6) -> 73448.913 | K15: =J14*EXP(-S14-J$5*$Y14)*(1-J$6) -> 46995.708 | L15: =K14*EXP(-T14-K$5*$Y14)*(1-K$6) -> 19859.679 | M15: =L14*EXP(-U14-L$5*$Y14)*(1-L$6) -> 577.65883 | N15: =M14*EXP(-V14-M$5*$Y14)*(1-M$6) -> 3.1702589 | O15: 0.13494288 | P15: =O15-1 -> -0.86505712 | Q15: =MeMin+Mden*H15+P15 -> 2.0620402 | R15: =I$4+Mseal*AN15/40+Mhatch*AO15/30+Mtemp*(AP15-14.5) -> 2.8 | S15: =J$4 -> 0.3 | T15: =K$4+MSSLNRKWq*AQ15 -> 0.3 | U15: =L$4+MSSLNRKWq*AQ15 -> 0.3 | V15: =M$4 -> 0.3 | W15: =N$4 -> 0.3 | X15: =Q15+R16+S17+T18+U19+V20 -> 6.0620402 | Y15: =IF(UseRetro,RetroF,Ftest*ER!$D22+AS15) -> 0.3 | Z15: =Ssum*J15*EXP(-J$5*$Y15)*J$6 -> 4704.3592 | AA15: =Ssum*K15*EXP(-K$5*$Y15)*K$6 -> 4804.5082 | AB15: =Ssum*L15*EXP(-L$5*$Y15)*L$6 -> 8359.5927 | AC15: =Ssum*M15*EXP(-M$5*$Y15)*M$6 -> 254.19647 | AD15: =Ssum*N15*EXP(-N$5*$Y15)*N$6 -> 1.4091513 | AE15: =(1-EXP(-J$5*$Y15))*J15 -> 2170.7434 | AF15: =(1-EXP(-K$5*$Y15))*K15 -> 12180.431 | AG15: =(1-EXP(-L$5*$Y15))*L15 -> 5147.2671 | AH15: =(1-EXP(-M$5*$Y15))*M15 -> 149.71864 | AI15: =(1-EXP(-N$5*$Y15))*N15 -> 0.82167333 | AJ15: =G15 -> 1980 | AK15: =SUM(AE15:AI15) -> 19648.982 | AL15: =SUM(Z15:AD15) -> 18124.066 | AM15: =AK15/(AK15+AL15) -> 0.52018524 | AN15: 8.6430824 | AO15: 8.749515 | AP15: 14.675 | AQ15: =stressors!U10/stressors!U$49 -> 0.28598083 | AR15: =CHOOSE(stockcode,Esc!F30,Esc!G30,Esc!H30,Esc!I30,Esc!J30,Esc!K30,Esc!L30,Esc!M30,Esc!N29,Esc!O29,Esc!P29) -> 19514.502 | AS15: 0 | AT15: =AJ15 -> 1980 | AU15: 10000 | AV15: =AU14*J15/I14 -> 608.10063 | AW15: =AV14*K15/J14 -> 0 | AX15: =AW14*L15/K14 -> 0 | AY15: =AX14*M15/L14 -> 0 | AZ15: =AY14*N15/M14 -> 0 | BA15: =AV15*Z15/J15 -> 38.948483 | BB15: =AW15*AA15/K15 -> 0 | BC15: =AX15*AB15/L15 -> 0 | BD15: =AY15*AC15/M15 -> 0 | BE15: =AZ15*AD15/N15 -> 0 | BF15: =AV15*AE15/J15 -> 17.97209 | BG15: =AW15*AF15/K15 -> 0 | BH15: =AX15*AG15/L15 -> 0 | BI15: =AY15*AH15/M15 -> 0 | BJ15: =AZ15*AI15/N15 -> 0 | BK15: =AT15-2 -> 1978 | BL15: =(AE15+AF16+AG17+AH18+AI19)/(AE15+AF16+AG17+AH18+AI19+Z15+AA16+AB17+AC18+AD19) -> 0.52018524 | BM15: =AT15 -> 1980 | BN15: =BF16 -> 17.97209 | BO15: =BG17 -> 100.84462 | BP15: =BH18 -> 42.615421 | BQ15: =BI19 -> 1.2395555 | BR15: =BJ20 -> 0.0068028246 | BS15: =BA16 -> 38.948483 | BT15: =BB17 -> 39.777641 | BU15: =BC18 -> 69.211012 | BV15: =BD19 -> 2.1045517 | BW15: =BE20 -> 0.011666691 | BX15: =BY15*EXP(J$4)+BN15+BS15/Ssum -> 608.10063 | BY15: =BZ15*EXP(K$4)+BO15+BT15/Ssum -> 389.0884 | BZ15: =CA15*EXP(L$4)+BP15+BU15/Ssum -> 164.4229 | CA15: =CB15*EXP(M$4)+BQ15+BV15/Ssum -> 4.7825718 | CB15: =BR15+BW15/Ssum -> 0.02624731 | CC15: =BX15/AU15 -> 0.060810063
A16: unfished M | B16: =MeUnf+SUM(Mo) -> 7.8733327 | C16: Unfished lifecycle total M | G16: 1981 | H16: =SUMPRODUCT(J$7:N$7,Z16:AD16) -> 24565666 | I16: =IF(LHT=1,H15*EXP(-Q15),H14*EXP(-Q14)) -> 1354715.3 | J16: =I15*EXP(-R15-I$5*$Y15)*(1-I$6) -> 82380.322 | K16: =J15*EXP(-S15-J$5*$Y15)*(1-J$6) -> 46995.708 | L16: =K15*EXP(-T15-K$5*$Y15)*(1-K$6) -> 19859.679 | M16: =L15*EXP(-U15-L$5*$Y15)*(1-L$6) -> 577.65883 | N16: =M15*EXP(-V15-M$5*$Y15)*(1-M$6) -> 3.1702589 | O16: 0.16571233 | P16: =O16-1 -> -0.83428767 | Q16: =MeMin+Mden*H16+P16 -> 2.0928097 | R16: =I$4+Mseal*AN16/40+Mhatch*AO16/30+Mtemp*(AP16-14.5) -> 2.8 | S16: =J$4 -> 0.3 | T16: =K$4+MSSLNRKWq*AQ16 -> 0.3 | U16: =L$4+MSSLNRKWq*AQ16 -> 0.3 | V16: =M$4 -> 0.3 | W16: =N$4 -> 0.3 | X16: =Q16+R17+S18+T19+U20+V21 -> 6.0928097 | Y16: =IF(UseRetro,RetroF,Ftest*ER!$D23+AS16) -> 0.3 | Z16: =Ssum*J16*EXP(-J$5*$Y16)*J$6 -> 5276.4106 | AA16: =Ssum*K16*EXP(-K$5*$Y16)*K$6 -> 4804.5082 | AB16: =Ssum*L16*EXP(-L$5*$Y16)*L$6 -> 8359.5927 | AC16: =Ssum*M16*EXP(-M$5*$Y16)*M$6 -> 254.19647 | AD16: =Ssum*N16*EXP(-N$5*$Y16)*N$6 -> 1.4091513 | AE16: =(1-EXP(-J$5*$Y16))*J16 -> 2434.7065 | AF16: =(1-EXP(-K$5*$Y16))*K16 -> 12180.431 | AG16: =(1-EXP(-L$5*$Y16))*L16 -> 5147.2671 | AH16: =(1-EXP(-M$5*$Y16))*M16 -> 149.71864 | AI16: =(1-EXP(-N$5*$Y16))*N16 -> 0.82167333 | AJ16: =G16 -> 1981 | AK16: =SUM(AE16:AI16) -> 19912.945 | AL16: =SUM(Z16:AD16) -> 18696.117 | AM16: =AK16/(AK16+AL16) -> 0.51575832 | AN16: 9.9811619 | AO16: 7.274729 | AP16: 15.689 | AQ16: =stressors!U11/stressors!U$49 -> 0.28832188 | AR16: =CHOOSE(stockcode,Esc!F31,Esc!G31,Esc!H31,Esc!I31,Esc!J31,Esc!K31,Esc!L31,Esc!M31,Esc!N30,Esc!O30,Esc!P30) -> 14214.614 | AS16: 0 | AT16: =AJ16 -> 1981 | AU16: 10000 | AV16: =AU15*J16/I15 -> 608.10063 | AW16: =AV15*K16/J15 -> 389.0884 | AX16: =AW15*L16/K15 -> 0 | AY16: =AX15*M16/L15 -> 0 | AZ16: =AY15*N16/M15 -> 0 | BA16: =AV16*Z16/J16 -> 38.948483 | BB16: =AW16*AA16/K16 -> 39.777641 | BC16: =AX16*AB16/L16 -> 0 | BD16: =AY16*AC16/M16 -> 0 | BE16: =AZ16*AD16/N16 -> 0 | BF16: =AV16*AE16/J16 -> 17.97209 | BG16: =AW16*AF16/K16 -> 100.84462 | BH16: =AX16*AG16/L16 -> 0 | BI16: =AY16*AH16/M16 -> 0 | BJ16: =AZ16*AI16/N16 -> 0 | BK16: =AT16-2 -> 1979 | BL16: =(AE16+AF17+AG18+AH19+AI20)/(AE16+AF17+AG18+AH19+AI20+Z16+AA17+AB18+AC19+AD20) -> 0.52018524 | BM16: =AT16 -> 1981 | BN16: =BF17 -> 17.97209 | BO16: =BG18 -> 100.84462 | BP16: =BH19 -> 42.615421 | BQ16: =BI20 -> 1.2395555 | BR16: =BJ21 -> 0.0068028246 | BS16: =BA17 -> 38.948483 | BT16: =BB18 -> 39.777641 | BU16: =BC19 -> 69.211012 | BV16: =BD20 -> 2.1045517 | BW16: =BE21 -> 0.011666691 | BX16: =BY16*EXP(J$4)+BN16+BS16/Ssum -> 608.10063 | BY16: =BZ16*EXP(K$4)+BO16+BT16/Ssum -> 389.0884 | BZ16: =CA16*EXP(L$4)+BP16+BU16/Ssum -> 164.4229 | CA16: =CB16*EXP(M$4)+BQ16+BV16/Ssum -> 4.7825718 | CB16: =BR16+BW16/Ssum -> 0.02624731 | CC16: =BX16/AU16 -> 0.060810063
A17: exp unf. M | B17: =-LN(1/2000) -> 7.6009025 | C17: Expected lifecycle M to replace a spawner | G17: 1982 | H17: =SUMPRODUCT(J$7:N$7,Z17:AD17) -> 25442011 | I17: =IF(LHT=1,H16*EXP(-Q16),H15*EXP(-Q15)) -> 3124610.3 | J17: =I16*EXP(-R16-I$5*$Y16)*(1-I$6) -> 82380.322 | K17: =J16*EXP(-S16-J$5*$Y16)*(1-J$6) -> 52710.4 | L17: =K16*EXP(-T16-K$5*$Y16)*(1-K$6) -> 19859.679 | M17: =L16*EXP(-U16-L$5*$Y16)*(1-L$6) -> 577.65883 | N17: =M16*EXP(-V16-M$5*$Y16)*(1-M$6) -> 3.1702589 | O17: -0.1844188 | P17: =O17-1 -> -1.1844188 | Q17: =MeMin+Mden*H17+P17 -> 1.7568195 | R17: =I$4+Mseal*AN17/40+Mhatch*AO17/30+Mtemp*(AP17-14.5) -> 2.8 | S17: =J$4 -> 0.3 | T17: =K$4+MSSLNRKWq*AQ17 -> 0.3 | U17: =L$4+MSSLNRKWq*AQ17 -> 0.3 | V17: =M$4 -> 0.3 | W17: =N$4 -> 0.3 | X17: =Q17+R18+S19+T20+U21+V22 -> 5.7568195 | Y17: =IF(UseRetro,RetroF,Ftest*ER!$D24+AS17) -> 0.3 | Z17: =Ssum*J17*EXP(-J$5*$Y17)*J$6 -> 5276.4106 | AA17: =Ssum*K17*EXP(-K$5*$Y17)*K$6 -> 5388.7378 | AB17: =Ssum*L17*EXP(-L$5*$Y17)*L$6 -> 8359.5927 | AC17: =Ssum*M17*EXP(-M$5*$Y17)*M$6 -> 254.19647 | AD17: =Ssum*N17*EXP(-N$5*$Y17)*N$6 -> 1.4091513 | AE17: =(1-EXP(-J$5*$Y17))*J17 -> 2434.7065 | AF17: =(1-EXP(-K$5*$Y17))*K17 -> 13661.575 | AG17: =(1-EXP(-L$5*$Y17))*L17 -> 5147.2671 | AH17: =(1-EXP(-M$5*$Y17))*M17 -> 149.71864 | AI17: =(1-EXP(-N$5*$Y17))*N17 -> 0.82167333 | AJ17: =G17 -> 1982 | AK17: =SUM(AE17:AI17) -> 21394.089 | AL17: =SUM(Z17:AD17) -> 19280.347 | AM17: =AK17/(AK17+AL17) -> 0.52598367 | AN17: 11.487578 | AO17: 10.804773 | AP17: 15.307 | AQ17: =stressors!U12/stressors!U$49 -> 0.2950187 | AR17: =CHOOSE(stockcode,Esc!F32,Esc!G32,Esc!H32,Esc!I32,Esc!J32,Esc!K32,Esc!L32,Esc!M32,Esc!N31,Esc!O31,Esc!P31) -> 17650.493 | AS17: 0 | AT17: =AJ17 -> 1982 | AU17: 10000 | AV17: =AU16*J17/I16 -> 608.10063 | AW17: =AV16*K17/J16 -> 389.0884 | AX17: =AW16*L17/K16 -> 164.4229 | AY17: =AX16*M17/L16 -> 0 | AZ17: =AY16*N17/M16 -> 0 | BA17: =AV17*Z17/J17 -> 38.948483 | BB17: =AW17*AA17/K17 -> 39.777641 | BC17: =AX17*AB17/L17 -> 69.211012 | BD17: =AY17*AC17/M17 -> 0 | BE17: =AZ17*AD17/N17 -> 0 | BF17: =AV17*AE17/J17 -> 17.97209 | BG17: =AW17*AF17/K17 -> 100.84462 | BH17: =AX17*AG17/L17 -> 42.615421 | BI17: =AY17*AH17/M17 -> 0 | BJ17: =AZ17*AI17/N17 -> 0 | BK17: =AT17-2 -> 1980 | BL17: =(AE17+AF18+AG19+AH20+AI21)/(AE17+AF18+AG19+AH20+AI21+Z17+AA18+AB19+AC20+AD21) -> 0.52018524 | BM17: =AT17 -> 1982 | BN17: =BF18 -> 17.97209 | BO17: =BG19 -> 100.84462 | BP17: =BH20 -> 42.615421 | BQ17: =BI21 -> 1.2395555 | BR17: =BJ22 -> 0.0068028246 | BS17: =BA18 -> 38.948483 | BT17: =BB19 -> 39.777641 | BU17: =BC20 -> 69.211012 | BV17: =BD21 -> 2.1045517 | BW17: =BE22 -> 0.011666691 | BX17: =BY17*EXP(J$4)+BN17+BS17/Ssum -> 608.10063 | BY17: =BZ17*EXP(K$4)+BO17+BT17/Ssum -> 389.0884 | BZ17: =CA17*EXP(L$4)+BP17+BU17/Ssum -> 164.4229 | CA17: =CB17*EXP(M$4)+BQ17+BV17/Ssum -> 4.7825718 | CB17: =BR17+BW17/Ssum -> 0.02624731 | CC17: =BX17/AU17 -> 0.060810063
A18: exp Ric a | B18: =0.2*B17 -> 1.5201805 | C18: Hilborn-Walters predicted Ricker a | G18: 1983 | H18: =SUMPRODUCT(J$7:N$7,Z18:AD18) -> 27475069 | I18: =IF(LHT=1,H17*EXP(-Q17),H16*EXP(-Q16)) -> 3029931.8 | J18: =I17*EXP(-R17-I$5*$Y17)*(1-I$6) -> 190007.75 | K18: =J17*EXP(-S17-J$5*$Y17)*(1-J$6) -> 52710.4 | L18: =K17*EXP(-T17-K$5*$Y17)*(1-K$6) -> 22274.622 | M18: =L17*EXP(-U17-L$5*$Y17)*(1-L$6) -> 577.65883 | N18: =M17*EXP(-V17-M$5*$Y17)*(1-M$6) -> 3.1702589 | O18: -0.046716085 | P18: =O18-1 -> -1.0467161 | Q18: =MeMin+Mden*H18+P18 -> 1.9273282 | R18: =I$4+Mseal*AN18/40+Mhatch*AO18/30+Mtemp*(AP18-14.5) -> 2.8 | S18: =J$4 -> 0.3 | T18: =K$4+MSSLNRKWq*AQ18 -> 0.3 | U18: =L$4+MSSLNRKWq*AQ18 -> 0.3 | V18: =M$4 -> 0.3 | W18: =N$4 -> 0.3 | X18: =Q18+R19+S20+T21+U22+V23 -> 5.9273282 | Y18: =IF(UseRetro,RetroF,Ftest*ER!$D25+AS18) -> 0.3 | Z18: =Ssum*J18*EXP(-J$5*$Y18)*J$6 -> 12169.883 | AA18: =Ssum*K18*EXP(-K$5*$Y18)*K$6 -> 5388.7378 | AB18: =Ssum*L18*EXP(-L$5*$Y18)*L$6 -> 9376.1216 | AC18: =Ssum*M18*EXP(-M$5*$Y18)*M$6 -> 254.19647 | AD18: =Ssum*N18*EXP(-N$5*$Y18)*N$6 -> 1.4091513 | AE18: =(1-EXP(-J$5*$Y18))*J18 -> 5615.5776 | AF18: =(1-EXP(-K$5*$Y18))*K18 -> 13661.575 | AG18: =(1-EXP(-L$5*$Y18))*L18 -> 5773.1762 | AH18: =(1-EXP(-M$5*$Y18))*M18 -> 149.71864 | AI18: =(1-EXP(-N$5*$Y18))*N18 -> 0.82167333 | AJ18: =G18 -> 1983 | AK18: =SUM(AE18:AI18) -> 25200.869 | AL18: =SUM(Z18:AD18) -> 27190.348 | AM18: =AK18/(AK18+AL18) -> 0.48101324 | AN18: 13.169482 | AO18: 12.547973 | AP18: 14.999 | AQ18: =stressors!U13/stressors!U$49 -> 0.30518206 | AR18: =CHOOSE(stockcode,Esc!F33,Esc!G33,Esc!H33,Esc!I33,Esc!J33,Esc!K33,Esc!L33,Esc!M33,Esc!N32,Esc!O32,Esc!P32) -> 29204.887 | AS18: 0 | AT18: =AJ18 -> 1983 | AU18: 10000 | AV18: =AU17*J18/I17 -> 608.10063 | AW18: =AV17*K18/J17 -> 389.0884 | AX18: =AW17*L18/K17 -> 164.4229 | AY18: =AX17*M18/L17 -> 4.7825718 | AZ18: =AY17*N18/M17 -> 0 | BA18: =AV18*Z18/J18 -> 38.948483 | BB18: =AW18*AA18/K18 -> 39.777641 | BC18: =AX18*AB18/L18 -> 69.211012 | BD18: =AY18*AC18/M18 -> 2.1045517 | BE18: =AZ18*AD18/N18 -> 0 | BF18: =AV18*AE18/J18 -> 17.97209 | BG18: =AW18*AF18/K18 -> 100.84462 | BH18: =AX18*AG18/L18 -> 42.615421 | BI18: =AY18*AH18/M18 -> 1.2395555 | BJ18: =AZ18*AI18/N18 -> 0 | BK18: =AT18-2 -> 1981 | BL18: =(AE18+AF19+AG20+AH21+AI22)/(AE18+AF19+AG20+AH21+AI22+Z18+AA19+AB20+AC21+AD22) -> 0.52018524 | BM18: =AT18 -> 1983 | BN18: =BF19 -> 17.97209 | BO18: =BG20 -> 100.84462 | BP18: =BH21 -> 42.615421 | BQ18: =BI22 -> 1.2395555 | BR18: =BJ23 -> 0.0068028246 | BS18: =BA19 -> 38.948483 | BT18: =BB20 -> 39.777641 | BU18: =BC21 -> 69.211012 | BV18: =BD22 -> 2.1045517 | BW18: =BE23 -> 0.011666691 | BX18: =BY18*EXP(J$4)+BN18+BS18/Ssum -> 608.10063 | BY18: =BZ18*EXP(K$4)+BO18+BT18/Ssum -> 389.0884 | BZ18: =CA18*EXP(L$4)+BP18+BU18/Ssum -> 164.4229 | CA18: =CB18*EXP(M$4)+BQ18+BV18/Ssum -> 4.7825718 | CB18: =BR18+BW18/Ssum -> 0.02624731 | CC18: =BX18/AU18 -> 0.060810063
A19: Fhist | B19: =Ftest -> 0.3 | C19: assumed average historical F | D19: Pellet egg-smolt surv | E19: 0.12 | G19: 1984 | H19: =SUMPRODUCT(J$7:N$7,Z19:AD19) -> 38112682 | I19: =IF(LHT=1,H18*EXP(-Q18),H17*EXP(-Q17)) -> 4391111.1 | J19: =I18*EXP(-R18-I$5*$Y18)*(1-I$6) -> 184250.34 | K19: =J18*EXP(-S18-J$5*$Y18)*(1-J$6) -> 121574.96 | L19: =K18*EXP(-T18-K$5*$Y18)*(1-K$6) -> 22274.622 | M19: =L18*EXP(-U18-L$5*$Y18)*(1-L$6) -> 647.90231 | N19: =M18*EXP(-V18-M$5*$Y18)*(1-M$6) -> 3.1702589 | O19: 0.77674456 | P19: =O19-1 -> -0.22325544 | Q19: =MeMin+Mden*H19+P19 -> 2.9224402 | R19: =I$4+Mseal*AN19/40+Mhatch*AO19/30+Mtemp*(AP19-14.5) -> 2.8 | S19: =J$4 -> 0.3 | T19: =K$4+MSSLNRKWq*AQ19 -> 0.3 | U19: =L$4+MSSLNRKWq*AQ19 -> 0.3 | V19: =M$4 -> 0.3 | W19: =N$4 -> 0.3 | X19: =Q19+R20+S21+T22+U23+V24 -> 6.9224402 | Y19: =IF(UseRetro,RetroF,Ftest*ER!$D26+AS19) -> 0.3 | Z19: =Ssum*J19*EXP(-J$5*$Y19)*J$6 -> 11801.125 | AA19: =Ssum*K19*EXP(-K$5*$Y19)*K$6 -> 12428.963 | AB19: =Ssum*L19*EXP(-L$5*$Y19)*L$6 -> 9376.1216 | AC19: =Ssum*M19*EXP(-M$5*$Y19)*M$6 -> 285.10683 | AD19: =Ssum*N19*EXP(-N$5*$Y19)*N$6 -> 1.4091513 | AE19: =(1-EXP(-J$5*$Y19))*J19 -> 5445.4206 | AF19: =(1-EXP(-K$5*$Y19))*K19 -> 31510.015 | AG19: =(1-EXP(-L$5*$Y19))*L19 -> 5773.1762 | AH19: =(1-EXP(-M$5*$Y19))*M19 -> 167.92447 | AI19: =(1-EXP(-N$5*$Y19))*N19 -> 0.82167333 | AJ19: =G19 -> 1984 | AK19: =SUM(AE19:AI19) -> 42897.358 | AL19: =SUM(Z19:AD19) -> 33892.725 | AM19: =AK19/(AK19+AL19) -> 0.55863148 | AN19: 15.028157 | AO19: 14.370434 | AP19: 15.337 | AQ19: =stressors!U14/stressors!U$49 -> 0.30889098 | AR19: =CHOOSE(stockcode,Esc!F34,Esc!G34,Esc!H34,Esc!I34,Esc!J34,Esc!K34,Esc!L34,Esc!M34,Esc!N33,Esc!O33,Esc!P33) -> 36372.975 | AS19: 0 | AT19: =AJ19 -> 1984 | AU19: 10000 | AV19: =AU18*J19/I18 -> 608.10063 | AW19: =AV18*K19/J18 -> 389.0884 | AX19: =AW18*L19/K18 -> 164.4229 | AY19: =AX18*M19/L18 -> 4.7825718 | AZ19: =AY18*N19/M18 -> 0.02624731 | BA19: =AV19*Z19/J19 -> 38.948483 | BB19: =AW19*AA19/K19 -> 39.777641 | BC19: =AX19*AB19/L19 -> 69.211012 | BD19: =AY19*AC19/M19 -> 2.1045517 | BE19: =AZ19*AD19/N19 -> 0.011666691 | BF19: =AV19*AE19/J19 -> 17.97209 | BG19: =AW19*AF19/K19 -> 100.84462 | BH19: =AX19*AG19/L19 -> 42.615421 | BI19: =AY19*AH19/M19 -> 1.2395555 | BJ19: =AZ19*AI19/N19 -> 0.0068028246 | BK19: =AT19-2 -> 1982 | BL19: =(AE19+AF20+AG21+AH22+AI23)/(AE19+AF20+AG21+AH22+AI23+Z19+AA20+AB21+AC22+AD23) -> 0.52018524 | BM19: =AT19 -> 1984 | BN19: =BF20 -> 17.97209 | BO19: =BG21 -> 100.84462 | BP19: =BH22 -> 42.615421 | BQ19: =BI23 -> 1.2395555 | BR19: =BJ24 -> 0.0068028246 | BS19: =BA20 -> 38.948483 | BT19: =BB21 -> 39.777641 | BU19: =BC22 -> 69.211012 | BV19: =BD23 -> 2.1045517 | BW19: =BE24 -> 0.011666691 | BX19: =BY19*EXP(J$4)+BN19+BS19/Ssum -> 608.10063 | BY19: =BZ19*EXP(K$4)+BO19+BT19/Ssum -> 389.0884 | BZ19: =CA19*EXP(L$4)+BP19+BU19/Ssum -> 164.4229 | CA19: =CB19*EXP(M$4)+BQ19+BV19/Ssum -> 4.7825718 | CB19: =BR19+BW19/Ssum -> 0.02624731 | CC19: =BX19/AU19 -> 0.060810063
A20: EPRhist | B20: =SUMPRODUCT(Lhist,fec,mat,EXP(-vul*Fhist)*Ssum) -> 20.338486 | C20: historical sustained eggs per smolt | D20: hist egg-smolt surv | E20: =1/B20 -> 0.049167867 | G20: 1985 | H20: =SUMPRODUCT(J$7:N$7,Z20:AD20) -> 62047527 | I20: =IF(LHT=1,H19*EXP(-Q19),H18*EXP(-Q18)) -> 3998626.1 | J20: =I19*EXP(-R19-I$5*$Y19)*(1-I$6) -> 267023.74 | K20: =J19*EXP(-S19-J$5*$Y19)*(1-J$6) -> 117891.13 | L20: =K19*EXP(-T19-K$5*$Y19)*(1-K$6) -> 51375.75 | M20: =L19*EXP(-U19-L$5*$Y19)*(1-L$6) -> 647.90231 | N20: =M19*EXP(-V19-M$5*$Y19)*(1-M$6) -> 3.5557633 | O20: 0.26434207 | P20: =O20-1 -> -0.73565793 | Q20: =MeMin+Mden*H20+P20 -> 2.796257 | R20: =I$4+Mseal*AN20/40+Mhatch*AO20/30+Mtemp*(AP20-14.5) -> 2.8 | S20: =J$4 -> 0.3 | T20: =K$4+MSSLNRKWq*AQ20 -> 0.3 | U20: =L$4+MSSLNRKWq*AQ20 -> 0.3 | V20: =M$4 -> 0.3 | W20: =N$4 -> 0.3 | X20: =Q20+R21+S22+T23+U24+V25 -> 6.796257 | Y20: =IF(UseRetro,RetroF,Ftest*ER!$D27+AS20) -> 0.3 | Z20: =Ssum*J20*EXP(-J$5*$Y20)*J$6 -> 17102.712 | AA20: =Ssum*K20*EXP(-K$5*$Y20)*K$6 -> 12052.354 | AB20: =Ssum*L20*EXP(-L$5*$Y20)*L$6 -> 21625.744 | AC20: =Ssum*M20*EXP(-M$5*$Y20)*M$6 -> 285.10683 | AD20: =Ssum*N20*EXP(-N$5*$Y20)*N$6 -> 1.5805045 | AE20: =(1-EXP(-J$5*$Y20))*J20 -> 7891.7442 | AF20: =(1-EXP(-K$5*$Y20))*K20 -> 30555.233 | AG20: =(1-EXP(-L$5*$Y20))*L20 -> 13315.658 | AH20: =(1-EXP(-M$5*$Y20))*M20 -> 167.92447 | AI20: =(1-EXP(-N$5*$Y20))*N20 -> 0.92158905 | AJ20: =G20 -> 1985 | AK20: =SUM(AE20:AI20) -> 51931.481 | AL20: =SUM(Z20:AD20) -> 51067.497 | AM20: =AK20/(AK20+AL20) -> 0.50419414 | AN20: 17.057706 | AO20: 20.076246 | AP20: 15.185 | AQ20: =stressors!U15/stressors!U$49 -> 0.32413603 | AR20: =CHOOSE(stockcode,Esc!F35,Esc!G35,Esc!H35,Esc!I35,Esc!J35,Esc!K35,Esc!L35,Esc!M35,Esc!N34,Esc!O34,Esc!P34) -> 52231.921 | AS20: 0 | AT20: =AJ20 -> 1985 | AU20: 10000 | AV20: =AU19*J20/I19 -> 608.10063 | AW20: =AV19*K20/J19 -> 389.0884 | AX20: =AW19*L20/K19 -> 164.4229 | AY20: =AX19*M20/L19 -> 4.7825718 | AZ20: =AY19*N20/M19 -> 0.02624731 | BA20: =AV20*Z20/J20 -> 38.948483 | BB20: =AW20*AA20/K20 -> 39.777641 | BC20: =AX20*AB20/L20 -> 69.211012 | BD20: =AY20*AC20/M20 -> 2.1045517 | BE20: =AZ20*AD20/N20 -> 0.011666691 | BF20: =AV20*AE20/J20 -> 17.97209 | BG20: =AW20*AF20/K20 -> 100.84462 | BH20: =AX20*AG20/L20 -> 42.615421 | BI20: =AY20*AH20/M20 -> 1.2395555 | BJ20: =AZ20*AI20/N20 -> 0.0068028246 | BK20: =AT20-2 -> 1983 | BL20: =(AE20+AF21+AG22+AH23+AI24)/(AE20+AF21+AG22+AH23+AI24+Z20+AA21+AB22+AC23+AD24) -> 0.52018524 | BM20: =AT20 -> 1985 | BN20: =BF21 -> 17.97209 | BO20: =BG22 -> 100.84462 | BP20: =BH23 -> 42.615421 | BQ20: =BI24 -> 1.2395555 | BR20: =BJ25 -> 0.0068028246 | BS20: =BA21 -> 38.948483 | BT20: =BB22 -> 39.777641 | BU20: =BC23 -> 69.211012 | BV20: =BD24 -> 2.1045517 | BW20: =BE25 -> 0.011666691 | BX20: =BY20*EXP(J$4)+BN20+BS20/Ssum -> 608.10063 | BY20: =BZ20*EXP(K$4)+BO20+BT20/Ssum -> 389.0884 | BZ20: =CA20*EXP(L$4)+BP20+BU20/Ssum -> 164.4229 | CA20: =CB20*EXP(M$4)+BQ20+BV20/Ssum -> 4.7825718 | CB20: =BR20+BW20/Ssum -> 0.02624731 | CC20: =BX20/AU20 -> 0.060810063
A21: Ffuture | B21: 0.2 | C21: Future F | D21: delm | E21: =-LN(1/EPRo)+LN(1/EPRhist) -> 0.5608177 | G21: 1986 | H21: =SUMPRODUCT(J$7:N$7,Z21:AD21) -> 69789853 | I21: =IF(LHT=1,H20*EXP(-Q20),H19*EXP(-Q19)) -> 2050547.5 | J21: =I20*EXP(-R20-I$5*$Y20)*(1-I$6) -> 243156.7 | K21: =J20*EXP(-S20-J$5*$Y20)*(1-J$6) -> 170853.04 | L21: =K20*EXP(-T20-K$5*$Y20)*(1-K$6) -> 49819.019 | M21: =L20*EXP(-U20-L$5*$Y20)*(1-L$6) -> 1494.3673 | N21: =M20*EXP(-V20-M$5*$Y20)*(1-M$6) -> 3.5557633 | O21: 0.71773053 | P21: =O21-1 -> -0.28226947 | Q21: =MeMin+Mden*H21+P21 -> 3.3745777 | R21: =I$4+Mseal*AN21/40+Mhatch*AO21/30+Mtemp*(AP21-14.5) -> 2.8 | S21: =J$4 -> 0.3 | T21: =K$4+MSSLNRKWq*AQ21 -> 0.3 | U21: =L$4+MSSLNRKWq*AQ21 -> 0.3 | V21: =M$4 -> 0.3 | W21: =N$4 -> 0.3 | X21: =Q21+R22+S23+T24+U25+V26 -> 7.3745777 | Y21: =IF(UseRetro,RetroF,Ftest*ER!$D28+AS21) -> 0.3 | Z21: =Ssum*J21*EXP(-J$5*$Y21)*J$6 -> 15574.042 | AA21: =Ssum*K21*EXP(-K$5*$Y21)*K$6 -> 17466.804 | AB21: =Ssum*L21*EXP(-L$5*$Y21)*L$6 -> 20970.465 | AC21: =Ssum*M21*EXP(-M$5*$Y21)*M$6 -> 657.59038 | AD21: =Ssum*N21*EXP(-N$5*$Y21)*N$6 -> 1.5805045 | AE21: =(1-EXP(-J$5*$Y21))*J21 -> 7186.3666 | AF21: =(1-EXP(-K$5*$Y21))*K21 -> 44281.994 | AG21: =(1-EXP(-L$5*$Y21))*L21 -> 12912.182 | AH21: =(1-EXP(-M$5*$Y21))*M21 -> 387.31277 | AI21: =(1-EXP(-N$5*$Y21))*N21 -> 0.92158905 | AJ21: =G21 -> 1986 | AK21: =SUM(AE21:AI21) -> 64768.777 | AL21: =SUM(Z21:AD21) -> 54670.482 | AM21: =AK21/(AK21+AL21) -> 0.54227377 | AN21: 19.243188 | AO21: 26.832445 | AP21: 15.359 | AQ21: =stressors!U16/stressors!U$49 -> 0.34020101 | AR21: =CHOOSE(stockcode,Esc!F36,Esc!G36,Esc!H36,Esc!I36,Esc!J36,Esc!K36,Esc!L36,Esc!M36,Esc!N35,Esc!O35,Esc!P35) -> 60718.439 | AS21: 0 | AT21: =AJ21 -> 1986 | AU21: 10000 | AV21: =AU20*J21/I20 -> 608.10063 | AW21: =AV20*K21/J20 -> 389.0884 | AX21: =AW20*L21/K20 -> 164.4229 | AY21: =AX20*M21/L20 -> 4.7825718 | AZ21: =AY20*N21/M20 -> 0.02624731 | BA21: =AV21*Z21/J21 -> 38.948483 | BB21: =AW21*AA21/K21 -> 39.777641 | BC21: =AX21*AB21/L21 -> 69.211012 | BD21: =AY21*AC21/M21 -> 2.1045517 | BE21: =AZ21*AD21/N21 -> 0.011666691 | BF21: =AV21*AE21/J21 -> 17.97209 | BG21: =AW21*AF21/K21 -> 100.84462 | BH21: =AX21*AG21/L21 -> 42.615421 | BI21: =AY21*AH21/M21 -> 1.2395555 | BJ21: =AZ21*AI21/N21 -> 0.0068028246 | BK21: =AT21-2 -> 1984 | BL21: =(AE21+AF22+AG23+AH24+AI25)/(AE21+AF22+AG23+AH24+AI25+Z21+AA22+AB23+AC24+AD25) -> 0.52018524 | BM21: =AT21 -> 1986 | BN21: =BF22 -> 17.97209 | BO21: =BG23 -> 100.84462 | BP21: =BH24 -> 42.615421 | BQ21: =BI25 -> 1.2395555 | BR21: =BJ26 -> 0.0068028246 | BS21: =BA22 -> 38.948483 | BT21: =BB23 -> 39.777641 | BU21: =BC24 -> 69.211012 | BV21: =BD25 -> 2.1045517 | BW21: =BE26 -> 0.011666691 | BX21: =BY21*EXP(J$4)+BN21+BS21/Ssum -> 608.10063 | BY21: =BZ21*EXP(K$4)+BO21+BT21/Ssum -> 389.0884 | BZ21: =CA21*EXP(L$4)+BP21+BU21/Ssum -> 164.4229 | CA21: =CB21*EXP(M$4)+BQ21+BV21/Ssum -> 4.7825718 | CB21: =BR21+BW21/Ssum -> 0.02624731 | CC21: =BX21/AU21 -> 0.060810063
A22: Mseal | B22: 0 | C22: added M due to seals at seal N=40000 | G22: 1987 | H22: =SUMPRODUCT(J$7:N$7,Z22:AD22) -> 86246134 | I22: =IF(LHT=1,H21*EXP(-Q21),H20*EXP(-Q20)) -> 3787263.3 | J22: =I21*EXP(-R21-I$5*$Y21)*(1-I$6) -> 124693.92 | K22: =J21*EXP(-S21-J$5*$Y21)*(1-J$6) -> 155581.9 | L22: =K21*EXP(-T21-K$5*$Y21)*(1-K$6) -> 72199.924 | M22: =L21*EXP(-U21-L$5*$Y21)*(1-L$6) -> 1449.0866 | N22: =M21*EXP(-V21-M$5*$Y21)*(1-M$6) -> 8.2012616 | O22: 0.60899123 | P22: =O22-1 -> -0.39100877 | Q22: =MeMin+Mden*H22+P22 -> 3.5313815 | R22: =I$4+Mseal*AN22/40+Mhatch*AO22/30+Mtemp*(AP22-14.5) -> 2.8 | S22: =J$4 -> 0.3 | T22: =K$4+MSSLNRKWq*AQ22 -> 0.3 | U22: =L$4+MSSLNRKWq*AQ22 -> 0.3 | V22: =M$4 -> 0.3 | W22: =N$4 -> 0.3 | X22: =Q22+R23+S24+T25+U26+V27 -> 7.5313815 | Y22: =IF(UseRetro,RetroF,Ftest*ER!$D29+AS22) -> 0.3 | Z22: =Ssum*J22*EXP(-J$5*$Y22)*J$6 -> 7986.5715 | AA22: =Ssum*K22*EXP(-K$5*$Y22)*K$6 -> 15905.591 | AB22: =Ssum*L22*EXP(-L$5*$Y22)*L$6 -> 30391.324 | AC22: =Ssum*M22*EXP(-M$5*$Y22)*M$6 -> 637.66481 | AD22: =Ssum*N22*EXP(-N$5*$Y22)*N$6 -> 3.6453864 | AE22: =(1-EXP(-J$5*$Y22))*J22 -> 3685.2623 | AF22: =(1-EXP(-K$5*$Y22))*K22 -> 40323.994 | AG22: =(1-EXP(-L$5*$Y22))*L22 -> 18712.905 | AH22: =(1-EXP(-M$5*$Y22))*M22 -> 375.57685 | AI22: =(1-EXP(-N$5*$Y22))*N22 -> 2.1256176 | AJ22: =G22 -> 1987 | AK22: =SUM(AE22:AI22) -> 63099.864 | AL22: =SUM(Z22:AD22) -> 54924.797 | AM22: =AK22/(AK22+AL22) -> 0.53463287 | AN22: 21.559445 | AO22: 33.270881 | AP22: 15.293 | AQ22: =stressors!U17/stressors!U$49 -> 0.34693537 | AR22: =CHOOSE(stockcode,Esc!F37,Esc!G37,Esc!H37,Esc!I37,Esc!J37,Esc!K37,Esc!L37,Esc!M37,Esc!N36,Esc!O36,Esc!P36) -> 61979.185 | AS22: 0 | AT22: =AJ22 -> 1987 | AU22: 10000 | AV22: =AU21*J22/I21 -> 608.10063 | AW22: =AV21*K22/J21 -> 389.0884 | AX22: =AW21*L22/K21 -> 164.4229 | AY22: =AX21*M22/L21 -> 4.7825718 | AZ22: =AY21*N22/M21 -> 0.02624731 | BA22: =AV22*Z22/J22 -> 38.948483 | BB22: =AW22*AA22/K22 -> 39.777641 | BC22: =AX22*AB22/L22 -> 69.211012 | BD22: =AY22*AC22/M22 -> 2.1045517 | BE22: =AZ22*AD22/N22 -> 0.011666691 | BF22: =AV22*AE22/J22 -> 17.97209 | BG22: =AW22*AF22/K22 -> 100.84462 | BH22: =AX22*AG22/L22 -> 42.615421 | BI22: =AY22*AH22/M22 -> 1.2395555 | BJ22: =AZ22*AI22/N22 -> 0.0068028246 | BK22: =AT22-2 -> 1985 | BL22: =(AE22+AF23+AG24+AH25+AI26)/(AE22+AF23+AG24+AH25+AI26+Z22+AA23+AB24+AC25+AD26) -> 0.52018524 | BM22: =AT22 -> 1987 | BN22: =BF23 -> 17.97209 | BO22: =BG24 -> 100.84462 | BP22: =BH25 -> 42.615421 | BQ22: =BI26 -> 1.2395555 | BR22: =BJ27 -> 0.0068028246 | BS22: =BA23 -> 38.948483 | BT22: =BB24 -> 39.777641 | BU22: =BC25 -> 69.211012 | BV22: =BD26 -> 2.1045517 | BW22: =BE27 -> 0.011666691 | BX22: =BY22*EXP(J$4)+BN22+BS22/Ssum -> 608.10063 | BY22: =BZ22*EXP(K$4)+BO22+BT22/Ssum -> 389.0884 | BZ22: =CA22*EXP(L$4)+BP22+BU22/Ssum -> 164.4229 | CA22: =CB22*EXP(M$4)+BQ22+BV22/Ssum -> 4.7825718 | CB22: =BR22+BW22/Ssum -> 0.02624731 | CC22: =BX22/AU22 -> 0.060810063
A23: Mhatch | B23: 0 | C23: added M at hatchery release 30 million | G23: 1988 | H23: =SUMPRODUCT(J$7:N$7,Z23:AD23) -> 69905618 | I23: =IF(LHT=1,H22*EXP(-Q22),H21*EXP(-Q21)) -> 2389086.1 | J23: =I22*EXP(-R22-I$5*$Y22)*(1-I$6) -> 230303.72 | K23: =J22*EXP(-S22-J$5*$Y22)*(1-J$6) -> 79784.424 | L23: =K22*EXP(-T22-K$5*$Y22)*(1-K$6) -> 65746.571 | M23: =L22*EXP(-U22-L$5*$Y22)*(1-L$6) -> 2100.0804 | N23: =M22*EXP(-V22-M$5*$Y22)*(1-M$6) -> 7.952756 | O23: 1.0271816 | P23: =O23-1 -> 0.027181587 | Q23: =MeMin+Mden*H23+P23 -> 3.6858968 | R23: =I$4+Mseal*AN23/40+Mhatch*AO23/30+Mtemp*(AP23-14.5) -> 2.8 | S23: =J$4 -> 0.3 | T23: =K$4+MSSLNRKWq*AQ23 -> 0.3 | U23: =L$4+MSSLNRKWq*AQ23 -> 0.3 | V23: =M$4 -> 0.3 | W23: =N$4 -> 0.3 | X23: =Q23+R24+S25+T26+U27+V28 -> 7.6858968 | Y23: =IF(UseRetro,RetroF,Ftest*ER!$D30+AS23) -> 0.3 | Z23: =Ssum*J23*EXP(-J$5*$Y23)*J$6 -> 14750.816 | AA23: =Ssum*K23*EXP(-K$5*$Y23)*K$6 -> 8156.5942 | AB23: =Ssum*L23*EXP(-L$5*$Y23)*L$6 -> 27674.896 | AC23: =Ssum*M23*EXP(-M$5*$Y23)*M$6 -> 924.13203 | AD23: =Ssum*N23*EXP(-N$5*$Y23)*N$6 -> 3.5349279 | AE23: =(1-EXP(-J$5*$Y23))*J23 -> 6806.5036 | AF23: =(1-EXP(-K$5*$Y23))*K23 -> 20678.669 | AG23: =(1-EXP(-L$5*$Y23))*L23 -> 17040.313 | AH23: =(1-EXP(-M$5*$Y23))*M23 -> 544.30258 | AI23: =(1-EXP(-N$5*$Y23))*N23 -> 2.0612095 | AJ23: =G23 -> 1988 | AK23: =SUM(AE23:AI23) -> 45071.85 | AL23: =SUM(Z23:AD23) -> 51509.973 | AM23: =AK23/(AK23+AL23) -> 0.46667011 | AN23: 23.969612 | AO23: 32.180595 | AP23: 15.997 | AQ23: =stressors!U18/stressors!U$49 -> 0.36094411 | AR23: =CHOOSE(stockcode,Esc!F38,Esc!G38,Esc!H38,Esc!I38,Esc!J38,Esc!K38,Esc!L38,Esc!M38,Esc!N37,Esc!O37,Esc!P37) -> 54064.134 | AS23: 0 | AT23: =AJ23 -> 1988 | AU23: 10000 | AV23: =AU22*J23/I22 -> 608.10063 | AW23: =AV22*K23/J22 -> 389.0884 | AX23: =AW22*L23/K22 -> 164.4229 | AY23: =AX22*M23/L22 -> 4.7825718 | AZ23: =AY22*N23/M22 -> 0.02624731 | BA23: =AV23*Z23/J23 -> 38.948483 | BB23: =AW23*AA23/K23 -> 39.777641 | BC23: =AX23*AB23/L23 -> 69.211012 | BD23: =AY23*AC23/M23 -> 2.1045517 | BE23: =AZ23*AD23/N23 -> 0.011666691 | BF23: =AV23*AE23/J23 -> 17.97209 | BG23: =AW23*AF23/K23 -> 100.84462 | BH23: =AX23*AG23/L23 -> 42.615421 | BI23: =AY23*AH23/M23 -> 1.2395555 | BJ23: =AZ23*AI23/N23 -> 0.0068028246 | BK23: =AT23-2 -> 1986 | BL23: =(AE23+AF24+AG25+AH26+AI27)/(AE23+AF24+AG25+AH26+AI27+Z23+AA24+AB25+AC26+AD27) -> 0.52018524 | BM23: =AT23 -> 1988 | BN23: =BF24 -> 17.97209 | BO23: =BG25 -> 100.84462 | BP23: =BH26 -> 42.615421 | BQ23: =BI27 -> 1.2395555 | BR23: =BJ28 -> 0.0068028246 | BS23: =BA24 -> 38.948483 | BT23: =BB25 -> 39.777641 | BU23: =BC26 -> 69.211012 | BV23: =BD27 -> 2.1045517 | BW23: =BE28 -> 0.011666691 | BX23: =BY23*EXP(J$4)+BN23+BS23/Ssum -> 608.10063 | BY23: =BZ23*EXP(K$4)+BO23+BT23/Ssum -> 389.0884 | BZ23: =CA23*EXP(L$4)+BP23+BU23/Ssum -> 164.4229 | CA23: =CB23*EXP(M$4)+BQ23+BV23/Ssum -> 4.7825718 | CB23: =BR23+BW23/Ssum -> 0.02624731 | CC23: =BX23/AU23 -> 0.060810063
A24: Mtemp | B24: 0 | C24: added M at temperature>14.5 | G24: 1989 | H24: =SUMPRODUCT(J$7:N$7,Z24:AD24) -> 53100551 | I24: =IF(LHT=1,H23*EXP(-Q23),H22*EXP(-Q22)) -> 2523946.5 | J24: =I23*EXP(-R23-I$5*$Y23)*(1-I$6) -> 145280.47 | K24: =J23*EXP(-S23-J$5*$Y23)*(1-J$6) -> 147358.02 | L24: =K23*EXP(-T23-K$5*$Y23)*(1-K$6) -> 33715.697 | M24: =L23*EXP(-U23-L$5*$Y23)*(1-L$6) -> 1912.3716 | N24: =M23*EXP(-V23-M$5*$Y23)*(1-M$6) -> 11.525486 | O24: 0.061937969 | P24: =O24-1 -> -0.93806203 | Q24: =MeMin+Mden*H24+P24 -> 2.449482 | R24: =I$4+Mseal*AN24/40+Mhatch*AO24/30+Mtemp*(AP24-14.5) -> 2.8 | S24: =J$4 -> 0.3 | T24: =K$4+MSSLNRKWq*AQ24 -> 0.3 | U24: =L$4+MSSLNRKWq*AQ24 -> 0.3 | V24: =M$4 -> 0.3 | W24: =N$4 -> 0.3 | X24: =Q24+R25+S26+T27+U28+V29 -> 6.449482 | Y24: =IF(UseRetro,RetroF,Ftest*ER!$D31+AS24) -> 0.3 | Z24: =Ssum*J24*EXP(-J$5*$Y24)*J$6 -> 9305.128 | AA24: =Ssum*K24*EXP(-K$5*$Y24)*K$6 -> 15064.84 | AB24: =Ssum*L24*EXP(-L$5*$Y24)*L$6 -> 14192.047 | AC24: =Ssum*M24*EXP(-M$5*$Y24)*M$6 -> 841.53153 | AD24: =Ssum*N24*EXP(-N$5*$Y24)*N$6 -> 5.1229739 | AE24: =(1-EXP(-J$5*$Y24))*J24 -> 4293.6869 | AF24: =(1-EXP(-K$5*$Y24))*K24 -> 38192.514 | AG24: =(1-EXP(-L$5*$Y24))*L24 -> 8738.4945 | AH24: =(1-EXP(-M$5*$Y24))*M24 -> 495.65188 | AI24: =(1-EXP(-N$5*$Y24))*N24 -> 2.9871959 | AJ24: =G24 -> 1989 | AK24: =SUM(AE24:AI24) -> 51723.335 | AL24: =SUM(Z24:AD24) -> 39408.669 | AM24: =AK24/(AK24+AL24) -> 0.56756499 | AN24: 26.424648 | AO24: 30.065616 | AP24: 16.347 | AQ24: =stressors!U19/stressors!U$49 -> 0.37110747 | AR24: =CHOOSE(stockcode,Esc!F39,Esc!G39,Esc!H39,Esc!I39,Esc!J39,Esc!K39,Esc!L39,Esc!M39,Esc!N38,Esc!O38,Esc!P38) -> 37950.629 | AS24: 0 | AT24: =AJ24 -> 1989 | AU24: 10000 | AV24: =AU23*J24/I23 -> 608.10063 | AW24: =AV23*K24/J23 -> 389.0884 | AX24: =AW23*L24/K23 -> 164.4229 | AY24: =AX23*M24/L23 -> 4.7825718 | AZ24: =AY23*N24/M23 -> 0.02624731 | BA24: =AV24*Z24/J24 -> 38.948483 | BB24: =AW24*AA24/K24 -> 39.777641 | BC24: =AX24*AB24/L24 -> 69.211012 | BD24: =AY24*AC24/M24 -> 2.1045517 | BE24: =AZ24*AD24/N24 -> 0.011666691 | BF24: =AV24*AE24/J24 -> 17.97209 | BG24: =AW24*AF24/K24 -> 100.84462 | BH24: =AX24*AG24/L24 -> 42.615421 | BI24: =AY24*AH24/M24 -> 1.2395555 | BJ24: =AZ24*AI24/N24 -> 0.0068028246 | BK24: =AT24-2 -> 1987 | BL24: =(AE24+AF25+AG26+AH27+AI28)/(AE24+AF25+AG26+AH27+AI28+Z24+AA25+AB26+AC27+AD28) -> 0.52018524 | BM24: =AT24 -> 1989 | BN24: =BF25 -> 17.97209 | BO24: =BG26 -> 100.84462 | BP24: =BH27 -> 42.615421 | BQ24: =BI28 -> 1.2395555 | BR24: =BJ29 -> 0.0068028246 | BS24: =BA25 -> 38.948483 | BT24: =BB26 -> 39.777641 | BU24: =BC27 -> 69.211012 | BV24: =BD28 -> 2.1045517 | BW24: =BE29 -> 0.011666691 | BX24: =BY24*EXP(J$4)+BN24+BS24/Ssum -> 608.10063 | BY24: =BZ24*EXP(K$4)+BO24+BT24/Ssum -> 389.0884 | BZ24: =CA24*EXP(L$4)+BP24+BU24/Ssum -> 164.4229 | CA24: =CB24*EXP(M$4)+BQ24+BV24/Ssum -> 4.7825718 | CB24: =BR24+BW24/Ssum -> 0.02624731 | CC24: =BX24/AU24 -> 0.060810063
A25: MSSLNRKWq | B25: 0 | C25: added M at peak SSL+NRKW Q | G25: 1990 | H25: =SUMPRODUCT(J$7:N$7,Z25:AD25) -> 67771763 | I25: =IF(LHT=1,H24*EXP(-Q24),H23*EXP(-Q23)) -> 1752860.9 | J25: =I24*EXP(-R24-I$5*$Y24)*(1-I$6) -> 153481.35 | K25: =J24*EXP(-S24-J$5*$Y24)*(1-J$6) -> 92956.567 | L25: =K24*EXP(-T24-K$5*$Y24)*(1-K$6) -> 62271.283 | M25: =L24*EXP(-U24-L$5*$Y24)*(1-L$6) -> 980.68905 | N25: =M24*EXP(-V24-M$5*$Y24)*(1-M$6) -> 10.495318 | O25: 0.28646754 | P25: =O25-1 -> -0.71353246 | Q25: =MeMin+Mden*H25+P25 -> 2.9107503 | R25: =I$4+Mseal*AN25/40+Mhatch*AO25/30+Mtemp*(AP25-14.5) -> 2.8 | S25: =J$4 -> 0.3 | T25: =K$4+MSSLNRKWq*AQ25 -> 0.3 | U25: =L$4+MSSLNRKWq*AQ25 -> 0.3 | V25: =M$4 -> 0.3 | W25: =N$4 -> 0.3 | X25: =Q25+R26+S27+T28+U29+V30 -> 6.9107503 | Y25: =IF(UseRetro,RetroF,Ftest*ER!$D32+AS25) -> 0.3 | Z25: =Ssum*J25*EXP(-J$5*$Y25)*J$6 -> 9830.389 | AA25: =Ssum*K25*EXP(-K$5*$Y25)*K$6 -> 9503.2208 | AB25: =Ssum*L25*EXP(-L$5*$Y25)*L$6 -> 26212.033 | AC25: =Ssum*M25*EXP(-M$5*$Y25)*M$6 -> 431.54832 | AD25: =Ssum*N25*EXP(-N$5*$Y25)*N$6 -> 4.6650737 | AE25: =(1-EXP(-J$5*$Y25))*J25 -> 4536.0593 | AF25: =(1-EXP(-K$5*$Y25))*K25 -> 24092.649 | AG25: =(1-EXP(-L$5*$Y25))*L25 -> 16139.582 | AH25: =(1-EXP(-M$5*$Y25))*M25 -> 254.17673 | AI25: =(1-EXP(-N$5*$Y25))*N25 -> 2.7201952 | AJ25: =G25 -> 1990 | AK25: =SUM(AE25:AI25) -> 45025.187 | AL25: =SUM(Z25:AD25) -> 45981.856 | AM25: =AK25/(AK25+AL25) -> 0.49474398 | AN25: 28.864553 | AO25: 33.204686 | AP25: 15.516 | AQ25: =stressors!U20/stressors!U$49 -> 0.3810889 | AR25: =CHOOSE(stockcode,Esc!F40,Esc!G40,Esc!H40,Esc!I40,Esc!J40,Esc!K40,Esc!L40,Esc!M40,Esc!N39,Esc!O39,Esc!P39) -> 51157.855 | AS25: 0 | AT25: =AJ25 -> 1990 | AU25: 10000 | AV25: =AU24*J25/I24 -> 608.10063 | AW25: =AV24*K25/J24 -> 389.0884 | AX25: =AW24*L25/K24 -> 164.4229 | AY25: =AX24*M25/L24 -> 4.7825718 | AZ25: =AY24*N25/M24 -> 0.02624731 | BA25: =AV25*Z25/J25 -> 38.948483 | BB25: =AW25*AA25/K25 -> 39.777641 | BC25: =AX25*AB25/L25 -> 69.211012 | BD25: =AY25*AC25/M25 -> 2.1045517 | BE25: =AZ25*AD25/N25 -> 0.011666691 | BF25: =AV25*AE25/J25 -> 17.97209 | BG25: =AW25*AF25/K25 -> 100.84462 | BH25: =AX25*AG25/L25 -> 42.615421 | BI25: =AY25*AH25/M25 -> 1.2395555 | BJ25: =AZ25*AI25/N25 -> 0.0068028246 | BK25: =AT25-2 -> 1988 | BL25: =(AE25+AF26+AG27+AH28+AI29)/(AE25+AF26+AG27+AH28+AI29+Z25+AA26+AB27+AC28+AD29) -> 0.52018524 | BM25: =AT25 -> 1990 | BN25: =BF26 -> 17.97209 | BO25: =BG27 -> 100.84462 | BP25: =BH28 -> 42.615421 | BQ25: =BI29 -> 1.2395555 | BR25: =BJ30 -> 0.0052884073 | BS25: =BA26 -> 38.948483 | BT25: =BB27 -> 39.777641 | BU25: =BC28 -> 69.211012 | BV25: =BD29 -> 2.1045517 | BW25: =BE30 -> 0.012575342 | BX25: =BY25*EXP(J$4)+BN25+BS25/Ssum -> 608.10063 | BY25: =BZ25*EXP(K$4)+BO25+BT25/Ssum -> 389.0884 | BZ25: =CA25*EXP(L$4)+BP25+BU25/Ssum -> 164.4229 | CA25: =CB25*EXP(M$4)+BQ25+BV25/Ssum -> 4.7825718 | CB25: =BR25+BW25/Ssum -> 0.02624731 | CC25: =BX25/AU25 -> 0.060810063
G26: 1991 | H26: =SUMPRODUCT(J$7:N$7,Z26:AD26) -> 50129509 | I26: =IF(LHT=1,H25*EXP(-Q25),H24*EXP(-Q24)) -> 4584611.1 | J26: =I25*EXP(-R25-I$5*$Y25)*(1-I$6) -> 106591.58 | K26: =J25*EXP(-S25-J$5*$Y25)*(1-J$6) -> 98203.831 | L26: =K25*EXP(-T25-K$5*$Y25)*(1-K$6) -> 39282.047 | M26: =L25*EXP(-U25-L$5*$Y25)*(1-L$6) -> 1811.2859 | N26: =M25*EXP(-V25-M$5*$Y25)*(1-M$6) -> 5.3821356 | O26: 0.67064636 | P26: =O26-1 -> -0.32935364 | Q26: =MeMin+Mden*H26+P26 -> 3.0102489 | R26: =I$4+Mseal*AN26/40+Mhatch*AO26/30+Mtemp*(AP26-14.5) -> 2.8 | S26: =J$4 -> 0.3 | T26: =K$4+MSSLNRKWq*AQ26 -> 0.3 | U26: =L$4+MSSLNRKWq*AQ26 -> 0.3 | V26: =M$4 -> 0.3 | W26: =N$4 -> 0.3 | X26: =Q26+R27+S28+T29+U30+V31 -> 7.0102489 | Y26: =IF(UseRetro,RetroF,Ftest*ER!$D33+AS26) -> 0.3 | Z26: =Ssum*J26*EXP(-J$5*$Y26)*J$6 -> 6827.1272 | AA26: =Ssum*K26*EXP(-K$5*$Y26)*K$6 -> 10039.664 | AB26: =Ssum*L26*EXP(-L$5*$Y26)*L$6 -> 16535.107 | AC26: =Ssum*M26*EXP(-M$5*$Y26)*M$6 -> 797.04914 | AD26: =Ssum*N26*EXP(-N$5*$Y26)*N$6 -> 2.3923105 | AE26: =(1-EXP(-J$5*$Y26))*J26 -> 3150.2572 | AF26: =(1-EXP(-K$5*$Y26))*K26 -> 25452.644 | AG26: =(1-EXP(-L$5*$Y26))*L26 -> 10181.191 | AH26: =(1-EXP(-M$5*$Y26))*M26 -> 469.45229 | AI26: =(1-EXP(-N$5*$Y26))*N26 -> 1.3949515 | AJ26: =G26 -> 1991 | AK26: =SUM(AE26:AI26) -> 39254.939 | AL26: =SUM(Z26:AD26) -> 34201.339 | AM26: =AK26/(AK26+AL26) -> 0.53439869 | AN26: 31.221511 | AO26: 27.483294 | AP26: 16.361 | AQ26: =stressors!U21/stressors!U$49 -> 0.3916024 | AR26: =CHOOSE(stockcode,Esc!F41,Esc!G41,Esc!H41,Esc!I41,Esc!J41,Esc!K41,Esc!L41,Esc!M41,Esc!N40,Esc!O40,Esc!P40) -> 34767.352 | AS26: 0 | AT26: =AJ26 -> 1991 | AU26: 10000 | AV26: =AU25*J26/I25 -> 608.10063 | AW26: =AV25*K26/J25 -> 389.0884 | AX26: =AW25*L26/K25 -> 164.4229 | AY26: =AX25*M26/L25 -> 4.7825718 | AZ26: =AY25*N26/M25 -> 0.02624731 | BA26: =AV26*Z26/J26 -> 38.948483 | BB26: =AW26*AA26/K26 -> 39.777641 | BC26: =AX26*AB26/L26 -> 69.211012 | BD26: =AY26*AC26/M26 -> 2.1045517 | BE26: =AZ26*AD26/N26 -> 0.011666691 | BF26: =AV26*AE26/J26 -> 17.97209 | BG26: =AW26*AF26/K26 -> 100.84462 | BH26: =AX26*AG26/L26 -> 42.615421 | BI26: =AY26*AH26/M26 -> 1.2395555 | BJ26: =AZ26*AI26/N26 -> 0.0068028246 | BK26: =AT26-2 -> 1989 | BL26: =(AE26+AF27+AG28+AH29+AI30)/(AE26+AF27+AG28+AH29+AI30+Z26+AA27+AB28+AC29+AD30) -> 0.52018141 | BM26: =AT26 -> 1991 | BN26: =BF27 -> 17.97209 | BO26: =BG28 -> 100.84462 | BP26: =BH29 -> 42.615421 | BQ26: =BI30 -> 0.96361064 | BR26: =BJ31 -> 0.0057002904 | BS26: =BA27 -> 38.948483 | BT26: =BB28 -> 39.777641 | BU26: =BC29 -> 69.211012 | BV26: =BD30 -> 2.2684629 | BW26: =BE31 -> 0.013554762 | BX26: =BY26*EXP(J$4)+BN26+BS26/Ssum -> 608.10063 | BY26: =BZ26*EXP(K$4)+BO26+BT26/Ssum -> 389.0884 | BZ26: =CA26*EXP(L$4)+BP26+BU26/Ssum -> 164.4229 | CA26: =CB26*EXP(M$4)+BQ26+BV26/Ssum -> 4.7825718 | CB26: =BR26+BW26/Ssum -> 0.02829156 | CC26: =BX26/AU26 -> 0.060810063
A27: stockcode | B27: 11 | C27: 1=cow,2=che,3=nan,4=qual,5=pun,6=quin,7=eng,8=total,9=Harrison,10=sum41 | G27: 1992 | H27: =SUMPRODUCT(J$7:N$7,Z27:AD27) -> 46665923 | I27: =IF(LHT=1,H26*EXP(-Q26),H25*EXP(-Q25)) -> 3689147.3 | J27: =I26*EXP(-R26-I$5*$Y26)*(1-I$6) -> 278790.49 | K27: =J26*EXP(-S26-J$5*$Y26)*(1-J$6) -> 68201.782 | L27: =K26*EXP(-T26-K$5*$Y26)*(1-K$6) -> 41499.462 | M27: =L26*EXP(-U26-L$5*$Y26)*(1-L$6) -> 1142.5976 | N27: =M26*EXP(-V26-M$5*$Y26)*(1-M$6) -> 9.9405476 | O27: 0.56179562 | P27: =O27-1 -> -0.43820438 | Q27: =MeMin+Mden*H27+P27 -> 2.8455088 | R27: =I$4+Mseal*AN27/40+Mhatch*AO27/30+Mtemp*(AP27-14.5) -> 2.8 | S27: =J$4 -> 0.3 | T27: =K$4+MSSLNRKWq*AQ27 -> 0.3 | U27: =L$4+MSSLNRKWq*AQ27 -> 0.3 | V27: =M$4 -> 0.3 | W27: =N$4 -> 0.3 | X27: =Q27+R28+S29+T30+U31+V32 -> 6.8455088 | Y27: =IF(UseRetro,RetroF,Ftest*ER!$D34+AS27) -> 0.3 | Z27: =Ssum*J27*EXP(-J$5*$Y27)*J$6 -> 17856.365 | AA27: =Ssum*K27*EXP(-K$5*$Y27)*K$6 -> 6972.4669 | AB27: =Ssum*L27*EXP(-L$5*$Y27)*L$6 -> 17468.489 | AC27: =Ssum*M27*EXP(-M$5*$Y27)*M$6 -> 502.79552 | AD27: =Ssum*N27*EXP(-N$5*$Y27)*N$6 -> 4.4184833 | AE27: =(1-EXP(-J$5*$Y27))*J27 -> 8239.5042 | AF27: =(1-EXP(-K$5*$Y27))*K27 -> 17676.659 | AG27: =(1-EXP(-L$5*$Y27))*L27 -> 10755.904 | AH27: =(1-EXP(-M$5*$Y27))*M27 -> 296.14047 | AI27: =(1-EXP(-N$5*$Y27))*N27 -> 2.5764088 | AJ27: =G27 -> 1992 | AK27: =SUM(AE27:AI27) -> 36970.785 | AL27: =SUM(Z27:AD27) -> 42804.535 | AM27: =AK27/(AK27+AL27) -> 0.46343637 | AN27: 33.424904 | AO27: 26.055396 | AP27: 16.343 | AQ27: =stressors!U22/stressors!U$49 -> 0.37870725 | AR27: =CHOOSE(stockcode,Esc!F42,Esc!G42,Esc!H42,Esc!I42,Esc!J42,Esc!K42,Esc!L42,Esc!M42,Esc!N41,Esc!O41,Esc!P41) -> 42483.844 | AS27: 0 | AT27: =AJ27 -> 1992 | AU27: 10000 | AV27: =AU26*J27/I26 -> 608.10063 | AW27: =AV26*K27/J26 -> 389.0884 | AX27: =AW26*L27/K26 -> 164.4229 | AY27: =AX26*M27/L26 -> 4.7825718 | AZ27: =AY26*N27/M26 -> 0.02624731 | BA27: =AV27*Z27/J27 -> 38.948483 | BB27: =AW27*AA27/K27 -> 39.777641 | BC27: =AX27*AB27/L27 -> 69.211012 | BD27: =AY27*AC27/M27 -> 2.1045517 | BE27: =AZ27*AD27/N27 -> 0.011666691 | BF27: =AV27*AE27/J27 -> 17.97209 | BG27: =AW27*AF27/K27 -> 100.84462 | BH27: =AX27*AG27/L27 -> 42.615421 | BI27: =AY27*AH27/M27 -> 1.2395555 | BJ27: =AZ27*AI27/N27 -> 0.0068028246 | BK27: =AT27-2 -> 1990 | BL27: =(AE27+AF28+AG29+AH30+AI31)/(AE27+AF28+AG29+AH30+AI31+Z27+AA28+AB29+AC30+AD31) -> 0.51948415 | BM27: =AT27 -> 1992 | BN27: =BF28 -> 17.97209 | BO27: =BG29 -> 100.84462 | BP27: =BH30 -> 33.128548 | BQ27: =BI31 -> 1.0386606 | BR27: =BJ32 -> 0.0056833685 | BS27: =BA28 -> 38.948483 | BT27: =BB29 -> 39.777641 | BU27: =BC30 -> 74.601453 | BV27: =BD31 -> 2.4451402 | BW27: =BE32 -> 0.014886993 | BX27: =BY27*EXP(J$4)+BN27+BS27/Ssum -> 608.10063 | BY27: =BZ27*EXP(K$4)+BO27+BT27/Ssum -> 389.0884 | BZ27: =CA27*EXP(L$4)+BP27+BU27/Ssum -> 164.4229 | CA27: =CB27*EXP(M$4)+BQ27+BV27/Ssum -> 5.1550583 | CB27: =BR27+BW27/Ssum -> 0.030495024 | CC27: =BX27/AU27 -> 0.060810063
A28: YPR | B28: =SUMPRODUCT(Lhist,(1-EXP(-vul*Fhist))) -> 0.016267849 | E28: 11=spring42 | G28: 1993 | H28: =SUMPRODUCT(J$7:N$7,Z28:AD28) -> 52954513 | I28: =IF(LHT=1,H27*EXP(-Q27),H26*EXP(-Q26)) -> 2470352.8 | J28: =I27*EXP(-R27-I$5*$Y27)*(1-I$6) -> 224337.28 | K28: =J27*EXP(-S27-J$5*$Y27)*(1-J$6) -> 178381.9 | L28: =K27*EXP(-T27-K$5*$Y27)*(1-K$6) -> 28821.047 | M28: =L27*EXP(-U27-L$5*$Y27)*(1-L$6) -> 1207.0955 | N28: =M27*EXP(-V27-M$5*$Y27)*(1-M$6) -> 6.2707084 | O28: 0.69701129 | P28: =O28-1 -> -0.30298871 | Q28: =MeMin+Mden*H28+P28 -> 3.0821988 | R28: =I$4+Mseal*AN28/40+Mhatch*AO28/30+Mtemp*(AP28-14.5) -> 2.8 | S28: =J$4 -> 0.3 | T28: =K$4+MSSLNRKWq*AQ28 -> 0.3 | U28: =L$4+MSSLNRKWq*AQ28 -> 0.3 | V28: =M$4 -> 0.3 | W28: =N$4 -> 0.3 | X28: =Q28+R29+S30+T31+U32+V33 -> 7.0821988 | Y28: =IF(UseRetro,RetroF,Ftest*ER!$D35+AS28) -> 0.3 | Z28: =Ssum*J28*EXP(-J$5*$Y28)*J$6 -> 14368.669 | AA28: =Ssum*K28*EXP(-K$5*$Y28)*K$6 -> 18236.501 | AB28: =Ssum*L28*EXP(-L$5*$Y28)*L$6 -> 12131.727 | AC28: =Ssum*M28*EXP(-M$5*$Y28)*M$6 -> 531.17759 | AD28: =Ssum*N28*EXP(-N$5*$Y28)*N$6 -> 2.787273 | AE28: =(1-EXP(-J$5*$Y28))*J28 -> 6630.1686 | AF28: =(1-EXP(-K$5*$Y28))*K28 -> 46233.338 | AG28: =(1-EXP(-L$5*$Y28))*L28 -> 7469.8903 | AH28: =(1-EXP(-M$5*$Y28))*M28 -> 312.85717 | AI28: =(1-EXP(-N$5*$Y28))*N28 -> 1.6252534 | AJ28: =G28 -> 1993 | AK28: =SUM(AE28:AI28) -> 60647.879 | AL28: =SUM(Z28:AD28) -> 45270.863 | AM28: =AK28/(AK28+AL28) -> 0.57258874 | AN28: 35.407846 | AO28: 22.782777 | AP28: 16.461 | AQ28: =stressors!U23/stressors!U$49 -> 0.37865475 | AR28: =CHOOSE(stockcode,Esc!F43,Esc!G43,Esc!H43,Esc!I43,Esc!J43,Esc!K43,Esc!L43,Esc!M43,Esc!N42,Esc!O42,Esc!P42) -> 43757.978 | AS28: 0 | AT28: =AJ28 -> 1993 | AU28: 10000 | AV28: =AU27*J28/I27 -> 608.10063 | AW28: =AV27*K28/J27 -> 389.0884 | AX28: =AW27*L28/K27 -> 164.4229 | AY28: =AX27*M28/L27 -> 4.7825718 | AZ28: =AY27*N28/M27 -> 0.02624731 | BA28: =AV28*Z28/J28 -> 38.948483 | BB28: =AW28*AA28/K28 -> 39.777641 | BC28: =AX28*AB28/L28 -> 69.211012 | BD28: =AY28*AC28/M28 -> 2.1045517 | BE28: =AZ28*AD28/N28 -> 0.011666691 | BF28: =AV28*AE28/J28 -> 17.97209 | BG28: =AW28*AF28/K28 -> 100.84462 | BH28: =AX28*AG28/L28 -> 42.615421 | BI28: =AY28*AH28/M28 -> 1.2395555 | BJ28: =AZ28*AI28/N28 -> 0.0068028246 | BK28: =AT28-2 -> 1991 | BL28: =(AE28+AF29+AG30+AH31+AI32)/(AE28+AF29+AG30+AH31+AI32+Z28+AA29+AB30+AC31+AD32) -> 0.49546923 | BM28: =AT28 -> 1993 | BN28: =BF29 -> 17.97209 | BO28: =BG30 -> 78.395001 | BP28: =BH31 -> 35.708737 | BQ28: =BI32 -> 1.0355773 | BR28: =BJ33 -> 0.0057261964 | BS28: =BA29 -> 38.948483 | BT28: =BB30 -> 42.875688 | BU28: =BC31 -> 80.411724 | BV28: =BD32 -> 2.6854612 | BW28: =BE33 -> 0.016659621 | BX28: =BY28*EXP(J$4)+BN28+BS28/Ssum -> 608.10063 | BY28: =BZ28*EXP(K$4)+BO28+BT28/Ssum -> 389.0884 | BZ28: =CA28*EXP(L$4)+BP28+BU28/Ssum -> 177.22884 | CA28: =CB28*EXP(M$4)+BQ28+BV28/Ssum -> 5.5565556 | CB28: =BR28+BW28/Ssum -> 0.033492232 | CC28: =BX28/AU28 -> 0.060810063
A29: Equilibrium catch vs F | G29: 1994 | H29: =SUMPRODUCT(J$7:N$7,Z29:AD29) -> 86404032 | I29: =IF(LHT=1,H28*EXP(-Q28),H27*EXP(-Q27)) -> 2711509.4 | J29: =I28*EXP(-R28-I$5*$Y28)*(1-I$6) -> 150222.31 | K29: =J28*EXP(-S28-J$5*$Y28)*(1-J$6) -> 143540.44 | L29: =K28*EXP(-T28-K$5*$Y28)*(1-K$6) -> 75381.507 | M29: =L28*EXP(-U28-L$5*$Y28)*(1-L$6) -> 838.31828 | N29: =M28*EXP(-V28-M$5*$Y28)*(1-M$6) -> 6.6246808 | O29: 1.213154 | P29: =O29-1 -> 0.21315403 | Q29: =MeMin+Mden*H29+P29 -> 4.1380922 | R29: =I$4+Mseal*AN29/40+Mhatch*AO29/30+Mtemp*(AP29-14.5) -> 2.8 | S29: =J$4 -> 0.3 | T29: =K$4+MSSLNRKWq*AQ29 -> 0.3 | U29: =L$4+MSSLNRKWq*AQ29 -> 0.3 | V29: =M$4 -> 0.3 | W29: =N$4 -> 0.3 | X29: =Q29+R30+S31+T32+U33+V34 -> 8.1380922 | Y29: =IF(UseRetro,RetroF,Ftest*ER!$D36+AS29) -> 0.3 | Z29: =Ssum*J29*EXP(-J$5*$Y29)*J$6 -> 9621.6495 | AA29: =Ssum*K29*EXP(-K$5*$Y29)*K$6 -> 14674.558 | AB29: =Ssum*L29*EXP(-L$5*$Y29)*L$6 -> 31730.558 | AC29: =Ssum*M29*EXP(-M$5*$Y29)*M$6 -> 368.89863 | AD29: =Ssum*N29*EXP(-N$5*$Y29)*N$6 -> 2.9446105 | AE29: =(1-EXP(-J$5*$Y29))*J29 -> 4439.7402 | AF29: =(1-EXP(-K$5*$Y29))*K29 -> 37203.067 | AG29: =(1-EXP(-L$5*$Y29))*L29 -> 19537.513 | AH29: =(1-EXP(-M$5*$Y29))*M29 -> 217.27682 | AI29: =(1-EXP(-N$5*$Y29))*N29 -> 1.7169966 | AJ29: =G29 -> 1994 | AK29: =SUM(AE29:AI29) -> 61399.314 | AL29: =SUM(Z29:AD29) -> 56398.608 | AM29: =AK29/(AK29+AL29) -> 0.52122578 | AN29: 37.114527 | AO29: 24.666446 | AP29: 16.315 | AQ29: =stressors!U24/stressors!U$49 -> 0.39280696 | AR29: =CHOOSE(stockcode,Esc!F44,Esc!G44,Esc!H44,Esc!I44,Esc!J44,Esc!K44,Esc!L44,Esc!M44,Esc!N43,Esc!O43,Esc!P43) -> 65814.376 | AS29: 0 | AT29: =AJ29 -> 1994 | AU29: 10000 | AV29: =AU28*J29/I28 -> 608.10063 | AW29: =AV28*K29/J28 -> 389.0884 | AX29: =AW28*L29/K28 -> 164.4229 | AY29: =AX28*M29/L28 -> 4.7825718 | AZ29: =AY28*N29/M28 -> 0.02624731 | BA29: =AV29*Z29/J29 -> 38.948483 | BB29: =AW29*AA29/K29 -> 39.777641 | BC29: =AX29*AB29/L29 -> 69.211012 | BD29: =AY29*AC29/M29 -> 2.1045517 | BE29: =AZ29*AD29/N29 -> 0.011666691 | BF29: =AV29*AE29/J29 -> 17.97209 | BG29: =AW29*AF29/K29 -> 100.84462 | BH29: =AX29*AG29/L29 -> 42.615421 | BI29: =AY29*AH29/M29 -> 1.2395555 | BJ29: =AZ29*AI29/N29 -> 0.0068028246 | BK29: =AT29-2 -> 1992 | BL29: =(AE29+AF30+AG31+AH32+AI33)/(AE29+AF30+AG31+AH32+AI33+Z29+AA30+AB31+AC32+AD33) -> 0.44661913 | BM29: =AT29 -> 1994 | BN29: =BF30 -> 13.529487 | BO29: =BG31 -> 78.985174 | BP29: =BH32 -> 33.27886 | BQ29: =BI33 -> 0.97527715 | BR29: =BJ34 -> 0.0054400476 | BS29: =BA30 -> 39.241695 | BT29: =BB31 -> 43.198465 | BU29: =BC32 -> 82.55048 | BV29: =BD33 -> 2.8090672 | BW29: =BE34 -> 0.017756256 | BX29: =BY29*EXP(J$4)+BN29+BS29/Ssum -> 608.10063 | BY29: =BZ29*EXP(K$4)+BO29+BT29/Ssum -> 392.01753 | BZ29: =CA29*EXP(L$4)+BP29+BU29/Ssum -> 178.56306 | CA29: =CB29*EXP(M$4)+BQ29+BV29/Ssum -> 5.7043465 | CB29: =BR29+BW29/Ssum -> 0.035033807 | CC29: =BX29/AU29 -> 0.060810063
B30: =AK79 -> 1815.2356 | G30: 1995 | H30: =SUMPRODUCT(J$7:N$7,Z30:AD30) -> 73537480 | I30: =IF(LHT=1,H29*EXP(-Q29),H28*EXP(-Q28)) -> 2428404.5 | J30: =I29*EXP(-R29-I$5*$Y29)*(1-I$6) -> 164887.06 | K30: =J29*EXP(-S29-J$5*$Y29)*(1-J$6) -> 96118.561 | L30: =K29*EXP(-T29-K$5*$Y29)*(1-K$6) -> 60658.032 | M30: =L29*EXP(-U29-L$5*$Y29)*(1-L$6) -> 2192.6232 | N30: =M29*EXP(-V29-M$5*$Y29)*(1-M$6) -> 4.6007883 | O30: 1.1191617 | P30: =O30-1 -> 0.11916167 | Q30: =MeMin+Mden*H30+P30 -> 3.8364816 | R30: =I$4+Mseal*AN30/40+Mhatch*AO30/30+Mtemp*(AP30-14.5) -> 2.8 | S30: =J$4 -> 0.3 | T30: =K$4+MSSLNRKWq*AQ30 -> 0.3 | U30: =L$4+MSSLNRKWq*AQ30 -> 0.3 | V30: =M$4 -> 0.3 | W30: =N$4 -> 0.3 | X30: =Q30+R31+S32+T33+U34+V35 -> 7.8364816 | Y30: =IF(UseRetro,RetroF,Ftest*ER!$D37+AS30) -> 0.225 | Z30: =Ssum*J30*EXP(-J$5*$Y30)*J$6 -> 10640.422 | AA30: =Ssum*K30*EXP(-K$5*$Y30)*K$6 -> 10591.808 | AB30: =Ssum*L30*EXP(-L$5*$Y30)*L$6 -> 27521.575 | AC30: =Ssum*M30*EXP(-M$5*$Y30)*M$6 -> 1040.002 | AD30: =Ssum*N30*EXP(-N$5*$Y30)*N$6 -> 2.2042824 | AE30: =(1-EXP(-J$5*$Y30))*J30 -> 3668.533 | AF30: =(1-EXP(-K$5*$Y30))*K30 -> 19366.331 | AG30: =(1-EXP(-L$5*$Y30))*L30 -> 12221.61 | AH30: =(1-EXP(-M$5*$Y30))*M30 -> 441.77801 | AI30: =(1-EXP(-N$5*$Y30))*N30 -> 0.92698422 | AJ30: =G30 -> 1995 | AK30: =SUM(AE30:AI30) -> 35699.179 | AL30: =SUM(Z30:AD30) -> 49796.012 | AM30: =AK30/(AK30+AL30) -> 0.41755774 | AN30: 38.50714 | AO30: 20.354689 | AP30: 15.488 | AQ30: =stressors!U25/stressors!U$49 -> 0.4102972 | AR30: =CHOOSE(stockcode,Esc!F45,Esc!G45,Esc!H45,Esc!I45,Esc!J45,Esc!K45,Esc!L45,Esc!M45,Esc!N44,Esc!O44,Esc!P44) -> 52326.452 | AS30: 0 | AT30: =AJ30 -> 1995 | AU30: 10000 | AV30: =AU29*J30/I29 -> 608.10063 | AW30: =AV29*K30/J29 -> 389.0884 | AX30: =AW29*L30/K29 -> 164.4229 | AY30: =AX29*M30/L29 -> 4.7825718 | AZ30: =AY29*N30/M29 -> 0.02624731 | BA30: =AV30*Z30/J30 -> 39.241695 | BB30: =AW30*AA30/K30 -> 42.875688 | BC30: =AX30*AB30/L30 -> 74.601453 | BD30: =AY30*AC30/M30 -> 2.2684629 | BE30: =AZ30*AD30/N30 -> 0.012575342 | BF30: =AV30*AE30/J30 -> 13.529487 | BG30: =AW30*AF30/K30 -> 78.395001 | BH30: =AX30*AG30/L30 -> 33.128548 | BI30: =AY30*AH30/M30 -> 0.96361064 | BJ30: =AZ30*AI30/N30 -> 0.0052884073 | BK30: =AT30-2 -> 1993 | BL30: =(AE30+AF31+AG32+AH33+AI34)/(AE30+AF31+AG32+AH33+AI34+Z30+AA31+AB32+AC33+AD34) -> 0.4303388 | BM30: =AT30 -> 1995 | BN30: =BF31 -> 13.529487 | BO30: =BG32 -> 73.060447 | BP30: =BH33 -> 31.106904 | BQ30: =BI34 -> 0.91961766 | BR30: =BJ35 -> 0.005162293 | BS30: =BA31 -> 39.241695 | BT30: =BB32 -> 44.016077 | BU30: =BC33 -> 85.704898 | BV30: =BD34 -> 2.9716058 | BW30: =BE35 -> 0.019139187 | BX30: =BY30*EXP(J$4)+BN30+BS30/Ssum -> 608.10063 | BY30: =BZ30*EXP(K$4)+BO30+BT30/Ssum -> 392.01753 | BZ30: =CA30*EXP(L$4)+BP30+BU30/Ssum -> 181.9427 | CA30: =CB30*EXP(M$4)+BQ30+BV30/Ssum -> 5.922321 | CB30: =BR30+BW30/Ssum -> 0.037060938 | CC30: =BX30/AU30 -> 0.060810063
A31: 0 | B31: 0 | G31: 1996 | H31: =SUMPRODUCT(J$7:N$7,Z31:AD31) -> 59572786 | I31: =IF(LHT=1,H30*EXP(-Q30),H29*EXP(-Q29)) -> 1378425.9 | J31: =I30*EXP(-R30-I$5*$Y30)*(1-I$6) -> 147671.43 | K31: =J30*EXP(-S30-J$5*$Y30)*(1-J$6) -> 106295.92 | L31: =K30*EXP(-T30-K$5*$Y30)*(1-K$6) -> 43781.777 | M31: =L30*EXP(-U30-L$5*$Y30)*(1-L$6) -> 1901.777 | N31: =M30*EXP(-V30-M$5*$Y30)*(1-M$6) -> 12.97058 | O31: 1.3409606 | P31: =O31-1 -> 0.34096063 | Q31: =MeMin+Mden*H31+P31 -> 3.8329424 | R31: =I$4+Mseal*AN31/40+Mhatch*AO31/30+Mtemp*(AP31-14.5) -> 2.8 | S31: =J$4 -> 0.3 | T31: =K$4+MSSLNRKWq*AQ31 -> 0.3 | U31: =L$4+MSSLNRKWq*AQ31 -> 0.3 | V31: =M$4 -> 0.3 | W31: =N$4 -> 0.3 | X31: =Q31+R32+S33+T34+U35+V36 -> 7.8329424 | Y31: =IF(UseRetro,RetroF,Ftest*ER!$D38+AS31) -> 0.225 | Z31: =Ssum*J31*EXP(-J$5*$Y31)*J$6 -> 9529.4711 | AA31: =Ssum*K31*EXP(-K$5*$Y31)*K$6 -> 11713.304 | AB31: =Ssum*L31*EXP(-L$5*$Y31)*L$6 -> 19864.533 | AC31: =Ssum*M31*EXP(-M$5*$Y31)*M$6 -> 902.04825 | AD31: =Ssum*N31*EXP(-N$5*$Y31)*N$6 -> 6.2143311 | AE31: =(1-EXP(-J$5*$Y31))*J31 -> 3285.5067 | AF31: =(1-EXP(-K$5*$Y31))*K31 -> 21416.904 | AG31: =(1-EXP(-L$5*$Y31))*L31 -> 8821.3179 | AH31: =(1-EXP(-M$5*$Y31))*M31 -> 383.17721 | AI31: =(1-EXP(-N$5*$Y31))*N31 -> 2.6133615 | AJ31: =G31 -> 1996 | AK31: =SUM(AE31:AI31) -> 33909.519 | AL31: =SUM(Z31:AD31) -> 42015.571 | AM31: =AK31/(AK31+AL31) -> 0.4466181 | AN31: 39.570878 | AO31: 25.425556 | AP31: 16.018 | AQ31: =stressors!U26/stressors!U$49 -> 0.42394207 | AR31: =CHOOSE(stockcode,Esc!F46,Esc!G46,Esc!H46,Esc!I46,Esc!J46,Esc!K46,Esc!L46,Esc!M46,Esc!N45,Esc!O45,Esc!P45) -> 41132.629 | AS31: 0 | AT31: =AJ31 -> 1996 | AU31: 10000 | AV31: =AU30*J31/I30 -> 608.10063 | AW31: =AV30*K31/J30 -> 392.01753 | AX31: =AW30*L31/K30 -> 177.22884 | AY31: =AX30*M31/L30 -> 5.1550583 | AZ31: =AY30*N31/M30 -> 0.02829156 | BA31: =AV31*Z31/J31 -> 39.241695 | BB31: =AW31*AA31/K31 -> 43.198465 | BC31: =AX31*AB31/L31 -> 80.411724 | BD31: =AY31*AC31/M31 -> 2.4451402 | BE31: =AZ31*AD31/N31 -> 0.013554762 | BF31: =AV31*AE31/J31 -> 13.529487 | BG31: =AW31*AF31/K31 -> 78.985174 | BH31: =AX31*AG31/L31 -> 35.708737 | BI31: =AY31*AH31/M31 -> 1.0386606 | BJ31: =AZ31*AI31/N31 -> 0.0057002904 | BK31: =AT31-2 -> 1994 | BL31: =(AE31+AF32+AG33+AH34+AI35)/(AE31+AF32+AG33+AH34+AI35+Z31+AA32+AB33+AC34+AD35) -> 0.40823059 | BM31: =AT31 -> 1996 | BN31: =BF32 -> 12.41362 | BO31: =BG33 -> 67.14937 | BP31: =BH34 -> 28.840801 | BQ31: =BI35 -> 0.85806173 | BR31: =BJ36 -> 0.0054712432 | BS31: =BA32 -> 39.315342 | BT31: =BB33 -> 44.933336 | BU31: =BC34 -> 89.146848 | BV31: =BD35 -> 3.1494488 | BW31: =BE36 -> 0.020284619 | BX31: =BY31*EXP(J$4)+BN31+BS31/Ssum -> 608.10063 | BY31: =BZ31*EXP(K$4)+BO31+BT31/Ssum -> 392.75325 | BZ31: =CA31*EXP(L$4)+BP31+BU31/Ssum -> 185.73423 | CA31: =CB31*EXP(M$4)+BQ31+BV31/Ssum -> 6.1601642 | CB31: =BR31+BW31/Ssum -> 0.039278941 | CC31: =BX31/AU31 -> 0.060810063
