Workbook

Sheet runsize correlations
B1: Swift | C1: Fraser | D1: Horsey | E1: Nevin | F1: Holmes | G1: McKale | H1: Twin | I1: Goat | J1: Morkill | K1: Walker | L1: Torpy | M1: Dome | N1: Slim | O1: Bowron | P1: McGregor | Q1: Willow | R1: Salmon (PG) | S1: Stuart | T1: Nechako | U1: Stellako | V1: Endako | W1: Chilako | X1: Blackwater | Y1: Cottonwood | Z1: Quesnel | AA1: Cariboo | AB1: Horsefly | AC1: Chilko | AD1: Chilcotin Upper | AE1: Chilcotin Lower | AF1: Elkin | AG1: Taseko | AH1: Bridge | AI1: Portage | AJ1: Seton | AK1: Mahood | AL1: Clearwater | AM1: Finn | AN1: Raft | AO1: Barriere | AP1: Louis | AQ1: North Thompson | AR1: Bessette | AS1: Middle Shuswap | AT1: Lower Shuswap | AU1: Eagle | AV1: Salmon (ST) | AW1: Adams | AX1: Little River | AY1: South Thompson | AZ1: Lower Thompson | BA1: Deadman | BB1: Bonaparte | BC1: Coldwater | BD1: Spius | BE1: Nicola | BF1: Nahatlatch | BG1: Maria Slough | BH1: Birkenhead | BI1: Harrison | BJ1: Chilliwack | BK1: Pitt | BL1: Blue | BM1: Lemieux | BN1: Upper Adams | BO1: Scotch | BP1: Seymour | BQ1: Stave | BR1: Baker | BS1: Big Silver | BT1: Chilliwack Su | BU1: Douglas | BV1: Holliday | BW1: Kazchek | BX1: Kuzkwa | BY1: Narcosli | BZ1: Naver | CA1: Pinchi | CB1: Sloquet | CC1: Small | CD1: Tipella | CE1: Wap | CF1: McKinley | CG1: Chehalis
A2: Swift | B2: 1
A3: Fraser | B3: 0.56823523 | C3: 1
A4: Horsey | B4: 0.64277759 | C4: 0.57345515 | D4: 1
A5: Nevin | B5: 0.34626463 | C5: 0.082300863 | D5: 0.56512037 | E5: 1
A6: Holmes | B6: 0.79491613 | C6: 0.51529261 | D6: 0.80284853 | E6: 0.59863498 | F6: 1
A7: McKale | B7: 0.25622877 | C7: 0.14318264 | D7: 0.32307574 | E7: 0.47215505 | F7: 0.41339165 | G7: 1
A8: Twin | B8: 0.25388556 | C8: 0.012193053 | D8: 0.38120874 | E8: 0.72806786 | F8: 0.48604877 | G8: 0.5319939 | H8: 1
A9: Goat | B9: 0.57891484 | C9: 0.19148808 | D9: 0.5572776 | E9: 0.53585425 | F9: 0.68162347 | G9: 0.45998575 | H9: 0.45912941 | I9: 1
A10: Morkill | B10: 0.42152621 | C10: 0.12332657 | D10: 0.15851329 | E10: 0.31268629 | F10: 0.34416417 | G10: 0.24035407 | H10: 0.4221087 | I10: 0.041720778 | J10: 1
A11: Walker | B11: 0.48672523 | C11: 0.36769089 | D11: 0.53444049 | E11: 0.49801073 | F11: 0.62289279 | G11: 0.29814234 | H11: 0.51208534 | I11: 0.29100501 | J11: 0.49760392 | K11: 1
A12: Torpy | B12: 0.51369292 | C12: 0.34574889 | D12: 0.62386583 | E12: 0.77607709 | F12: 0.71821937 | G12: 0.4083777 | H12: 0.61187386 | I12: 0.55058853 | J12: 0.52230354 | K12: 0.65303758 | L12: 1
A13: Dome | B13: 0.62798146 | C13: 0.33417816 | D13: 0.39704862 | E13: 0.25677396 | F13: 0.61817888 | G13: 0.19875143 | H13: 0.21667684 | I13: 0.51509204 | J13: 0.34635645 | K13: 0.18919109 | L13: 0.41389618 | M13: 1
A14: Slim | B14: 0.59109182 | C14: 0.65349977 | D14: 0.59753144 | E14: 0.37925704 | F14: 0.6528457 | G14: 0.33612892 | H14: 0.2716247 | I14: 0.29716657 | J14: 0.33345154 | K14: 0.58721179 | L14: 0.52230913 | M14: 0.34655466 | N14: 1
A15: Bowron | B15: 0.55198476 | C15: 0.54222182 | D15: 0.65378429 | E15: 0.51896078 | F15: 0.69075651 | G15: 0.29872951 | H15: 0.31478233 | I15: 0.34335976 | J15: 0.51029303 | K15: 0.49601258 | L15: 0.71747878 | M15: 0.4694073 | N15: 0.67716165 | O15: 1
A16: McGregor | B16: 0.63069026 | C16: 0.37218057 | D16: 0.58274162 | E16: 0.53135279 | F16: 0.73770984 | G16: 0.30242411 | H16: 0.46670014 | I16: 0.45554792 | J16: 0.54137471 | K16: 0.74708705 | L16: 0.7757373 | M16: 0.49005062 | N16: 0.51726808 | O16: 0.61866712 | P16: 1
A17: Willow | B17: 0.44182205 | C17: 0.29244457 | D17: 0.37531178 | E17: 0.44234814 | F17: 0.5219674 | G17: 0.34626578 | H17: 0.3897326 | I17: 0.24515936 | J17: 0.45153994 | K17: 0.40665656 | L17: 0.52198407 | M17: 0.31301923 | N17: 0.62202453 | O17: 0.58649577 | P17: 0.50097214 | Q17: 1
A18: Salmon (PG) | B18: 0.32910102 | C18: 0.11313942 | D18: 0.33955107 | E18: 0.73547126 | F18: 0.46483871 | G18: 0.32962546 | H18: 0.55150303 | I18: 0.46140977 | J18: 0.19736419 | K18: 0.40433459 | L18: 0.62179867 | M18: 0.23392618 | N18: 0.3133894 | O18: 0.3566196 | P18: 0.4224823 | Q18: 0.59824424 | R18: 1
A19: Stuart | B19: 0.34249668 | C19: 0.097329377 | D19: 0.16366245 | E19: 0.18263281 | F19: 0.43638249 | G19: 0.023653559 | H19: 0.18253045 | I19: 0.28351464 | J19: 0.36301228 | K19: 0.24074042 | L19: 0.38872394 | M19: 0.54384748 | N19: 0.25654867 | O19: 0.2546106 | P19: 0.48447597 | Q19: 0.19528474 | R19: 0.12028929 | S19: 1
A20: Nechako | B20: -0.087607565 | C20: -0.11343066 | D20: 0.076991074 | E20: 0.32612139 | F20: -0.051341512 | G20: 0.11536595 | H20: 0.1280544 | I20: 0.17697049 | J20: -0.10967549 | K20: -0.038893371 | L20: 0.15918726 | M20: -0.13301056 | N20: 0.053292156 | O20: 0.024767993 | P20: 0.021622245 | Q20: 0.1636048 | R20: 0.32959892 | S20: 0.055891108 | T20: 1
A21: Stellako | B21: 0.087857927 | C21: 0.14952256 | D21: -0.0083803917 | E21: -0.023863798 | F21: 0.067291037 | G21: 0.24914086 | H21: 0.049941447 | I21: -0.035455386 | J21: 0.10901102 | K21: 0.20846135 | L21: 0.0946997 | M21: 0.092706373 | N21: 0.23798039 | O21: 0.092681494 | P21: 0.21951121 | Q21: 0.16907258 | R21: 0.073780192 | S21: 0.020856638 | T21: -0.034209961 | U21: 1
A22: Endako | B22: 0.35345601 | C22: 0.33805434 | D22: 0.50746147 | E22: 0.29723313 | F22: 0.37631223 | G22: 0.24819194 | H22: 0.32189139 | I22: 0.33324375 | J22: 0.24861988 | K22: 0.44496705 | L22: 0.4877848 | M22: 0.10098221 | N22: 0.42880273 | O22: 0.54173681 | P22: 0.39210355 | Q22: 0.35117617 | R22: 0.30486673 | S22: 0.063690054 | T22: 0.2502853 | U22: 0.24883282 | V22: 1
A23: Chilako | B23: 0.3544713 | C23: 0.24575454 | D23: 0.15362419 | E23: 0.071727896 | F23: 0.28259963 | G23: 0.16945405 | H23: 0.11356947 | I23: 0.27891995 | J23: 0.044987059 | K23: 0.22920627 | L23: 0.20755312 | M23: 0.22393375 | N23: 0.43084349 | O23: 0.08740238 | P23: 0.21959133 | Q23: 0.26919702 | R23: 0.30791974 | S23: 0.23739917 | T23: 0.21092871 | U23: 0.44074107 | V23: 0.10519819 | W23: 1
A24: Blackwater | B24: 0.6778599 | C24: 0.68386737 | D24: 0.5425171 | E24: 0.094571748 | F24: 0.5805357 | G24: -0.037718508 | H24: 0.00628419 | I24: 0.16510808 | J24: 0.29057655 | K24: 0.34100347 | L24: 0.31262952 | M24: 0.47836643 | N24: 0.61048949 | O24: 0.6232138 | P24: 0.41199629 | Q24: 0.34316279 | R24: 0.18069366 | S24: 0.17391993 | T24: -0.27743383 | U24: 0.099292753 | V24: 0.28422607 | W24: 0.28622721 | X24: 1
A25: Cottonwood | B25: 0.61902948 | C25: 0.22548772 | D25: 0.48379363 | E25: 0.27730019 | F25: 0.60247315 | G25: 0.1805179 | H25: 0.15448559 | I25: 0.33226312 | J25: 0.51242317 | K25: 0.22215286 | L25: 0.41385 | M25: 0.739512 | N25: 0.23492354 | O25: 0.62179047 | P25: 0.49646083 | Q25: 0.36227534 | R25: 0.15794886 | S25: 0.25656897 | T25: -0.26461949 | U25: 0.0512868 | V25: 0.1286713 | W25: 0.021357548 | X25: 0.56024868 | Y25: 1
A26: Quesnel | B26: 0.6380854 | C26: 0.50695665 | D26: 0.49974494 | E26: 0.34284367 | F26: 0.70311642 | G26: 0.25402859 | H26: 0.18799588 | I26: 0.29976774 | J26: 0.40851271 | K26: 0.57847196 | L26: 0.59853092 | M26: 0.47520664 | N26: 0.72434681 | O26: 0.71675996 | P26: 0.55869216 | Q26: 0.4813176 | R26: 0.21169469 | S26: 0.36878477 | T26: -0.020558753 | U26: 0.21267221 | V26: 0.36536897 | W26: 0.31994072 | X26: 0.50550785 | Y26: 0.47016176 | Z26: 1
A27: Cariboo | B27: 0.60979495 | C27: 0.49438958 | D27: 0.51257828 | E27: 0.21550088 | F27: 0.68016264 | G27: 0.22316076 | H27: 0.1571042 | I27: 0.24819818 | J27: 0.29032566 | K27: 0.33270503 | L27: 0.41582978 | M27: 0.61728992 | N27: 0.55270992 | O27: 0.57015459 | P27: 0.43053226 | Q27: 0.38720639 | R27: 0.1168154 | S27: 0.3904265 | T27: -0.16614915 | U27: 0.028171968 | V27: 0.1727453 | W27: 0.29623979 | X27: 0.67096964 | Y27: 0.63394645 | Z27: 0.69447808 | AA27: 1
A28: Horsefly | B28: 0.14791297 | C28: 0.25658609 | D28: 0.21195197 | E28: 0.0045858479 | F28: 0.12749051 | G28: 0.20961006 | H28: -0.0044164824 | I28: 0.12905665 | J28: 0.19556234 | K28: 0.011183974 | L28: 0.14191405 | M28: 0.33871434 | N28: 0.14854721 | O28: 0.33456739 | P28: 0.04862171 | Q28: 0.16122126 | R28: 0.070522119 | S28: -0.00052685791 | T28: -0.12351084 | U28: 0.042490252 | V28: 0.065372453 | W28: 0.12838359 | X28: 0.48186984 | Y28: 0.44375139 | Z28: 0.043708045 | AA28: 0.3787731 | AB28: 1
A29: Chilko | B29: 0.48669497 | C29: 0.019473522 | D29: 0.27671109 | E29: 0.65202935 | F29: 0.5859104 | G29: 0.34163856 | H29: 0.41944971 | I29: 0.6149175 | J29: 0.30598418 | K29: 0.30830607 | L29: 0.60661586 | M29: 0.48585716 | N29: 0.27303904 | O29: 0.39394583 | P29: 0.56170482 | Q29: 0.5087628 | R29: 0.72012338 | S29: 0.44307493 | T29: 0.3073393 | U29: 0.016865376 | V29: 0.19342506 | W29: 0.2318448 | X29: 0.11494464 | Y29: 0.39286398 | Z29: 0.38362837 | AA29: 0.2651044 | AB29: -0.072877255 | AC29: 1
A30: Chilcotin Upper | B30: 0.75070699 | C30: 0.33460786 | D30: 0.5707352 | E30: 0.49068389 | F30: 0.76874788 | G30: 0.20435418 | H30: 0.39740573 | I30: 0.65786903 | J30: 0.39140703 | K30: 0.57668365 | L30: 0.69373468 | M30: 0.58982027 | N30: 0.47638892 | O30: 0.55820322 | P30: 0.66584703 | Q30: 0.51429912 | R30: 0.55881689 | S30: 0.4124724 | T30: -0.046139444 | U30: 0.089904544 | V30: 0.38300827 | W30: 0.45161577 | X30: 0.50222229 | Y30: 0.59046597 | Z30: 0.60617265 | AA30: 0.57983906 | AB30: 0.1934469 | AC30: 0.6396151 | AD30: 1
A31: Chilcotin Lower | B31: 0.41816415 | C31: 0.42014043 | D31: 0.38563994 | E31: 0.170834 | F31: 0.49472685 | G31: 0.14365919 | H31: 0.028193084 | I31: 0.24330113 | J31: 0.31813473 | K31: 0.19793226 | L31: 0.3416647 | M31: 0.66152081 | N31: 0.38383009 | O31: 0.5581196 | P31: 0.32806874 | Q31: 0.45807908 | R31: 0.35654937 | S31: 0.32014535 | T31: -0.042131702 | U31: 0.12370984 | V31: 0.23022228 | W31: 0.12203045 | X31: 0.55287342 | Y31: 0.61655062 | Z31: 0.3936454 | AA31: 0.50820293 | AB31: 0.50300376 | AC31: 0.3112668 | AD31: 0.46398449 | AE31: 1
A32: Elkin | B32: 0.37188977 | C32: -0.018014807 | D32: 0.21032172 | E32: 0.45439623 | F32: 0.40696438 | G32: 0.18906704 | H32: 0.26990098 | I32: 0.44340501 | J32: 0.18392162 | K32: 0.09153676 | L32: 0.34902045 | M32: 0.47013396 | N32: 0.19665088 | O32: 0.28389131 | P32: 0.32364872 | Q32: 0.32413986 | R32: 0.4725511 | S32: 0.38931925 | T32: 0.48619139 | U32: -0.029808282 | V32: 0.23417057 | W32: 0.22729675 | X32: 0.17084687 | Y32: 0.33374968 | Z32: 0.27035483 | AA32: 0.27781806 | AB32: 0.034871482 | AC32: 0.7357615 | AD32: 0.40983807 | AE32: 0.25859951 | AF32: 1
A33: Taseko | B33: -0.39950212 | C33: -0.3455908 | D33: -0.24834695 | E33: 0.068308765 | F33: -0.33230989 | G33: 0.16867075 | H33: 0.23728816 | I33: -0.054625983 | J33: -0.1099777 | K33: -0.24081466 | L33: -0.21897866 | M33: -0.28170402 | N33: -0.30917285 | O33: -0.30831571 | P33: -0.3257829 | Q33: -0.12092668 | R33: -0.05994114 | S33: -0.1468889 | T33: 0.39077967 | U33: -0.15616669 | V33: -0.09122734 | W33: -0.19847833 | X33: -0.51114502 | Y33: -0.38047824 | Z33: -0.43867727 | AA33: -0.42703616 | AB33: -0.16716666 | AC33: -0.095966382 | AD33: -0.49101729 | AE33: -0.33750951 | AF33: 0.054331561 | AG33: 1
A34: Bridge | B34: 0.54522189 | C34: 0.2013117 | D34: 0.37169312 | E34: 0.35647085 | F34: 0.61982347 | G34: 0.19082959 | H34: 0.19728657 | I34: 0.45414739 | J34: 0.13015379 | K34: 0.26616312 | L34: 0.40143333 | M34: 0.5063458 | N34: 0.2675478 | O34: 0.42605544 | P34: 0.54649014 | Q34: 0.48260066 | R34: 0.49537376 | S34: 0.30609121 | T34: 0.0036650916 | U34: 0.049162205 | V34: 0.14558763 | W34: 0.13087316 | X34: 0.30700187 | Y34: 0.53194172 | Z34: 0.40996355 | AA34: 0.35586164 | AB34: 0.0054681022 | AC34: 0.71537279 | AD34: 0.58946569 | AE34: 0.45173834 | AF34: 0.50061387 | AG34: -0.37344517 | AH34: 1
A35: Portage | B35: 0.34193364 | C35: 0.3864488 | D35: 0.20834707 | E35: -0.093859545 | F35: 0.17136039 | G35: 0.04265767 | H35: -0.04577453 | I35: 0.044489538 | J35: -0.086513276 | K35: 0.17222272 | L35: 0.049383454 | M35: 0.0096130522 | N35: 0.14303503 | O35: -0.0004281049 | P35: 0.17764716 | Q35: 0.019744104 | R35: -0.0039298878 | S35: -0.12873208 | T35: 0.053975561 | U35: 0.083375964 | V35: 0.21151343 | W35: 0.35052394 | X35: 0.25423675 | Y35: 0.0019458949 | Z35: 0.23009817 | AA35: 0.3243744 | AB35: 0.017430445 | AC35: -0.065475219 | AD35: 0.24605018 | AE35: -0.084212539 | AF35: -0.039627813 | AG35: -0.37135982 | AH35: 0.0026342919 | AI35: 1
A36: Seton | B36: 0.30147762 | C36: 0.53730318 | D36: 0.26914163 | E36: -0.14534934 | F36: 0.18458609 | G36: -0.15546235 | H36: -0.20116362 | I36: -0.21422803 | J36: 0.14669329 | K36: 0.31900957 | L36: 0.073693835 | M36: 0.016815617 | N36: 0.19700299 | O36: 0.24967641 | P36: 0.22392694 | Q36: -0.010011351 | R36: -0.03720973 | S36: -0.090860493 | T36: -0.20610037 | U36: 0.13660292 | V36: 0.20891457 | W36: 0.21121818 | X36: 0.4513619 | Y36: 0.22266697 | Z36: 0.32942588 | AA36: 0.29220639 | AB36: 0.084843639 | AC36: -0.13624031 | AD36: 0.17866585 | AE36: 0.1163579 | AF36: -0.12471785 | AG36: -0.43521329 | AH36: 0.089981256 | AI36: 0.59037685 | AJ36: 1
A37: Mahood | B37: 0.53957248 | C37: 0.41104288 | D37: 0.54248989 | E37: 0.51314392 | F37: 0.63745256 | G37: 0.26058613 | H37: 0.38467862 | I37: 0.29314535 | J37: 0.26052829 | K37: 0.67059959 | L37: 0.62276276 | M37: 0.12625427 | N37: 0.61321231 | O37: 0.46655541 | P37: 0.57732391 | Q37: 0.5543435 | R37: 0.59381644 | S37: 0.14590982 | T37: 0.062904868 | U37: 0.2250741 | V37: 0.3638041 | W37: 0.46769069 | X37: 0.50382653 | Y37: 0.23937953 | Z37: 0.58881826 | AA37: 0.52563726 | AB37: 0.10734167 | AC37: 0.45864225 | AD37: 0.64532089 | AE37: 0.17171469 | AF37: 0.25599143 | AG37: -0.37348998 | AH37: 0.36759276 | AI37: 0.40945271 | AJ37: 0.39844501 | AK37: 1
A38: Clearwater | B38: 0.6604038 | C38: 0.34744368 | D38: 0.38429888 | E38: 0.38874968 | F38: 0.63994883 | G38: 0.41776364 | H38: 0.29684134 | I38: 0.5041471 | J38: 0.33998182 | K38: 0.43449501 | L38: 0.45773266 | M38: 0.42533563 | N38: 0.64619795 | O38: 0.51620278 | P38: 0.46457916 | Q38: 0.60786979 | R38: 0.43841868 | S38: 0.28427637 | T38: 0.017174489 | U38: 0.0402964 | V38: 0.20654293 | W38: 0.37415468 | X38: 0.42443803 | Y38: 0.43678995 | Z38: 0.59993751 | AA38: 0.5582633 | AB38: 0.20698036 | AC38: 0.62576087 | AD38: 0.68117015 | AE38: 0.33209964 | AF38: 0.43494264 | AG38: -0.29683124 | AH38: 0.57172985 | AI38: 0.13533969 | AJ38: 0.090288237 | AK38: 0.62535387 | AL38: 1
A39: Finn | B39: 0.56230564 | C39: 0.55596997 | D39: 0.40062519 | E39: -0.082848742 | F39: 0.41296196 | G39: 0.038672465 | H39: -0.088266627 | I39: 0.060529076 | J39: 0.28588011 | K39: 0.37307456 | L39: 0.18284181 | M39: 0.1905428 | N39: 0.41732143 | O39: 0.3955797 | P39: 0.39859285 | Q39: 0.28845914 | R39: 0.030894512 | S39: -0.086358197 | T39: -0.19421164 | U39: 0.16146747 | V39: 0.33778754 | W39: 0.17780252 | X39: 0.6798316 | Y39: 0.4576134 | Z39: 0.42190812 | AA39: 0.50357714 | AB39: 0.37704281 | AC39: 0.06114728 | AD39: 0.38684661 | AE39: 0.33750203 | AF39: 0.034188509 | AG39: -0.47754509 | AH39: 0.32141971 | AI39: 0.54943041 | AJ39: 0.65874526 | AK39: 0.5385057 | AL39: 0.4407731 | AM39: 1
A40: Raft | B40: 0.57546319 | C40: 0.43112827 | D40: 0.35658841 | E40: 0.12912972 | F40: 0.50533501 | G40: 0.15254785 | H40: -0.056608915 | I40: 0.27443175 | J40: 0.21836702 | K40: 0.23314742 | L40: 0.33058653 | M40: 0.40486972 | N40: 0.47336445 | O40: 0.46736612 | P40: 0.36942315 | Q40: 0.45496494 | R40: 0.32411261 | S40: 0.14272951 | T40: -0.14239912 | U40: 0.065487936 | V40: 0.31708029 | W40: 0.1460234 | X40: 0.53119223 | Y40: 0.49696188 | Z40: 0.43111349 | AA40: 0.40170642 | AB40: 0.27388669 | AC40: 0.38874351 | AD40: 0.47448728 | AE40: 0.53218795 | AF40: 0.3180866 | AG40: -0.4382862 | AH40: 0.66247484 | AI40: 0.1139478 | AJ40: 0.30037822 | AK40: 0.38006093 | AL40: 0.59891717 | AM40: 0.63072672 | AN40: 1
...

Sheet RunSize_by_Stock
A1: Year | B1: Swift | C1: Fraser | D1: Horsey | E1: Nevin | F1: Holmes | G1: McKale | H1: Twin | I1: Goat | J1: Morkill | K1: Walker | L1: Torpy | M1: Dome | N1: Slim | O1: Bowron | P1: McGregor | Q1: Willow | R1: Salmon (PG) | S1: Stuart | T1: Nechako | U1: Stellako | V1: Endako | W1: Chilako | X1: Blackwater | Y1: Cottonwood | Z1: Quesnel | AA1: Cariboo | AB1: Horsefly | AC1: Chilko | AD1: Chilcotin Upper | AE1: Chilcotin Lower | AF1: Elkin | AG1: Taseko | AH1: Bridge | AI1: Portage | AJ1: Seton | AK1: Mahood | AL1: Clearwater | AM1: Finn | AN1: Raft | AO1: Barriere | AP1: Louis | AQ1: North Thompson | AR1: Bessette | AS1: Middle Shuswap | AT1: Lower Shuswap | AU1: Eagle | AV1: Salmon (ST) | AW1: Adams | AX1: Little River | AY1: South Thompson | AZ1: Lower Thompson | BA1: Deadman | BB1: Bonaparte | BC1: Coldwater | BD1: Spius | BE1: Nicola | BF1: Nahatlatch | BG1: Maria Slough | BH1: Birkenhead | BI1: Harrison | BJ1: Chilliwack | BK1: Pitt | BL1: Blue | BM1: Lemieux | BN1: Upper Adams | BO1: Scotch | BP1: Seymour | BQ1: Stave | BR1: Baker | BS1: Big Silver | BT1: Chilliwack Su | BU1: Douglas | BV1: Holliday | BW1: Kazchek | BX1: Kuzkwa | BY1: Narcosli | BZ1: Naver | CA1: Pinchi | CB1: Sloquet | CC1: Small | CD1: Tipella | CE1: Wap | CF1: McKinley | CG1: Chehalis | CH1: Total
A2: 1979 | B2: 941 | C2: 3564 | D2: 67 | E2: 51 | F2: 1135 | G2: 26 | H2: 64 | I2: 38 | J2: 519 | K2: 497 | L2: 1920 | M2: 510 | N2: 3065 | O2: 3202 | P2: 3747 | Q2: 1649 | R2: 1396 | S2: 1392 | T2: 3231 | U2: 134 | V2: 159 | W2: 709 | X2: 5787 | Y2: 618 | Z2: 1853 | AA2: 710 | AB2: 622 | AC2: 7556 | AD2: 516 | AE2: 4930 | AF2: 387 | AG2: 0 | AH2: 377 | AI2: 430 | AJ2: 118 | AK2: 473 | AL2: 2744 | AM2: 789 | AN2: 302 | AO2: 26 | AP2: 107 | AQ2: 2152 | AR2: 137 | AS2: 1212 | AT2: 31293 | AU2: 609 | AV2: 724 | AW2: 1958 | AX2: 1259 | AY2: 10792 | AZ2: 4742 | BA2: 173 | BB2: 0 | BC2: 2415 | BD2: 403 | BE2: 9690 | BF2: 42 | BG2: 138 | BH2: 572 | BI2: 81653 | BJ2: 72 | BK2: 299 | BL2: 28 | BM2: 0 | BN2: 51 | BO2: 49 | BP2: 22 | BQ2: 288 | BR2: 387 | BS2: 138 | BT2: 1033 | BU2: 8 | BV2: 43 | BW2: 46 | BX2: 139 | BY2: 317 | BZ2: 397 | CA2: 46 | CB2: 37 | CC2: 70 | CD2: 0 | CE2: 21 | CF2: 56 | CG2: 729 | CH2: 210601
A3: 1980 | B3: 516 | C3: 4520 | D3: 30 | E3: 16 | F3: 668 | G3: 5 | H3: 0 | I3: 116 | J3: 564 | K3: 328 | L3: 748 | M3: 291 | N3: 2178 | O3: 2682 | P3: 1047 | Q3: 627 | R3: 555 | S3: 2266 | T3: 2423 | U3: 58 | V3: 58 | W3: 702 | X3: 1960 | Y3: 890 | Z3: 3009 | AA3: 755 | AB3: 393 | AC3: 6454 | AD3: 550 | AE3: 2524 | AF3: 285 | AG3: 0 | AH3: 82 | AI3: 354 | AJ3: 355 | AK3: 194 | AL3: 3320 | AM3: 703 | AN3: 233 | AO3: 17 | AP3: 138 | AQ3: 1098 | AR3: 83 | AS3: 789 | AT3: 9708 | AU3: 286 | AV3: 410 | AW3: 989 | AX3: 1623 | AY3: 12174 | AZ3: 6426 | BA3: 415 | BB3: 125 | BC3: 2278 | BD3: 642 | BE3: 7877 | BF3: 215 | BG3: 231 | BH3: 485 | BI3: 70042 | BJ3: 93 | BK3: 216 | BL3: 23 | BM3: 12 | BN3: 18 | BO3: 27 | BP3: 24 | BQ3: 229 | BR3: 401 | BS3: 32 | BT3: 1201 | BU3: 10 | BV3: 25 | BW3: 3 | BX3: 31 | BY3: 328 | BZ3: 411 | CA3: 11 | CB3: 0 | CC3: 118 | CD3: 0 | CE3: 6 | CF3: 38 | CG3: 848 | CH3: 162615
A4: 1981 | B4: 452 | C4: 2831 | D4: 30 | E4: 8 | F4: 630 | G4: 16 | H4: 16 | I4: 31 | J4: 233 | K4: 222 | L4: 797 | M4: 16 | N4: 2123 | O4: 2351 | P4: 1168 | Q4: 768 | R4: 266 | S4: 213 | T4: 4025 | U4: 36 | V4: 52 | W4: 286 | X4: 3143 | Y4: 459 | Z4: 1307 | AA4: 449 | AB4: 290 | AC4: 6223 | AD4: 218 | AE4: 1462 | AF4: 292 | AG4: 0 | AH4: 608 | AI4: 326 | AJ4: 104 | AK4: 303 | AL4: 4501 | AM4: 1536 | AN4: 289 | AO4: 144 | AP4: 185 | AQ4: 3340 | AR4: 85 | AS4: 998 | AT4: 12654 | AU4: 392 | AV4: 563 | AW4: 1115 | AX4: 631 | AY4: 9458 | AZ4: 2991 | BA4: 46 | BB4: 46 | BC4: 453 | BD4: 226 | BE4: 6234 | BF4: 44 | BG4: 31 | BH4: 282 | BI4: 109133 | BJ4: 72 | BK4: 364 | BL4: 0 | BM4: 22 | BN4: 0 | BO4: 0 | BP4: 0 | BQ4: 384 | BR4: 151 | BS4: 148 | BT4: 1055 | BU4: 8 | BV4: 21 | BW4: 3 | BX4: 20 | BY4: 123 | BZ4: 154 | CA4: 13 | CB4: 37 | CC4: 44 | CD4: 0 | CE4: 11 | CF4: 36 | CG4: 745 | CH4: 190542
A5: 1982 | B5: 738 | C5: 2738 | D5: 19 | E5: 52 | F5: 1186 | G5: 52 | H5: 26 | I5: 66 | J5: 481 | K5: 232 | L5: 393 | M5: 108 | N5: 2653 | O5: 2471 | P5: 2078 | Q5: 760 | R5: 500 | S5: 1595 | T5: 3664 | U5: 27 | V5: 93 | W5: 220 | X5: 3089 | Y5: 413 | Z5: 2889 | AA5: 1030 | AB5: 708 | AC5: 10133 | AD5: 208 | AE5: 1402 | AF5: 546 | AG5: 0 | AH5: 168 | AI5: 647 | AJ5: 182 | AK5: 526 | AL5: 6299 | AM5: 2422 | AN5: 730 | AO5: 0 | AP5: 215 | AQ5: 4922 | AR5: 25 | AS5: 1265 | AT5: 6395 | AU5: 1037 | AV5: 1139 | AW5: 1106 | AX5: 228 | AY5: 7963 | AZ5: 2704 | BA5: 1000 | BB5: 250 | BC5: 1244 | BD5: 311 | BE5: 7789 | BF5: 27 | BG5: 86 | BH5: 948 | BI5: 130672 | BJ5: 86 | BK5: 326 | BL5: 187 | BM5: 8 | BN5: 18 | BO5: 0 | BP5: 37 | BQ5: 465 | BR5: 155 | BS5: 31 | BT5: 1233 | BU5: 38 | BV5: 22 | BW5: 7 | BX5: 40 | BY5: 127 | BZ5: 159 | CA5: 25 | CB5: 38 | CC5: 111 | CD5: 0 | CE5: 7 | CF5: 59 | CG5: 871 | CH5: 224920
A6: 1983 | B6: 878 | C6: 5620 | D6: 125 | E6: 57 | F6: 1407 | G6: 19 | H6: 13 | I6: 13 | J6: 774 | K6: 160 | L6: 1275 | M6: 97 | N6: 2613 | O6: 6627 | P6: 1107 | Q6: 1132 | R6: 327 | S6: 684 | T6: 1554 | U6: 0 | V6: 74 | W6: 116 | X6: 7269 | Y6: 1193 | Z6: 2865 | AA6: 973 | AB6: 396 | AC6: 8624 | AD6: 363 | AE6: 2066 | AF6: 432 | AG6: 0 | AH6: 258 | AI6: 206 | AJ6: 76 | AK6: 371 | AL6: 4966 | AM6: 883 | AN6: 216 | AO6: 80 | AP6: 29 | AQ6: 3234 | AR6: 142 | AS6: 508 | AT6: 7303 | AU6: 317 | AV6: 433 | AW6: 445 | AX6: 259 | AY6: 7765 | AZ6: 3948 | BA6: 230 | BB6: 45 | BC6: 1013 | BD6: 189 | BE6: 3482 | BF6: 36 | BG6: 72 | BH6: 869 | BI6: 45257 | BJ6: 196 | BK6: 313 | BL6: 137 | BM6: 12 | BN6: 14 | BO6: 0 | BP6: 0 | BQ6: 147 | BR6: 268 | BS6: 89 | BT6: 1064 | BU6: 18 | BV6: 35 | BW6: 0 | BX6: 17 | BY6: 219 | BZ6: 275 | CA6: 0 | CB6: 18 | CC6: 112 | CD6: 0 | CE6: 5 | CF6: 67 | CG6: 751 | CH6: 135242
A7: 1984 | B7: 1328 | C7: 7106 | D7: 277 | E7: 67 | F7: 1952 | G7: 13 | H7: 50 | I7: 145 | J7: 167 | K7: 447 | L7: 1669 | M7: 226 | N7: 2153 | O7: 7015 | P7: 1807 | Q7: 475 | R7: 981 | S7: 845 | T7: 3404 | U7: 0 | V7: 448 | W7: 178 | X7: 7020 | Y7: 1019 | Z7: 3752 | AA7: 1023 | AB7: 357 | AC7: 6677 | AD7: 347 | AE7: 2059 | AF7: 446 | AG7: 0 | AH7: 744 | AI7: 573 | AJ7: 479 | AK7: 672 | AL7: 4682 | AM7: 2326 | AN7: 760 | AO7: 114 | AP7: 116 | AQ7: 1921 | AR7: 184 | AS7: 1333 | AT7: 13137 | AU7: 1132 | AV7: 985 | AW7: 1280 | AX7: 584 | AY7: 14019 | AZ7: 6227 | BA7: 1941 | BB7: 976 | BC7: 782 | BD7: 335 | BE7: 5496 | BF7: 64 | BG7: 50 | BH7: 669 | BI7: 132965 | BJ7: 899 | BK7: 0 | BL7: 23 | BM7: 15 | BN7: 29 | BO7: 55 | BP7: 18 | BQ7: 460 | BR7: 285 | BS7: 83 | BT7: 1259 | BU7: 10 | BV7: 38 | BW7: 0 | BX7: 0 | BY7: 233 | BZ7: 292 | CA7: 0 | CB7: 45 | CC7: 280 | CD7: 0 | CE7: 11 | CF7: 90 | CG7: 889 | CH7: 253013
A8: 1985 | B8: 1325 | C8: 6928 | D8: 359 | E8: 111 | F8: 2665 | G8: 6 | H8: 55 | I8: 94 | J8: 443 | K8: 556 | L8: 1664 | M8: 501 | N8: 5671 | O8: 9891 | P8: 4676 | Q8: 1780 | R8: 415 | S8: 4739 | T8: 3763 | U8: 43 | V8: 377 | W8: 211 | X8: 8402 | Y8: 1655 | Z8: 3680 | AA8: 1829 | AB8: 321 | AC8: 6798 | AD8: 505 | AE8: 3165 | AF8: 561 | AG8: 0 | AH8: 1104 | AI8: 298 | AJ8: 159 | AK8: 398 | AL8: 6098 | AM8: 1734 | AN8: 764 | AO8: 73 | AP8: 286 | AQ8: 2289 | AR8: 362 | AS8: 1614 | AT8: 17494 | AU8: 1578 | AV8: 1847 | AW8: 1318 | AX8: 707 | AY8: 10991 | AZ8: 3107 | BA8: 1725 | BB8: 919 | BC8: 2792 | BD8: 135 | BE8: 8014 | BF8: 287 | BG8: 353 | BH8: 760 | BI8: 179691 | BJ8: 2100 | BK8: 0 | BL8: 100 | BM8: 33 | BN8: 37 | BO8: 72 | BP8: 64 | BQ8: 648 | BR8: 399 | BS8: 54 | BT8: 1838 | BU8: 15 | BV8: 54 | BW8: 8 | BX8: 0 | BY8: 326 | BZ8: 110 | CA8: 0 | CB8: 65 | CC8: 80 | CD8: 0 | CE8: 13 | CF8: 116 | CG8: 1298 | CH8: 327516
A9: 1986 | B9: 999 | C9: 7098 | D9: 194 | E9: 139 | F9: 3339 | G9: 45 | H9: 56 | I9: 167 | J9: 1113 | K9: 1112 | L9: 3339 | M9: 499 | N9: 6015 | O9: 14212 | P9: 4666 | Q9: 1758 | R9: 494 | S9: 3976 | T9: 3241 | U9: 89 | V9: 332 | W9: 176 | X9: 5799 | Y9: 1642 | Z9: 12928 | AA9: 1795 | AB9: 283 | AC9: 9673 | AD9: 573 | AE9: 5954 | AF9: 469 | AG9: 0 | AH9: 938 | AI9: 188 | AJ9: 206 | AK9: 609 | AL9: 7391 | AM9: 1711 | AN9: 795 | AO9: 6 | AP9: 175 | AQ9: 3171 | AR9: 354 | AS9: 1817 | AT9: 26459 | AU9: 1455 | AV9: 981 | AW9: 3472 | AX9: 501 | AY9: 9310 | AZ9: 5693 | BA9: 1195 | BB9: 1606 | BC9: 2815 | BD9: 610 | BE9: 9454 | BF9: 120 | BG9: 147 | BH9: 275 | BI9: 179968 | BJ9: 5195 | BK9: 317 | BL9: 23 | BM9: 28 | BN9: 44 | BO9: 83 | BP9: 73 | BQ9: 669 | BR9: 468 | BS9: 32 | BT9: 2248 | BU9: 18 | BV9: 63 | BW9: 8 | BX9: 161 | BY9: 383 | BZ9: 111 | CA9: 3 | CB9: 80 | CC9: 135 | CD9: 0 | CE9: 17 | CF9: 113 | CG9: 1587 | CH9: 365456
A10: 1987 | B10: 1181 | C10: 3826 | D10: 236 | E10: 128 | F10: 3470 | G10: 17 | H10: 122 | I10: 186 | J10: 2333 | K10: 576 | L10: 3252 | M10: 335 | N10: 4127 | O10: 16179 | P10: 4737 | Q10: 1942 | R10: 758 | S10: 6151 | T10: 2326 | U10: 56 | V10: 596 | W10: 247 | X10: 8963 | Y10: 3584 | Z10: 6598 | AA10: 1446 | AB10: 274 | AC10: 10949 | AD10: 701 | AE10: 6591 | AF10: 494 | AG10: 0 | AH10: 786 | AI10: 125 | AJ10: 195 | AK10: 363 | AL10: 4339 | AM10: 1787 | AN10: 732 | AO10: 56 | AP10: 40 | AQ10: 3231 | AR10: 0 | AS10: 2812 | AT10: 21049 | AU10: 1337 | AV10: 736 | AW10: 2622 | AX10: 262 | AY10: 11167 | AZ10: 4638 | BA10: 691 | BB10: 665 | BC10: 1183 | BD10: 793 | BE10: 5755 | BF10: 80 | BG10: 5 | BH10: 232 | BI10: 82056 | BJ10: 18443 | BK10: 366 | BL10: 58 | BM10: 0 | BN10: 41 | BO10: 86 | BP10: 76 | BQ10: 354 | BR10: 569 | BS10: 86 | BT10: 1838 | BU10: 0 | BV10: 67 | BW10: 6 | BX10: 12 | BY10: 199 | BZ10: 133 | CA10: 22 | CB10: 65 | CC10: 141 | CD10: 0 | CE10: 16 | CF10: 118 | CG10: 1298 | CH10: 264112
A11: 1988 | B11: 1742 | C11: 4363 | D11: 209 | E11: 161 | F11: 3085 | G11: 86 | H11: 80 | I11: 126 | J11: 2071 | K11: 911 | L11: 2293 | M11: 231 | N11: 5553 | O11: 7733 | P11: 3577 | Q11: 2180 | R11: 1301 | S11: 3621 | T11: 3167 | U11: 56 | V11: 352 | W11: 364 | X11: 7005 | Y11: 1461 | Z11: 7093 | AA11: 2269 | AB11: 274 | AC11: 10075 | AD11: 620 | AE11: 6644 | AF11: 347 | AG11: 0 | AH11: 718 | AI11: 258 | AJ11: 149 | AK11: 801 | AL11: 7927 | AM11: 2072 | AN11: 895 | AO11: 112 | AP11: 111 | AQ11: 2508 | AR11: 75 | AS11: 2632 | AT11: 27876 | AU11: 1388 | AV11: 1384 | AW11: 1801 | AX11: 486 | AY11: 14807 | AZ11: 7471 | BA11: 1543 | BB11: 1036 | BC11: 514 | BD11: 409 | BE11: 4358 | BF11: 53 | BG11: 71 | BH11: 613 | BI11: 38232 | BJ11: 16603 | BK11: 878 | BL11: 61 | BM11: 11 | BN11: 51 | BO11: 71 | BP11: 63 | BQ11: 191 | BR11: 464 | BS11: 87 | BT11: 1846 | BU11: 15 | BV11: 57 | BW11: 7 | BX11: 120 | BY11: 380 | BZ11: 476 | CA11: 149 | CB11: 66 | CC11: 124 | CD11: 0 | CE11: 22 | CF11: 100 | CG11: 1303 | CH11: 222495
A12: 1989 | B12: 1050 | C12: 6427 | D12: 124 | E12: 76 | F12: 1896 | G12: 43 | H12: 25 | I12: 63 | J12: 501 | K12: 95 | L12: 2391 | M12: 173 | N12: 2583 | O12: 9313 | P12: 2123 | Q12: 1713 | R12: 567 | S12: 2088 | T12: 3546 | U12: 17 | V12: 265 | W12: 62 | X12: 3888 | Y12: 972 | Z12: 4459 | AA12: 1517 | AB12: 488 | AC12: 4325 | AD12: 379 | AE12: 5201 | AF12: 244 | AG12: 0 | AH12: 950 | AI12: 429 | AJ12: 184 | AK12: 233 | AL12: 3524 | AM12: 1370 | AN12: 963 | AO12: 308 | AP12: 399 | AQ12: 2016 | AR12: 324 | AS12: 2975 | AT12: 24860 | AU12: 1226 | AV12: 2119 | AW12: 1762 | AX12: 515 | AY12: 13217 | AZ12: 4392 | BA12: 816 | BB12: 1346 | BC12: 1511 | BD12: 833 | BE12: 6568 | BF12: 61 | BG12: 71 | BH12: 594 | BI12: 77172 | BJ12: 3685 | BK12: 409 | BL12: 24 | BM12: 12 | BN12: 48 | BO12: 61 | BP12: 54 | BQ12: 289 | BR12: 319 | BS12: 60 | BT12: 1289 | BU12: 10 | BV12: 45 | BW12: 4 | BX12: 86 | BY12: 30 | BZ12: 327 | CA12: 13 | CB12: 46 | CC12: 53 | CD12: 0 | CE12: 19 | CF12: 80 | CG12: 910 | CH12: 215225
A13: 1990 | B13: 1324 | C13: 6792 | D13: 110 | E13: 22 | F13: 2326 | G13: 44 | H13: 77 | I13: 111 | J13: 1106 | K13: 222 | L13: 2214 | M13: 540 | N13: 5630 | O13: 8768 | P13: 1856 | Q13: 2262 | R13: 805 | S13: 7603 | T13: 3213 | U13: 0 | V13: 87 | W13: 652 | X13: 8655 | Y13: 1318 | Z13: 8783 | AA13: 3196 | AB13: 1185 | AC13: 8771 | AD13: 631 | AE13: 4919 | AF13: 292 | AG13: 0 | AH13: 468 | AI13: 299 | AJ13: 87 | AK13: 630 | AL13: 9642 | AM13: 1402 | AN13: 657 | AO13: 120 | AP13: 70 | AQ13: 1867 | AR13: 327 | AS13: 6346 | AT13: 30941 | AU13: 1868 | AV13: 1266 | AW13: 1917 | AX13: 529 | AY13: 7979 | AZ13: 5651 | BA13: 646 | BB13: 709 | BC13: 718 | BD13: 187 | BE13: 4303 | BF13: 59 | BG13: 33 | BH13: 415 | BI13: 181032 | BJ13: 2121 | BK13: 476 | BL13: 38 | BM13: 0 | BN13: 51 | BO13: 77 | BP13: 69 | BQ13: 653 | BR13: 395 | BS13: 103 | BT13: 2319 | BU13: 18 | BV13: 53 | BW13: 7 | BX13: 0 | BY13: 395 | BZ13: 132 | CA13: 0 | CB13: 78 | CC13: 101 | CD13: 0 | CE13: 21 | CF13: 331 | CG13: 1902 | CH13: 353022
... A46: 2023 | B46: 159 | C46: 1621 | D46: 0 | E46: 12 | F46: 578 | G46: 9 | H46: 11 | I46: 102 | J46: 196 | K46: 117 | L46: 732 | M46: 236 | N46: 1697 | O46: 4981 | P46: 1068 | Q46: 876 | R46: 412 | S46: 3462 | T46: 4063 | U46: 2 | V46: 31 | W46: 34 | X46: 1164 | Y46: 685 | Z46: 1439 | AA46: 992 | AB46: 57 | AC46: 7469 | AD46: 138 | AE46: 1754 | AF46: 463 | AG46: 282 | AH46: 98 | AI46: 122 | AJ46: 41 | AK46: 23 | AL46: 4607 | AM46: 50 | AN46: 85 | AO46: 41 | AP46: 256 | AQ46: 2404 | AR46: 8 | AS46: 3851 | AT46: 79909 | AU46: 968 | AV46: 296 | AW46: 23044 | AX46: 215978 | AY46: 344599 | AZ46: 14533 | BA46: 749 | BB46: 4645 | BC46: 683 | BD46: 788 | BE46: 4750 | BF46: 110 | BG46: 82 | BH46: 442 | BI46: 147063 | BJ46: 126217 | BK46: 70 | BL46: 421 | BM46: 30 | BN46: 6 | BO46: 640 | BP46: 18 | BQ46: 8 | BR46: 6 | BS46: 84 | BT46: 2698 | BU46: 3 | BV46: 0 | BW46: 5 | BX46: 19 | BY46: 76 | BZ46: 5 | CA46: 16 | CB46: 53 | CC46: 0 | CD46: 0 | CE46: 39 | CF46: 35 | CG46: 1164 | CH46: 1016680

Sheet Escapements
A1: Year | B1: Swift | C1: Fraser | D1: Horsey | E1: Nevin | F1: Holmes | G1: McKale | H1: Twin | I1: Goat | J1: Morkill | K1: Walker | L1: Torpy | M1: Dome | N1: Slim | O1: Bowron | P1: McGregor | Q1: Willow | R1: Salmon (PG) | S1: Stuart | T1: Nechako | U1: Stellako | V1: Endako | W1: Chilako | X1: Blackwater | Y1: Cottonwood | Z1: Quesnel | AA1: Cariboo | AB1: Horsefly | AC1: Chilko | AD1: Chilcotin Upper | AE1: Chilcotin Lower | AF1: Elkin | AG1: Taseko | AH1: Bridge | AI1: Portage | AJ1: Seton | AK1: Mahood | AL1: Clearwater | AM1: Finn | AN1: Raft | AO1: Barriere | AP1: Louis | AQ1: North Thompson | AR1: Bessette | AS1: Middle Shuswap | AT1: Lower Shuswap | AU1: Eagle | AV1: Salmon (ST) | AW1: Adams | AX1: Little River | AY1: South Thompson | AZ1: Lower Thompson | BA1: Deadman | BB1: Bonaparte | BC1: Coldwater | BD1: Spius | BE1: Nicola | BF1: Nahatlatch | BG1: Maria Slough | BH1: Birkenhead | BI1: Harrison | BJ1: Chilliwack | BK1: Pitt | BL1: Blue | BM1: Lemieux | BN1: Upper Adams | BO1: Scotch | BP1: Seymour | BQ1: Stave | BR1: Baker | BS1: Big Silver | BT1: Chilliwack Su | BU1: Douglas | BV1: Holliday | BW1: Kazchek | BX1: Kuzkwa | BY1: Narcosli | BZ1: Naver | CA1: Pinchi | CB1: Sloquet | CC1: Small | CD1: Tipella | CE1: Wap | CF1: McKinley | CG1: Chehalis | CI1: Spring 5.2 | CJ1: Summer 5.2 | CK1: Spring 4.2 | CL1: Summer 4.1 | CM1: Fall
A3: 1979 | B3: 350 | C3: 1800 | D3: 25 | E3: 20 | F3: 450 | G3: 10 | H3: 25 | I3: 15 | J3: 200 | K3: 200 | L3: 750 | M3: 215.99334 | N3: 1500 | O3: 1592.2642 | P3: 1559.998 | Q3: 832.72143 | R3: 750 | S3: 750 | T3: 1800 | U3: 75 | V3: 75 | W3: 200 | X3: 2244.9461 | Y3: 200 | Z3: 900 | AA3: 376.8504 | AB3: 350 | AC3: 3823.2177 | AD3: 145.66576 | AE3: 2398.4662 | AF3: 200 | AG3: 0.001 | AH3: 200 | AI3: 100 | AJ3: 20 | AK3: 260 | AL3: 1500 | AM3: 425 | AN3: 175 | AO3: 15 | AP3: 20 | AQ3: 1200 | AR3: 68.508643 | AS3: 689.37786 | AT3: 16453.49 | AU3: 300 | AV3: 300 | AW3: 1000 | AX3: 700 | AY3: 6000 | AZ3: 2978.828 | BA3: 50 | BB3: 0 | BC3: 300 | BD3: 50 | BE3: 3017 | BF3: 25 | BG3: 75 | BH3: 241 | BI3: 78000 | BJ3: 50 | BK3: 250 | BL3: 15 | BM3: 0 | BN3: 27.465717 | BO3: 22.349102 | BP3: 10 | BQ3: 280.7301 | BR3: 125.39236 | BS3: 75 | BT3: 562.67496 | BU3: 4.5066562 | BV3: 16.921317 | BW3: 25 | BX3: 75 | BY3: 102.60921 | BZ3: 128.65541 | CA3: 25 | CB3: 19.982343 | CC3: 20.719518 | CD3: 0.032704326 | CE3: 12.35675 | CF3: 31.363781 | CG3: 397.25945 | CI3: 18124.066 | CJ3: 12379.525 | CK3: 3505.5086 | CL3: 27936.518 | CM3: 78330.73
A4: 1980 | B4: 350 | C4: 4000 | D4: 20 | E4: 12 | F4: 500 | G4: 4 | H4: 0 | I4: 85 | J4: 407.10585 | K4: 250 | L4: 550 | M4: 232.56385 | N4: 1900 | O4: 2358.9099 | P4: 823.1479 | Q4: 555.14762 | R4: 500 | S4: 1800 | T4: 2038 | U4: 50 | V4: 50 | W4: 200 | X4: 1122.4731 | Y4: 300 | Z4: 1000 | AA4: 500.52325 | AB4: 350 | AC4: 5691.0794 | AD4: 156.8409 | AE4: 2238.5684 | AF4: 250 | AG4: 0.001 | AH4: 75 | AI4: 75 | AJ4: 75 | AK4: 150 | AL4: 2500 | AM4: 600 | AN4: 200 | AO4: 15 | AP4: 45 | AQ4: 750 | AR4: 68.508643 | AS4: 689.37786 | AT4: 5722.5818 | AU4: 250 | AV4: 360 | AW4: 350 | AX4: 400 | AY4: 3000 | AZ4: 1226.7748 | BA4: 250 | BB4: 75 | BC4: 710 | BD4: 200 | BE4: 6180 | BF4: 200 | BG4: 100 | BH4: 340 | BI4: 52000 | BJ4: 50 | BK4: 200 | BL4: 20 | BM4: 10 | BN4: 11.311244 | BO4: 24.063673 | BP4: 21.363533 | BQ4: 187.21334 | BR4: 135.01217 | BS4: 20 | BT4: 747.33078 | BU4: 5.9856278 | BV4: 18.219481 | BW4: 2.5818062 | BX4: 25 | BY4: 110.48115 | BZ4: 138.52555 | CA4: 8.9997937 | CB4: 0 | CC4: 22.309072 | CD4: 0.043437067 | CE4: 5.0888974 | CF4: 33.769937 | CG4: 527.63005 | CI4: 19514.502 | CJ4: 16442.175 | CK4: 7528.5086 | CL4: 11505.135 | CM4: 52237.213
A5: 1981 | B5: 300 | C5: 1800 | D5: 20 | E5: 5 | F5: 400 | G5: 10 | H5: 10 | I5: 20 | J5: 150 | K5: 140 | L5: 510 | M5: 10 | N5: 1335 | O5: 1486.1132 | P5: 730.21185 | Q5: 488.5299 | R5: 175 | S5: 140 | T5: 2814 | U5: 25 | V5: 32 | W5: 150 | X5: 2095.283 | Y5: 300 | Z5: 800 | AA5: 300 | AB5: 200 | AC5: 4155.0052 | AD5: 114.24493 | AE5: 959.38646 | AF5: 200 | AG5: 0.001 | AH5: 400 | AI5: 100 | AJ5: 30 | AK5: 200 | AL5: 3000 | AM5: 1000 | AN5: 200 | AO5: 100 | AP5: 110 | AQ5: 2250 | AR5: 54.806914 | AS5: 689.37786 | AT5: 8247.7249 | AU5: 250 | AV5: 300 | AW5: 700 | AX5: 400 | AY5: 6000 | AZ5: 1917.4467 | BA5: 25 | BB5: 25 | BC5: 200 | BD5: 100 | BE5: 3258 | BF5: 30 | BG5: 20 | BH5: 135 | BI5: 104000 | BJ5: 50 | BK5: 325 | BL5: 0 | BM5: 15 | BN5: 0 | BO5: 0 | BP5: 0 | BQ5: 374.24685 | BR5: 98.344598 | BS5: 100 | BT5: 713.63526 | BU5: 5.7157488 | BV5: 13.271303 | BW5: 2 | BX5: 13 | BY5: 80.475889 | BZ5: 100.90379 | CA5: 8.5940125 | CB5: 25 | CC5: 16.250214 | CD5: 0.041478583 | CE5: 7.9539369 | CF5: 24.598456 | CG5: 503.84035 | CI5: 14214.614 | CJ5: 15700.833 | CK5: 3772.8069 | CL5: 17982.503 | CM5: 104424.25
A6: 1982 | B6: 570 | C6: 1800 | D6: 15 | E6: 40 | F6: 900 | G6: 40 | H6: 20 | I6: 50 | J6: 368.21944 | K6: 175 | L6: 300 | M6: 80 | N6: 1800 | O6: 1651.2369 | P6: 1548.9342 | Q6: 499.63286 | R6: 300 | S6: 600 | T6: 1590 | U6: 12.223196 | V6: 65 | W6: 150 | X6: 2244.9461 | Y6: 325 | Z6: 1000 | AA6: 400 | AB6: 365 | AC6: 6018.0588 | AD6: 141.85959 | AE6: 879.43759 | AF6: 297.50379 | AG6: 0.001 | AH6: 80 | AI6: 150 | AJ6: 50 | AK6: 250 | AL6: 3000 | AM6: 850 | AN6: 375 | AO6: 0 | AP6: 150 | AQ6: 2500 | AR6: 13.701729 | AS6: 689.37786 | AT6: 2894.0017 | AU6: 400 | AV6: 700 | AW6: 500 | AX6: 100 | AY6: 3500 | AZ6: 924.49353 | BA6: 600 | BB6: 150 | BC6: 800 | BD6: 200 | BE6: 4737 | BF6: 16 | BG6: 50 | BH6: 475 | BI6: 114400 | BJ6: 56 | BK6: 300 | BL6: 65.687009 | BM6: 5 | BN6: 8.5241166 | BO6: 0 | BP6: 20 | BQ6: 411.67513 | BR6: 122.11592 | BS6: 20 | BT6: 805.37907 | BU6: 25 | BV6: 16.479171 | BW6: 2.7823458 | BX6: 15 | BY6: 99.928085 | BZ6: 125.29371 | CA6: 9.6988451 | CB6: 25 | CC6: 20.178128 | CD6: 0.046811004 | CE6: 3.8349766 | CF6: 30.544261 | CG6: 568.61327 | CI6: 17650.493 | CJ6: 17719.307 | CK6: 6650.7017 | CL6: 8670.2321 | CM6: 114867.68
A7: 1983 | B7: 700 | C7: 4300 | D7: 100 | E7: 45 | F7: 1100 | G7: 15 | H7: 10 | I7: 10 | J7: 609.26384 | K7: 125 | L7: 1000 | M7: 75 | N7: 2000 | O7: 5071.6562 | P7: 857.44573 | Q7: 866.03028 | R7: 250 | S7: 475 | T7: 1114 | U7: 0 | V7: 50 | W7: 75 | X7: 5687.1968 | Y7: 900 | Z7: 1500 | AA7: 700 | AB7: 300 | AC7: 6778.5555 | AD7: 234.72395 | AE7: 1598.9774 | AF7: 330.48019 | AG7: 0.001 | AH7: 210 | AI7: 70 | AJ7: 24 | AK7: 300 | AL7: 4000 | AM7: 700 | AN7: 175 | AO7: 65 | AP7: 20 | AQ7: 2500 | AR7: 13.701729 | AS7: 426.26581 | AT7: 5396 | AU7: 250 | AV7: 300 | AW7: 250 | AX7: 100 | AY7: 3000 | AZ7: 1102.4837 | BA7: 162 | BB7: 32 | BC7: 547 | BD7: 102 | BE7: 2407 | BF7: 30 | BG7: 50 | BH7: 640 | BI7: 31200 | BJ7: 100 | BK7: 300 | BL7: 108.68714 | BM7: 10 | BN7: 10.165241 | BO7: 0 | BP7: 0 | BQ7: 112.57978 | BR7: 202.05564 | BS7: 75 | BT7: 894.6502 | BU7: 15 | BV7: 27.266792 | BW7: 0 | BX7: 10 | BY7: 165.34317 | BZ7: 207.31368 | CA7: 0 | CB7: 15 | CC7: 33.387166 | CD7: 0.051999705 | CE7: 4.5733141 | CF7: 50.539194 | CG7: 631.64042 | CI7: 29204.887 | CJ7: 19683.379 | CK7: 3283.7017 | CL7: 10339.488 | CM7: 31412.58
A8: 1984 | B8: 1200 | C8: 5814 | D8: 250 | E8: 60 | F8: 1750 | G8: 12 | H8: 45 | I8: 130 | J8: 150 | K8: 400 | L8: 1500 | M8: 200 | N8: 1800 | O8: 5805.2772 | P8: 1604.2533 | Q8: 388.60333 | R8: 755.00563 | S8: 500 | T8: 2099 | U8: 0 | V8: 300 | W8: 150 | X8: 6061.3545 | Y8: 900 | Z8: 1800 | AA8: 600 | AB8: 250 | AC8: 4815.5794 | AD8: 292.33491 | AE8: 1519.0286 | AF8: 300 | AG8: 0.001 | AH8: 582 | AI8: 138 | AJ8: 157 | AK8: 400 | AL8: 2800 | AM8: 1500 | AN8: 500 | AO8: 75 | AP8: 100 | AQ8: 1200 | AR8: 137.01729 | AS8: 948.08896 | AT8: 7582 | AU8: 775 | AV8: 850 | AW8: 650 | AX8: 250 | AY8: 6000 | AZ8: 1848.1897 | BA8: 1626 | BB8: 818 | BC8: 598 | BD8: 256 | BE8: 4679 | BF8: 50 | BG8: 30 | BH8: 350 | BI8: 122401 | BJ8: 658 | BK8: 0.01 | BL8: 15 | BM8: 11 | BN8: 17.040881 | BO8: 44.852151 | BP8: 15 | BQ8: 442.61838 | BR8: 251.64846 | BS8: 50 | BT8: 762.68439 | BU8: 6.1086001 | BV8: 33.959192 | BW8: 0 | BX8: 0 | BY8: 205.92522 | BZ8: 258.19703 | CA8: 0 | CB8: 27.085302 | CC8: 41.581759 | CD8: 0.044329464 | CE8: 7.6666455 | CF8: 62.943604 | CG8: 538.47 | CI8: 36372.975 | CJ8: 16779.973 | CK8: 8214.0173 | CL8: 17332.986 | CM8: 123501.62
A9: 1985 | B9: 1200 | C9: 6050 | D9: 325 | E9: 100 | F9: 2400 | G9: 5 | H9: 50 | I9: 85 | J9: 400 | K9: 500 | L9: 1500 | M9: 450 | N9: 5000 | O9: 8681.3577 | P9: 4203.1906 | Q9: 1554.4133 | R9: 350 | S9: 3000 | T9: 2591 | U9: 30 | V9: 300 | W9: 175 | X9: 7483.1537 | Y9: 1500 | Z9: 2000 | AA9: 1150 | AB9: 250 | AC9: 5144.5394 | AD9: 419.79558 | AE9: 2398.4662 | AF9: 400 | AG9: 0.001 | AH9: 956 | AI9: 225 | AJ9: 114 | AK9: 250 | AL9: 3800 | AM9: 1300 | AN9: 525 | AO9: 50 | AP9: 250 | AQ9: 1500 | AR9: 274.03457 | AS9: 1204.1154 | AT9: 10539 | AU9: 1250 | AV9: 1670 | AW9: 750 | AX9: 450 | AY9: 7000 | AZ9: 2408.0261 | BA9: 1501 | BB9: 800 | BC9: 2061 | BD9: 100 | BE9: 7088 | BF9: 240 | BG9: 200 | BH9: 283 | BI9: 175417 | BJ9: 1492 | BK9: 0.01 | BL9: 75 | BM9: 25 | BN9: 22.202747 | BO9: 64.408094 | BP9: 57.180981 | BQ9: 636.30596 | BR9: 361.36946 | BS9: 30 | BT9: 1029.0317 | BU9: 8.241867 | BV9: 48.765707 | BW9: 5 | BX9: 0 | BY9: 295.71049 | BZ9: 100 | CA9: 0 | CB9: 36.544127 | CC9: 59.711782 | CD9: 0.059810355 | CE9: 9.9889545 | CF9: 90.387585 | CG9: 726.51639 | CI9: 52231.921 | CJ9: 22639.934 | CK9: 12074.035 | CL9: 22583.333 | CM9: 177545.31
A10: 1986 | B10: 900 | C10: 6500 | D10: 175 | E10: 125 | F10: 3000 | G10: 40 | H10: 50 | I10: 150 | J10: 1000 | K10: 1000 | L10: 3000 | M10: 450 | N10: 5500 | O10: 12994.559 | P10: 4204.25 | Q10: 1609.9281 | R10: 450 | S10: 3065 | T10: 2685 | U10: 75 | V10: 300 | W10: 150 | X10: 5243.8922 | Y10: 1473 | Z10: 9000 | AA10: 1400 | AB10: 250 | AC10: 8551.3881 | AD10: 488.00297 | AE10: 5276.6255 | AF10: 400 | AG10: 0.001 | AH10: 836 | AI10: 98 | AJ10: 105 | AK10: 500 | AL10: 6070 | AM10: 1499 | AN10: 700 | AO10: 5 | AP10: 150 | AQ10: 2652 | AR10: 315.13976 | AS10: 1556.3988 | AT10: 20762.997 | AU10: 1295 | AV10: 871 | AW10: 2500 | AX10: 350 | AY10: 6500 | AZ10: 3799.0953 | BA10: 1026 | BB10: 1379 | BC10: 2234 | BD10: 484 | BE10: 8180 | BF10: 112.89301 | BG10: 110 | BH10: 223 | BI10: 163327 | BJ10: 4469 | BK10: 300 | BL10: 20 | BM10: 25 | BN10: 35.028835 | BO10: 74.872967 | BP10: 66.47161 | BQ10: 603.52834 | BR10: 420.08391 | BS10: 25 | BT10: 1752.4265 | BU10: 14.035783 | BV10: 56.689042 | BW10: 6.0541137 | BX10: 125 | BY10: 343.75682 | BZ10: 100 | CA10: 2 | CB10: 62.234133 | CC10: 69.413609 | CD10: 0.10185619 | CE10: 15.759376 | CF10: 100 | CG10: 1237.2472 | CI10: 60718.439 | CJ10: 38555.489 | CK10: 13768.14 | CL10: 35629.279 | CM10: 168399.53
A11: 1987 | B11: 1000 | C11: 3500 | D11: 200 | E11: 110 | F11: 3000 | G11: 15 | H11: 105 | I11: 160 | J11: 2000 | K11: 500 | L11: 2800 | M11: 295 | N11: 3750 | O11: 14631.316 | P11: 4148.931 | Q11: 1776.4724 | R11: 700 | S11: 5052 | T11: 2042 | U11: 50 | V11: 500 | W11: 175 | X11: 7483.1537 | Y11: 2700 | Z11: 4756 | AA11: 1179 | AB11: 250 | AC11: 10007.43 | AD11: 498.13577 | AE11: 6076.1143 | AF11: 450 | AG11: 0.001 | AH11: 600 | AI11: 50 | AJ11: 65 | AK11: 300 | AL11: 3516 | AM11: 1542 | AN11: 650 | AO11: 50 | AP11: 25 | AQ11: 2743 | AR11: 0 | AS11: 2562.7452 | AT11: 16851.49 | AU11: 1175 | AV11: 641 | AW11: 2000 | AX11: 200 | AY11: 8500 | AZ11: 3600.5104 | BA11: 541 | BB11: 520 | BC11: 709 | BD11: 475 | BE11: 4823 | BF11: 75 | BG11: 4 | BH11: 113 | BI11: 79954 | BJ11: 17271 | BK11: 350 | BL11: 50 | BM11: 0 | BN11: 33.197821 | BO11: 76.427616 | BP11: 67.851814 | BQ11: 349.6987 | BR11: 428.80645 | BS11: 71.762169 | BT11: 1530.9237 | BU11: 0 | BV11: 57.866123 | BW11: 5.2888872 | BX11: 10 | BY11: 150 | BZ11: 100 | CA11: 18.436277 | CB11: 54.367876 | CC11: 70.8549 | CD11: 0.088981794 | CE11: 14.935608 | CF11: 107.25527 | CG11: 1080.8619 | CI11: 61979.185 | CJ11: 33682.16 | CK11: 7093 | CL11: 33766.879 | CM11: 97574.699
A12: 1988 | B12: 1500 | C12: 4000 | D12: 180 | E12: 140 | F12: 2700 | G12: 75 | H12: 70 | I12: 110 | J12: 1800 | K12: 800 | L12: 2000 | M12: 205 | N12: 5066 | O12: 6968.2198 | P12: 3164.2514 | Q12: 1998.5314 | R12: 1200 | S12: 3065 | T12: 2801 | U12: 50 | V12: 300 | W12: 250 | X12: 5986.523 | Y12: 1153 | Z12: 6300 | AA12: 1981 | AB12: 250 | AC12: 8975.5342 | AD12: 425.25451 | AE12: 5894.5131 | AF12: 300 | AG12: 0.001 | AH12: 638 | AI12: 125 | AJ12: 75 | AK12: 700 | AL12: 6740 | AM12: 1857 | AN12: 800 | AO12: 100 | AP12: 80 | AQ12: 2258 | AR12: 68.508643 | AS12: 2421.3896 | AT12: 24624.955 | AU12: 1259 | AV12: 1252 | AW12: 1600 | AX12: 400 | AY12: 12000 | AZ12: 4914.9303 | BA12: 1287 | BB12: 863 | BC12: 279 | BD12: 222 | BE12: 3701 | BF12: 50 | BG12: 67 | BH12: 501 | BI12: 35581 | BJ12: 14782 | BK12: 850 | BL12: 55 | BM12: 10 | BN12: 45.317179 | BO12: 65.245643 | BP12: 57.92455 | BQ12: 181.14555 | BR12: 366.06863 | BS12: 80.066727 | BT12: 1708.0873 | BU12: 13.680655 | BV12: 49.399845 | BW12: 5.9009348 | BX12: 100 | BY12: 299.55584 | BZ12: 375.59473 | CA12: 125 | CB12: 60.659508 | CC12: 60.488261 | CD12: 0.099279064 | CE12: 20.388074 | CF12: 91.562965 | CG12: 1205.9428 | CI12: 54064.134 | CJ12: 37579.972 | CK12: 6500.5086 | CL12: 46093.98 | CM12: 50544.146
A13: 1989 | B13: 850 | C13: 5000 | D13: 100 | E13: 60 | F13: 1500 | G13: 33.896908 | H13: 20 | I13: 50 | J13: 400 | K13: 75 | L13: 1900 | M13: 135 | N13: 2000 | O13: 7076.7296 | P13: 1659.5724 | Q13: 1332.3543 | R13: 450 | S13: 1659 | T13: 2928 | U13: 13.754553 | V13: 200 | W13: 50 | X13: 3142.9246 | Y13: 800 | Z13: 3000 | AA13: 1160 | AB13: 400 | AC13: 3490.2858 | AD13: 305.01475 | AE13: 4157.3413 | AF13: 200 | AG13: 0.001 | AH13: 750 | AI13: 330 | AJ13: 115 | AK13: 180 | AL13: 2491 | AM13: 1141 | AN13: 812 | AO13: 260 | AP13: 325 | AQ13: 1578 | AR13: 260.33284 | AS13: 2496.8439 | AT13: 18442.26 | AU13: 1004 | AV13: 1613 | AW13: 1250 | AX13: 400 | AY13: 10000 | AZ13: 3901.8699 | BA13: 644 | BB13: 1062 | BC13: 1200 | BD13: 661 | BE13: 4972 | BF13: 51 | BG13: 50 | BH13: 509 | BI13: 76083 | BJ13: 3333 | BK13: 375 | BL13: 20 | BM13: 10 | BN13: 35.976449 | BO13: 46.797583 | BP13: 41.546513 | BQ13: 285.64332 | BR13: 262.56354 | BS13: 42.481912 | BT13: 906.27925 | BU13: 7.2587004 | BV13: 35.432149 | BW13: 3.130926 | BX13: 70.038089 | BY13: 25 | BZ13: 269.39616 | CA13: 10.913944 | CB13: 32.184804 | CC13: 43.38534 | CD13: 0.05267562 | CE13: 16.185705 | CF13: 65.673742 | CG13: 639.85075 | CI13: 37950.629 | CJ13: 19939.232 | CK13: 9124.3328 | CL13: 36593.136 | CM13: 79701.643
A14: 1990 | B14: 1200 | C14: 6000 | D14: 100 | E14: 20 | F14: 2100 | G14: 40 | H14: 70 | I14: 100 | J14: 1000 | K14: 200 | L14: 2000 | M14: 486 | N14: 5000 | O14: 7666.4571 | P14: 1670.9748 | Q14: 1998.5314 | R14: 700 | S14: 6064 | T14: 2628 | U14: 0 | V14: 75 | W14: 425 | X14: 7483.1537 | Y14: 1000 | Z14: 6195 | AA14: 2500 | AB14: 1000 | AC14: 7606.9347 | AD14: 411.16316 | AE14: 4317.2391 | AF14: 250 | AG14: 0.001 | AH14: 375 | AI14: 175 | AJ14: 60 | AK14: 500 | AL14: 7320 | AM14: 1100 | AN14: 550 | AO14: 100 | AP14: 50 | AQ14: 1500 | AR14: 274.03457 | AS14: 5406.1227 | AT14: 22344.781 | AU14: 1477 | AV14: 1055 | AW14: 1397 | AX14: 400 | AY14: 6000 | AZ14: 4252.5935 | BA14: 532 | BB14: 584 | BC14: 411 | BD14: 107 | BE14: 3419 | BF14: 50 | BG14: 25 | BH14: 353 | BI14: 178852 | BJ14: 1795 | BK14: 450 | BL14: 30 | BM14: 0 | BN14: 39.210229 | BO14: 63.083644 | BP14: 56.005145 | BQ14: 649.7508 | BR14: 300 | BS14: 82.176672 | BT14: 1719 | BU14: 14.041172 | BV14: 47.762917 | BW14: 6.0564382 | BX14: 0 | BY14: 300 | BZ14: 100 | CA14: 0 | CB14: 62.258028 | CC14: 58.483904 | CD14: 0.1018953 | CE14: 17.640574 | CF14: 279 | CG14: 1237.7222 | CI14: 51157.855 | CJ14: 38570.292 | CK14: 5377.0346 | CL14: 39882.348 | CM14: 181296.75
... A47: 2023 | B47: 156 | C47: 1586 | D47: 0 | E47: 12 | F47: 566 | G47: 9 | H47: 11 | I47: 99.734074 | J47: 192 | K47: 115 | L47: 717 | M47: 231.16214 | N47: 1661 | O47: 4873 | P47: 1045.7601 | Q47: 857 | R47: 402.62741 | S47: 3323.7621 | T47: 3929 | U47: 2 | V47: 30 | W47: 34 | X47: 1143.0339 | Y47: 680 | Z47: 1343 | AA47: 948 | AB47: 55 | AC47: 7260 | AD47: 137 | AE47: 1707 | AF47: 449 | AG47: 273.60441 | AH47: 94 | AI47: 115.39696 | AJ47: 37.453324 | AK47: 22 | AL47: 4419 | AM47: 48 | AN47: 83 | AO47: 40 | AP47: 254 | AQ47: 2314.426 | AR47: 7.4028814 | AS47: 3761 | AT47: 74816 | AU47: 938 | AV47: 291 | AW47: 21564 | AX47: 205359 | AY47: 321763 | AZ47: 14282 | BA47: 736 | BB47: 4471 | BC47: 677 | BD47: 781 | BE47: 4646 | BF47: 108 | BG47: 79 | BH47: 357 | BI47: 146892 | BJ47: 102153 | BK47: 69 | BL47: 406 | BM47: 29 | BN47: 6 | BO47: 628 | BP47: 18 | BQ47: 8 | BR47: 6 | BS47: 82 | BT47: 2309 | BU47: 3 | BV47: 0 | BW47: 4.3976553 | BX47: 18 | BY47: 75 | BZ47: 5 | CA47: 15.329575 | CB47: 52 | CC47: 0 | CD47: 0 | CE47: 38 | CF47: 33.566399 | CG47: 934 | CI47: 19396.884 | CJ47: 28006.37 | CK47: 11572.403 | CL47: 641668 | CM47: 249053
A49: =A1 -> Year | B49: =B1 -> Swift | C49: =C1 -> Fraser | D49: =D1 -> Horsey | E49: =E1 -> Nevin | F49: =F1 -> Holmes | G49: =G1 -> McKale | H49: =H1 -> Twin | ... CG49: =CG1 -> Chehalis | CH49: Ubar
A50: =A3 -> 1979 | B50: =IF(RunSize_by_Stock!B2>0,(RunSize_by_Stock!B2-Escapements!B3)/RunSize_by_Stock!B2,"") -> 0.62805526 | C50: =IF(RunSize_by_Stock!C2>0,(RunSize_by_Stock!C2-Escapements!C3)/RunSize_by_Stock!C2,"") -> 0.49494949 | D50: =IF(RunSize_by_Stock!D2>0,(RunSize_by_Stock!D2-Escapements!D3)/RunSize_by_Stock!D2,"") -> 0.62686567 | E50: =IF(RunSize_by_Stock!E2>0,(RunSize_by_Stock!E2-Escapements!E3)/RunSize_by_Stock!E2,"") -> 0.60784314 | F50: =IF(RunSize_by_Stock!F2>0,(RunSize_by_Stock!F2-Escapements!F3)/RunSize_by_Stock!F2,"") -> 0.60352423 | G50: =IF(RunSize_by_Stock!G2>0,(RunSize_by_Stock!G2-Escapements!G3)/RunSize_by_Stock!G2,"") -> 0.61538462 | H50: =IF(RunSize_by_Stock!H2>0,(RunSize_by_Stock!H2-Escapements!H3)/RunSize_by_Stock!H2,"") -> 0.609375 | I50: =IF(RunSize_by_Stock!I2>0,(RunSize_by_Stock!I2-Escapements!I3)/RunSize_by_Stock!I2,"") -> 0.60526316 | ... CG50: =IF(RunSize_by_Stock!CG2>0,(RunSize_by_Stock!CG2-Escapements!CG3)/RunSize_by_Stock!CG2,"") -> 0.45506248 | CH50: =AVERAGE(B50:CG50) -> 0.52505573
A51: =A4 -> 1980 | B51: =IF(RunSize_by_Stock!B3>0,(RunSize_by_Stock!B3-Escapements!B4)/RunSize_by_Stock!B3,"") -> 0.32170543 | C51: =IF(RunSize_by_Stock!C3>0,(RunSize_by_Stock!C3-Escapements!C4)/RunSize_by_Stock!C3,"") -> 0.11504425 | D51: =IF(RunSize_by_Stock!D3>0,(RunSize_by_Stock!D3-Escapements!D4)/RunSize_by_Stock!D3,"") -> 0.33333333 | E51: =IF(RunSize_by_Stock!E3>0,(RunSize_by_Stock!E3-Escapements!E4)/RunSize_by_Stock!E3,"") -> 0.25 | F51: =IF(RunSize_by_Stock!F3>0,(RunSize_by_Stock!F3-Escapements!F4)/RunSize_by_Stock!F3,"") -> 0.25149701 | G51: =IF(RunSize_by_Stock!G3>0,(RunSize_by_Stock!G3-Escapements!G4)/RunSize_by_Stock!G3,"") -> 0.2 | H51: =IF(RunSize_by_Stock!H3>0,(RunSize_by_Stock!H3-Escapements!H4)/RunSize_by_Stock!H3,"") | I51: =IF(RunSize_by_Stock!I3>0,(RunSize_by_Stock!I3-Escapements!I4)/RunSize_by_Stock!I3,"") -> 0.26724138 | ... CG51: =IF(RunSize_by_Stock!CG3>0,(RunSize_by_Stock!CG3-Escapements!CG4)/RunSize_by_Stock!CG3,"") -> 0.37779475 | CH51: =AVERAGE(B51:CG51) -> 0.32562406
A52: =A5 -> 1981 | B52: =IF(RunSize_by_Stock!B4>0,(RunSize_by_Stock!B4-Escapements!B5)/RunSize_by_Stock!B4,"") -> 0.33628319 | C52: =IF(RunSize_by_Stock!C4>0,(RunSize_by_Stock!C4-Escapements!C5)/RunSize_by_Stock!C4,"") -> 0.36418227 | D52: =IF(RunSize_by_Stock!D4>0,(RunSize_by_Stock!D4-Escapements!D5)/RunSize_by_Stock!D4,"") -> 0.33333333 | E52: =IF(RunSize_by_Stock!E4>0,(RunSize_by_Stock!E4-Escapements!E5)/RunSize_by_Stock!E4,"") -> 0.375 | F52: =IF(RunSize_by_Stock!F4>0,(RunSize_by_Stock!F4-Escapements!F5)/RunSize_by_Stock!F4,"") -> 0.36507937 | G52: =IF(RunSize_by_Stock!G4>0,(RunSize_by_Stock!G4-Escapements!G5)/RunSize_by_Stock!G4,"") -> 0.375 | H52: =IF(RunSize_by_Stock!H4>0,(RunSize_by_Stock!H4-Escapements!H5)/RunSize_by_Stock!H4,"") -> 0.375 | I52: =IF(RunSize_by_Stock!I4>0,(RunSize_by_Stock!I4-Escapements!I5)/RunSize_by_Stock!I4,"") -> 0.35483871 | ... CG52: =IF(RunSize_by_Stock!CG4>0,(RunSize_by_Stock!CG4-Escapements!CG5)/RunSize_by_Stock!CG4,"") -> 0.32370422 | CH52: =AVERAGE(B52:CG52) -> 0.36287521
A53: =A6 -> 1982 | B53: =IF(RunSize_by_Stock!B5>0,(RunSize_by_Stock!B5-Escapements!B6)/RunSize_by_Stock!B5,"") -> 0.22764228 | C53: =IF(RunSize_by_Stock!C5>0,(RunSize_by_Stock!C5-Escapements!C6)/RunSize_by_Stock!C5,"") -> 0.34258583 | D53: =IF(RunSize_by_Stock!D5>0,(RunSize_by_Stock!D5-Escapements!D6)/RunSize_by_Stock!D5,"") -> 0.21052632 | E53: =IF(RunSize_by_Stock!E5>0,(RunSize_by_Stock!E5-Escapements!E6)/RunSize_by_Stock!E5,"") -> 0.23076923 | F53: =IF(RunSize_by_Stock!F5>0,(RunSize_by_Stock!F5-Escapements!F6)/RunSize_by_Stock!F5,"") -> 0.24114671 | G53: =IF(RunSize_by_Stock!G5>0,(RunSize_by_Stock!G5-Escapements!G6)/RunSize_by_Stock!G5,"") -> 0.23076923 | H53: =IF(RunSize_by_Stock!H5>0,(RunSize_by_Stock!H5-Escapements!H6)/RunSize_by_Stock!H5,"") -> 0.23076923 | I53: =IF(RunSize_by_Stock!I5>0,(RunSize_by_Stock!I5-Escapements!I6)/RunSize_by_Stock!I5,"") -> 0.24242424 | ... CG53: =IF(RunSize_by_Stock!CG5>0,(RunSize_by_Stock!CG5-Escapements!CG6)/RunSize_by_Stock!CG5,"") -> 0.34717191 | CH53: =AVERAGE(B53:CG53) -> 0.40783532
A54: =A7 -> 1983 | B54: =IF(RunSize_by_Stock!B6>0,(RunSize_by_Stock!B6-Escapements!B7)/RunSize_by_Stock!B6,"") -> 0.20273349 | C54: =IF(RunSize_by_Stock!C6>0,(RunSize_by_Stock!C6-Escapements!C7)/RunSize_by_Stock!C6,"") -> 0.23487544 | D54: =IF(RunSize_by_Stock!D6>0,(RunSize_by_Stock!D6-Escapements!D7)/RunSize_by_Stock!D6,"") -> 0.2 | E54: =IF(RunSize_by_Stock!E6>0,(RunSize_by_Stock!E6-Escapements!E7)/RunSize_by_Stock!E6,"") -> 0.21052632 | F54: =IF(RunSize_by_Stock!F6>0,(RunSize_by_Stock!F6-Escapements!F7)/RunSize_by_Stock!F6,"") -> 0.21819474 | G54: =IF(RunSize_by_Stock!G6>0,(RunSize_by_Stock!G6-Escapements!G7)/RunSize_by_Stock!G6,"") -> 0.21052632 | H54: =IF(RunSize_by_Stock!H6>0,(RunSize_by_Stock!H6-Escapements!H7)/RunSize_by_Stock!H6,"") -> 0.23076923 | I54: =IF(RunSize_by_Stock!I6>0,(RunSize_by_Stock!I6-Escapements!I7)/RunSize_by_Stock!I6,"") -> 0.23076923 | ... CG54: =IF(RunSize_by_Stock!CG6>0,(RunSize_by_Stock!CG6-Escapements!CG7)/RunSize_by_Stock!CG6,"") -> 0.15893419 | CH54: =AVERAGE(B54:CG54) -> 0.28945686
A55: =A8 -> 1984 | B55: =IF(RunSize_by_Stock!B7>0,(RunSize_by_Stock!B7-Escapements!B8)/RunSize_by_Stock!B7,"") -> 0.096385542 | C55: =IF(RunSize_by_Stock!C7>0,(RunSize_by_Stock!C7-Escapements!C8)/RunSize_by_Stock!C7,"") -> 0.18181818 | D55: =IF(RunSize_by_Stock!D7>0,(RunSize_by_Stock!D7-Escapements!D8)/RunSize_by_Stock!D7,"") -> 0.097472924 | E55: =IF(RunSize_by_Stock!E7>0,(RunSize_by_Stock!E7-Escapements!E8)/RunSize_by_Stock!E7,"") -> 0.10447761 | F55: =IF(RunSize_by_Stock!F7>0,(RunSize_by_Stock!F7-Escapements!F8)/RunSize_by_Stock!F7,"") -> 0.10348361 | G55: =IF(RunSize_by_Stock!G7>0,(RunSize_by_Stock!G7-Escapements!G8)/RunSize_by_Stock!G7,"") -> 0.076923077 | H55: =IF(RunSize_by_Stock!H7>0,(RunSize_by_Stock!H7-Escapements!H8)/RunSize_by_Stock!H7,"") -> 0.1 | I55: =IF(RunSize_by_Stock!I7>0,(RunSize_by_Stock!I7-Escapements!I8)/RunSize_by_Stock!I7,"") -> 0.10344828 | ... CG55: =IF(RunSize_by_Stock!CG7>0,(RunSize_by_Stock!CG7-Escapements!CG8)/RunSize_by_Stock!CG7,"") -> 0.39429697 | CH55: =AVERAGE(B55:CG55) -> 0.27784419
A56: =A9 -> 1985 | B56: =IF(RunSize_by_Stock!B8>0,(RunSize_by_Stock!B8-Escapements!B9)/RunSize_by_Stock!B8,"") -> 0.094339623 | C56: =IF(RunSize_by_Stock!C8>0,(RunSize_by_Stock!C8-Escapements!C9)/RunSize_by_Stock!C8,"") -> 0.1267321 | D56: =IF(RunSize_by_Stock!D8>0,(RunSize_by_Stock!D8-Escapements!D9)/RunSize_by_Stock!D8,"") -> 0.094707521 | E56: =IF(RunSize_by_Stock!E8>0,(RunSize_by_Stock!E8-Escapements!E9)/RunSize_by_Stock!E8,"") -> 0.099099099 | F56: =IF(RunSize_by_Stock!F8>0,(RunSize_by_Stock!F8-Escapements!F9)/RunSize_by_Stock!F8,"") -> 0.099437148 | G56: =IF(RunSize_by_Stock!G8>0,(RunSize_by_Stock!G8-Escapements!G9)/RunSize_by_Stock!G8,"") -> 0.16666667 | H56: =IF(RunSize_by_Stock!H8>0,(RunSize_by_Stock!H8-Escapements!H9)/RunSize_by_Stock!H8,"") -> 0.090909091 | I56: =IF(RunSize_by_Stock!I8>0,(RunSize_by_Stock!I8-Escapements!I9)/RunSize_by_Stock!I8,"") -> 0.095744681 | ... CG56: =IF(RunSize_by_Stock!CG8>0,(RunSize_by_Stock!CG8-Escapements!CG9)/RunSize_by_Stock!CG8,"") -> 0.44028013 | CH56: =AVERAGE(B56:CG56) -> 0.2279185
A57: =A10 -> 1986 | B57: =IF(RunSize_by_Stock!B9>0,(RunSize_by_Stock!B9-Escapements!B10)/RunSize_by_Stock!B9,"") -> 0.099099099 | C57: =IF(RunSize_by_Stock!C9>0,(RunSize_by_Stock!C9-Escapements!C10)/RunSize_by_Stock!C9,"") -> 0.084249084 | D57: =IF(RunSize_by_Stock!D9>0,(RunSize_by_Stock!D9-Escapements!D10)/RunSize_by_Stock!D9,"") -> 0.097938144 | E57: =IF(RunSize_by_Stock!E9>0,(RunSize_by_Stock!E9-Escapements!E10)/RunSize_by_Stock!E9,"") -> 0.10071942 | F57: =IF(RunSize_by_Stock!F9>0,(RunSize_by_Stock!F9-Escapements!F10)/RunSize_by_Stock!F9,"") -> 0.1015274 | G57: =IF(RunSize_by_Stock!G9>0,(RunSize_by_Stock!G9-Escapements!G10)/RunSize_by_Stock!G9,"") -> 0.11111111 | H57: =IF(RunSize_by_Stock!H9>0,(RunSize_by_Stock!H9-Escapements!H10)/RunSize_by_Stock!H9,"") -> 0.10714286 | I57: =IF(RunSize_by_Stock!I9>0,(RunSize_by_Stock!I9-Escapements!I10)/RunSize_by_Stock!I9,"") -> 0.10179641 | ... CG57: =IF(RunSize_by_Stock!CG9>0,(RunSize_by_Stock!CG9-Escapements!CG10)/RunSize_by_Stock!CG9,"") -> 0.22038617 | CH57: =AVERAGE(B57:CG57) -> 0.16093963
A58: =A11 -> 1987 | B58: =IF(RunSize_by_Stock!B10>0,(RunSize_by_Stock!B10-Escapements!B11)/RunSize_by_Stock!B10,"") -> 0.15325995 | C58: =IF(RunSize_by_Stock!C10>0,(RunSize_by_Stock!C10-Escapements!C11)/RunSize_by_Stock!C10,"") -> 0.085206482 | D58: =IF(RunSize_by_Stock!D10>0,(RunSize_by_Stock!D10-Escapements!D11)/RunSize_by_Stock!D10,"") -> 0.15254237 | E58: =IF(RunSize_by_Stock!E10>0,(RunSize_by_Stock!E10-Escapements!E11)/RunSize_by_Stock!E10,"") -> 0.140625 | F58: =IF(RunSize_by_Stock!F10>0,(RunSize_by_Stock!F10-Escapements!F11)/RunSize_by_Stock!F10,"") -> 0.13544669 | G58: =IF(RunSize_by_Stock!G10>0,(RunSize_by_Stock!G10-Escapements!G11)/RunSize_by_Stock!G10,"") -> 0.11764706 | H58: =IF(RunSize_by_Stock!H10>0,(RunSize_by_Stock!H10-Escapements!H11)/RunSize_by_Stock!H10,"") -> 0.13934426 | I58: =IF(RunSize_by_Stock!I10>0,(RunSize_by_Stock!I10-Escapements!I11)/RunSize_by_Stock!I10,"") -> 0.13978495 | ... CG58: =IF(RunSize_by_Stock!CG10>0,(RunSize_by_Stock!CG10-Escapements!CG11)/RunSize_by_Stock!CG10,"") -> 0.16728671 | CH58: =AVERAGE(B58:CG58) -> 0.17934609
A59: =A12 -> 1988 | B59: =IF(RunSize_by_Stock!B11>0,(RunSize_by_Stock!B11-Escapements!B12)/RunSize_by_Stock!B11,"") -> 0.13892078 | C59: =IF(RunSize_by_Stock!C11>0,(RunSize_by_Stock!C11-Escapements!C12)/RunSize_by_Stock!C11,"") -> 0.083199633 | D59: =IF(RunSize_by_Stock!D11>0,(RunSize_by_Stock!D11-Escapements!D12)/RunSize_by_Stock!D11,"") -> 0.13875598 | E59: =IF(RunSize_by_Stock!E11>0,(RunSize_by_Stock!E11-Escapements!E12)/RunSize_by_Stock!E11,"") -> 0.13043478 | F59: =IF(RunSize_by_Stock!F11>0,(RunSize_by_Stock!F11-Escapements!F12)/RunSize_by_Stock!F11,"") -> 0.12479741 | G59: =IF(RunSize_by_Stock!G11>0,(RunSize_by_Stock!G11-Escapements!G12)/RunSize_by_Stock!G11,"") -> 0.12790698 | H59: =IF(RunSize_by_Stock!H11>0,(RunSize_by_Stock!H11-Escapements!H12)/RunSize_by_Stock!H11,"") -> 0.125 | I59: =IF(RunSize_by_Stock!I11>0,(RunSize_by_Stock!I11-Escapements!I12)/RunSize_by_Stock!I11,"") -> 0.12698413 | ... CG59: =IF(RunSize_by_Stock!CG11>0,(RunSize_by_Stock!CG11-Escapements!CG12)/RunSize_by_Stock!CG11,"") -> 0.074487494 | CH59: =AVERAGE(B59:CG59) -> 0.14961183
A60: =A13 -> 1989 | B60: =IF(RunSize_by_Stock!B12>0,(RunSize_by_Stock!B12-Escapements!B13)/RunSize_by_Stock!B12,"") -> 0.19047619 | C60: =IF(RunSize_by_Stock!C12>0,(RunSize_by_Stock!C12-Escapements!C13)/RunSize_by_Stock!C12,"") -> 0.22203205 | D60: =IF(RunSize_by_Stock!D12>0,(RunSize_by_Stock!D12-Escapements!D13)/RunSize_by_Stock!D12,"") -> 0.19354839 | E60: =IF(RunSize_by_Stock!E12>0,(RunSize_by_Stock!E12-Escapements!E13)/RunSize_by_Stock!E12,"") -> 0.21052632 | F60: =IF(RunSize_by_Stock!F12>0,(RunSize_by_Stock!F12-Escapements!F13)/RunSize_by_Stock!F12,"") -> 0.20886076 | G60: =IF(RunSize_by_Stock!G12>0,(RunSize_by_Stock!G12-Escapements!G13)/RunSize_by_Stock!G12,"") -> 0.21169981 | H60: =IF(RunSize_by_Stock!H12>0,(RunSize_by_Stock!H12-Escapements!H13)/RunSize_by_Stock!H12,"") -> 0.2 | I60: =IF(RunSize_by_Stock!I12>0,(RunSize_by_Stock!I12-Escapements!I13)/RunSize_by_Stock!I12,"") -> 0.20634921 | ... CG60: =IF(RunSize_by_Stock!CG12>0,(RunSize_by_Stock!CG12-Escapements!CG13)/RunSize_by_Stock!CG12,"") -> 0.2968673 | CH60: =AVERAGE(B60:CG60) -> 0.2049151
A61: =A14 -> 1990 | B61: =IF(RunSize_by_Stock!B13>0,(RunSize_by_Stock!B13-Escapements!B14)/RunSize_by_Stock!B13,"") -> 0.093655589 | C61: =IF(RunSize_by_Stock!C13>0,(RunSize_by_Stock!C13-Escapements!C14)/RunSize_by_Stock!C13,"") -> 0.11660777 | D61: =IF(RunSize_by_Stock!D13>0,(RunSize_by_Stock!D13-Escapements!D14)/RunSize_by_Stock!D13,"") -> 0.090909091 | E61: =IF(RunSize_by_Stock!E13>0,(RunSize_by_Stock!E13-Escapements!E14)/RunSize_by_Stock!E13,"") -> 0.090909091 | F61: =IF(RunSize_by_Stock!F13>0,(RunSize_by_Stock!F13-Escapements!F14)/RunSize_by_Stock!F13,"") -> 0.097162511 | G61: =IF(RunSize_by_Stock!G13>0,(RunSize_by_Stock!G13-Escapements!G14)/RunSize_by_Stock!G13,"") -> 0.090909091 | H61: =IF(RunSize_by_Stock!H13>0,(RunSize_by_Stock!H13-Escapements!H14)/RunSize_by_Stock!H13,"") -> 0.090909091 | I61: =IF(RunSize_by_Stock!I13>0,(RunSize_by_Stock!I13-Escapements!I14)/RunSize_by_Stock!I13,"") -> 0.099099099 | ... CG61: =IF(RunSize_by_Stock!CG13>0,(RunSize_by_Stock!CG13-Escapements!CG14)/RunSize_by_Stock!CG13,"") -> 0.34925226 | CH61: =AVERAGE(B61:CG61) -> 0.18849585
