Workbook
Name aa: 'Orig data'!$B$1
Name ar: #REF!
Name bb: 'Orig data'!$B$2
Name br: #REF!
Name cslope: 'Orig data'!$AT$3
Name negLL: #REF!
Name nlim: 'Orig data'!$AV$3
Name retroU: 'Orig data'!$AN$2
Name retroUtil: 'Orig data'!$AX$1
Name retroY: 'Orig data'!$AN$3
Name rho: #REF!
Name sige: #REF!
Name sigev: #REF!
Name sigr: #REF!
Name umethod: 'Orig data'!$AR$2

Sheet Orig data
A1: aa | B1: =INTERCEPT(I5:I71,G5:G71) -> 1.129053 | C1: smsy | D1: =aa/bb*(1-0.07*aa) -> 1688967.4 | E1: Nmsy | F1: =D1/(1-D2) -> 3218878.6 | U1: Age 3 | V1: Age 4 | W1: Age 5 | X1: Age 6 | AJ1: retrtospective model in columns AJ-AO | AQ1: switch between historical and policy-based Ut values: | AW1: retroUtil | AX1: =SUMPRODUCT(AO5:AO76^0.6) -> 146494.56
A2: bb | B2: =-SLOPE(I5:I71,G5:G71) -> 6.1565412e-07 | C2: umsy | D2: =0.5*aa-0.07*aa^2 -> 0.47529324 | E2: msy | F2: =F1-D1 -> 1529911.2 | G2: Best S-R data | U2: 0.3 | V2: 0.6 | W2: 0.1 | X2: 0 | AM2: retroU | AN2: 0.5 | AQ2: Ut method | AR2: 1 | AS2: 1=historical,2=retroU,3=linear hcr | AW2: =retroY -> 26591286 | AX2: =retroUtil -> 146494.56
A3: Cass, Grant, Digitized, Haley's S/R | G3: Using age prop. by yr from 1996-2017 | K3: Haley's Best S/R | U3: recruits produced at age from Brood Year | AM3: retroY | AN3: =SUM(AO5:AO76) -> 26591286 | AO3: historical Y | AP3: =SUM(R5:R76)-SUM(G5:G76) -> 26787906 | AR3: linear hcr pars | AS3: cslope | AT3: 0.77633553 | AU3: nlim | AV3: 487692.73 | AY3: Johnstone | AZ3: Georgia. | BA3: West | BC3: U.S. | BD3: All Fraser | BE3: Total | BF3: Harvest | BG3: Gross (d) | BH3: Total | BJ3: Johnstone | BK3: West Coast | BP3: Johnstone | BQ3: West Coast
A4: Source | B4: Brood year | C4: Spawners (D) | D4: Haley's Recruits with some infill from mkm | E4: ln(R/S)(H) | F4: Source | G4: Spawners (D) | H4: Recruits | I4: ln(R/S)(D) | J4: wt | K4: broodyear | L4: spawners | M4: recruits | O4: Source | P4: Year | Q4: Gross Escapement | R4: total Stock, hr from Grant then Brittany | S4: Ut | T4: tot stock digitized from DFO 2023 | U4: Age 3 | V4: Age 4 | W4: Age 5 | X4: Age 6 | Y4: Recruits sum age | AD4: Improved recruits starting 1990 | AE4: brood year | AF4: rp3 | AG4: rp4 | AH4: rp5 | AJ4: year | AK4: retro run | AL4: retro U | AM4: retro spawners | AN4: retro Recruits | AO4: retro Yield | AW4: Source | AX4: Year | AY4: Strait (a) | AZ4: Strait | BA4: Coast (b) | BB4: 7&7A | BC4: 4B,5,6C | BD4: Harvest (c) | BE4: Harvest | BF4: Rate | BG4: Escapement | BH4: Stock | BI4: HR | BJ4: St. HR | BK4: HR | BL4: Fraser R HR | BM4: hr | BN4: catch | BP4: St. HR | BQ4: HR | BR4: Fraser R HR
A5: =O5 -> Cass | B5: =K5 -> 1951 | C5: =L5 -> 171725 | D5: =M5 -> 498986 | E5: =LN(D5/C5) -> 1.0666837 | F5: =A5 -> Cass | G5: =Q5 -> 171725 | H5: =Y5 -> 595477.2 | I5: =LN(H5/G5) -> 1.2434687 | J5: =I5-(aa-bb*G5) -> 0.22013898 | K5: 1951 | L5: 171725 | M5: 498986 | O5: =AW5 -> Cass | P5: =AX5 -> 1951 | Q5: =BG5 -> 171725 | R5: =BH5 -> 1187739 | S5: =1-Q5/R5 -> 0.85541857 | U5: =$R8*U$2 -> 328955.1 | V5: =$R9*V$2 -> 238259.4 | W5: =$R10*W$2 -> 28262.7 | X5: =$R11*X$2 -> 0 | Y5: =SUM(U5:X5) -> 595477.2 | AD5: =Y5 -> 595477.2 | AE5: =B5 -> 1951 | AF5: =U5/$Y5 -> 0.55242266 | AG5: =V5/$Y5 -> 0.40011507 | AH5: =W5/$Y5 -> 0.047462271 | AJ5: =B5 -> 1951 | AK5: =R5 -> 1187739 | AL5: =CHOOSE(umethod,S5,retroU,MAX(0,cslope*(AK5-nlim)/AK5)) -> 0.85541857 | AM5: =AK5*(1-AL5) -> 171725 | AN5: =AM5*EXP(aa-bb*AM5+J5) -> 595477.2 | AO5: =AK5-AM5 -> 1016014 | AW5: Cass | AX5: 1951 | AY5: 523874 | AZ5: N/A | BA5: 302 | BB5: 0 | BC5: 23 | BD5: 491815 | BE5: 1016014 | BF5: 0.86 | BG5: 171725 | BH5: 1187739 | BI5: =BE5/BH5 -> 0.85541857 | BJ5: =AY5/BH5 -> 0.44106828 | BK5: =BA5/(BH5-AY5) -> 0.00045491177 | BL5: =BD5/(BH5-AY5-BA5-BC5) -> 0.74119872 | BM5: =BE5/BH5 -> 0.85541857 | BN5: =BG5*BM5/(1-BM5) -> 1016014 | BP5: =BJ5/(SUM($BJ5:$BL5)) -> 0.37292645 | BQ5: =BK5/(SUM($BJ5:$BL5)) -> 0.00038463121 | BR5: =BL5/(SUM($BJ5:$BL5)) -> 0.62668892 | CO5: Grant vs. Cass
A6: =O6 -> Cass | B6: =K6 -> 1952 | C6: =L6 -> 176250 | D6: =M6 -> 283055 | E6: =LN(D6/C6) -> 0.47373778 | F6: =A6 -> Cass | G6: =Q6 -> 176250 | H6: =Y6 -> 319542.2 | I6: =LN(H6/G6) -> 0.5949859 | J6: =I6-(aa-bb*G6) -> -0.42555802 | K6: 1952 | L6: 176250 | M6: 283055 | O6: =AW6 -> Cass | P6: =AX6 -> 1952 | Q6: =BG6 -> 176250 | R6: =BH6 -> 927000 | S6: =1-Q6/R6 -> 0.80987055 | U6: =$R9*U$2 -> 119129.7 | V6: =$R10*V$2 -> 169576.2 | W6: =$R11*W$2 -> 30836.3 | X6: =$R12*X$2 -> 0 | Y6: =SUM(U6:X6) -> 319542.2 | AD6: =Y6 -> 319542.2 | AE6: =B6 -> 1952 | AF6: =U6/$Y6 -> 0.37281367 | AG6: =V6/$Y6 -> 0.53068484 | AH6: =W6/$Y6 -> 0.096501495 | AJ6: =B6 -> 1952 | AK6: =R6 -> 927000 | AL6: =CHOOSE(umethod,S6,retroU,MAX(0,cslope*(AK6-nlim)/AK6)) -> 0.80987055 | AM6: =AK6*(1-AL6) -> 176250 | AN6: =AM6*EXP(aa-bb*AM6+J6) -> 319542.2 | AO6: =AK6-AM6 -> 750750 | AS6: =retroY -> 26591286 | AW6: Cass | AX6: 1952 | AY6: 191249 | AZ6: N/A | BA6: 108 | BB6: 0 | BC6: 0 | BD6: 559393 | BE6: 750750 | BF6: 0.81 | BG6: 176250 | BH6: 927000 | BI6: =BE6/BH6 -> 0.80987055 | BJ6: =AY6/BH6 -> 0.2063096 | BK6: =BA6/(BH6-AY6) -> 0.00014678879 | BL6: =BD6/(BH6-AY6-BA6-BC6) -> 0.76041368 | BM6: =BE6/BH6 -> 0.80987055 | BN6: =BG6*BM6/(1-BM6) -> 750750 | BP6: =BJ6/(SUM($BJ6:$BL6)) -> 0.21337883 | BQ6: =BK6/(SUM($BJ6:$BL6)) -> 0.00015181853 | BR6: =BL6/(SUM($BJ6:$BL6)) -> 0.78646935 | CB6: Source | CC6: Year | CD6: Total Returns | CE6: Areas 11 to 13 | CF6: Area 14 | CG6: Areas 20 & 21 | CH6: Areas 7 & 7a | CI6: Areas 4b, 5, 6c | CJ6: Fraser | CK6: Gross Escapement | CL6: Gross Esc+catch | CN6: Total exploitation rate | CO6: Year | CP6: %dif tot returns | CQ6: %dif gross escape
A7: =O7 -> Grant | B7: =K7 -> 1953 | C7: =L7 -> 137225 | D7: =M7 -> 312122 | E7: =LN(D7/C7) -> 0.82177222 | F7: =A7 -> Grant | G7: =Q7 -> 137625 | H7: =Y7 -> 325788.8 | I7: =LN(H7/G7) -> 0.86171672 | J7: =I7-(aa-bb*G7) -> -0.18260684 | K7: 1953 | L7: 137225 | M7: 312122 | O7: =CB7 -> Grant | P7: =CC7 -> 1953 | Q7: =CK7 -> 137625 | R7: =CD7 -> 918122 | S7: =1-Q7/R7 -> 0.85010162 | U7: =$R10*U$2 -> 84788.1 | V7: =$R11*V$2 -> 185017.8 | W7: =$R12*W$2 -> 55982.9 | X7: =$R13*X$2 -> 0 | Y7: =SUM(U7:X7) -> 325788.8 | AD7: =Y7 -> 325788.8 | AE7: =B7 -> 1953 | AF7: =U7/$Y7 -> 0.2602548 | AG7: =V7/$Y7 -> 0.56790718 | AH7: =W7/$Y7 -> 0.17183801 | AJ7: =B7 -> 1953 | AK7: =R7 -> 918122 | AL7: =CHOOSE(umethod,S7,retroU,MAX(0,cslope*(AK7-nlim)/AK7)) -> 0.85010162 | AM7: =AK7*(1-AL7) -> 137625 | AN7: =AM7*EXP(aa-bb*AM7+J7) -> 325788.8 | AO7: =AK7-AM7 -> 780497 | AR7: 0.05 | AS7: 26591286 | AW7: Cass | AX7: 1953 | AY7: 465021 | AZ7: N/A | BA7: 404 | BB7: 0 | BC7: 0 | BD7: 331804 | BE7: 797229 | BF7: 0.85 | BG7: 137225 | BH7: 934454 | BI7: =BE7/BH7 -> 0.85314954 | BJ7: =AY7/BH7 -> 0.49763926 | BK7: =BA7/(BH7-AY7) -> 0.0008606127 | BL7: =BD7/(BH7-AY7-BA7-BC7) -> 0.70742747 | BM7: =BE7/BH7 -> 0.85314954 | BN7: =BG7*BM7/(1-BM7) -> 797229 | BP7: =BJ7/(SUM($BJ7:$BL7)) -> 0.41266106 | BQ7: =BK7/(SUM($BJ7:$BL7)) -> 0.00071365219 | BR7: =BL7/(SUM($BJ7:$BL7)) -> 0.58662528 | CB7: Grant | CC7: 1953 | CD7: 918122 | CE7: 434551 | CF7: 10184 | CG7: 3947 | CH7: 0 | CI7: 0 | CJ7: 331815 | CK7: 137625 | CL7: =SUM(CE7:CK7) -> 918122 | CN7: 0.85 | CO7: =CC7 -> 1953 | CP7: =(CD7-BH7)/BH7 -> -0.017477586 | CQ7: =(CK7-BG7)/BG7 -> 0.0029149208
A8: =O8 -> Grant | B8: =K8 -> 1954 | C8: =L8 -> 86375 | D8: =M8 -> 504589 | E8: =LN(D8/C8) -> 1.765046 | F8: =A8 -> Grant | G8: =Q8 -> 86375 | H8: =Y8 -> 493568.5 | I8: =LN(H8/G8) -> 1.7429634 | J8: =I8-(aa-bb*G8) -> 0.66708753 | K8: 1954 | L8: 86375 | M8: 504589 | O8: =CB8 -> Grant | P8: =CC8 -> 1954 | Q8: =CK8 -> 86375 | R8: =CD8 -> 1096517 | S8: =1-Q8/R8 -> 0.92122785 | U8: =$R11*U$2 -> 92508.9 | V8: =$R12*V$2 -> 335897.4 | W8: =$R13*W$2 -> 65162.2 | X8: =$R14*X$2 -> 0 | Y8: =SUM(U8:X8) -> 493568.5 | AD8: =Y8 -> 493568.5 | AE8: =B8 -> 1954 | AF8: =U8/$Y8 -> 0.1874287 | AG8: =V8/$Y8 -> 0.6805487 | AH8: =W8/$Y8 -> 0.13202261 | AJ8: =B8 -> 1954 | AK8: =R8 -> 1096517 | AL8: =CHOOSE(umethod,S8,retroU,MAX(0,cslope*(AK8-nlim)/AK8)) -> 0.92122785 | AM8: =AK8*(1-AL8) -> 86375 | AN8: =AM8*EXP(aa-bb*AM8+J8) -> 493568.5 | AO8: =AK8-AM8 -> 1010142 | AR8: 0.1 | AS8: 26591286 | AW8: Cass | AX8: 1954 | AY8: 590473 | AZ8: N/A | BA8: 253 | BB8: 0 | BC8: 0 | BD8: 457750 | BE8: 1048476 | BF8: 0.92 | BG8: 86375 | BH8: 1134851 | BI8: =BE8/BH8 -> 0.92388869 | BJ8: =AY8/BH8 -> 0.52030883 | BK8: =BA8/(BH8-AY8) -> 0.0004647506 | BL8: =BD8/(BH8-AY8-BA8-BC8) -> 0.8412589 | BM8: =BE8/BH8 -> 0.92388869 | BN8: =BG8*BM8/(1-BM8) -> 1048476 | BP8: =BJ8/(SUM($BJ8:$BL8)) -> 0.38200912 | BQ8: =BK8/(SUM($BJ8:$BL8)) -> 0.00034121844 | BR8: =BL8/(SUM($BJ8:$BL8)) -> 0.61764966 | CB8: Grant | CC8: 1954 | CD8: 1096517 | CE8: 542719 | CF8: 8768 | CG8: 1248 | CH8: 0 | CI8: 0 | CJ8: 457407 | CK8: 86375 | CL8: =SUM(CE8:CK8) -> 1096517 | CN8: 0.921 | CO8: =CC8 -> 1954 | CP8: =(CD8-BH8)/BH8 -> -0.033778884 | CQ8: =(CK8-BG8)/BG8 -> 0
A9: =O9 -> Grant | B9: =K9 -> 1955 | C9: =L9 -> 110500 | D9: =M9 -> 592568 | E9: =LN(D9/C9) -> 1.6794501 | F9: =A9 -> Grant | G9: =Q9 -> 110500 | H9: =Y9 -> 597993.3 | I9: =LN(H9/G9) -> 1.688564 | J9: =I9-(aa-bb*G9) -> 0.62754085 | K9: 1955 | L9: 110500 | M9: 592568 | O9: =CB9 -> Grant | P9: =CC9 -> 1955 | Q9: =CK9 -> 110500 | R9: =CD9 -> 397099 | S9: =1-Q9/R9 -> 0.72173186 | U9: =$R12*U$2 -> 167948.7 | V9: =$R13*V$2 -> 390973.2 | W9: =$R14*W$2 -> 39071.4 | X9: =$R15*X$2 -> 0 | Y9: =SUM(U9:X9) -> 597993.3 | AD9: =Y9 -> 597993.3 | AE9: =B9 -> 1955 | AF9: =U9/$Y9 -> 0.28085382 | AG9: =V9/$Y9 -> 0.65380866 | AH9: =W9/$Y9 -> 0.065337521 | AJ9: =B9 -> 1955 | AK9: =AF6*AN6+AG5*AN5 -> 357389.1 | AL9: =CHOOSE(umethod,S9,retroU,MAX(0,cslope*(AK9-nlim)/AK9)) -> 0.72173186 | AM9: =AK9*(1-AL9) -> 99450 | AN9: =AM9*EXP(aa-bb*AM9+J9) -> 541867.77 | AO9: =AK9-AM9 -> 257939.1 | AR9: 0.15 | AS9: 26591286 | AW9: Cass | AX9: 1955 | AY9: 143565 | AZ9: N/A | BA9: 759 | BB9: 0 | BC9: 9 | BD9: 103297 | BE9: 247630 | BF9: 0.69 | BG9: 110500 | BH9: 358130 | BI9: =BE9/BH9 -> 0.69145282 | BJ9: =AY9/BH9 -> 0.40087398 | BK9: =BA9/(BH9-AY9) -> 0.0035373896 | BL9: =BD9/(BH9-AY9-BA9-BC9) -> 0.48315458 | BM9: =BE9/BH9 -> 0.69145282 | BN9: =BG9*BM9/(1-BM9) -> 247630 | BP9: =BJ9/(SUM($BJ9:$BL9)) -> 0.45165543 | BQ9: =BK9/(SUM($BJ9:$BL9)) -> 0.0039854949 | BR9: =BL9/(SUM($BJ9:$BL9)) -> 0.54435907 | CB9: Grant | CC9: 1955 | CD9: 397099 | CE9: 174665 | CF9: 634 | CG9: 8217 | CH9: 0 | CI9: 0 | CJ9: 103084 | CK9: 110500 | CL9: =SUM(CE9:CK9) -> 397100 | CN9: 0.722 | CO9: =CC9 -> 1955 | CP9: =(CD9-BH9)/BH9 -> 0.10881244 | CQ9: =(CK9-BG9)/BG9 -> 0
A10: =O10 -> Grant | B10: =K10 -> 1956 | C10: =L10 -> 32925 | D10: =M10 -> 518932 | E10: =LN(D10/C10) -> 2.7575406 | F10: =A10 -> Grant | G10: =Q10 -> 32950 | H10: =Y10 -> 455279.4 | I10: =LN(H10/G10) -> 2.62592 | J10: =I10-(aa-bb*G10) -> 1.5171529 | K10: 1956 | L10: 32925 | M10: 518932 | O10: =CB10 -> Grant | P10: =CC10 -> 1956 | Q10: =CK10 -> 32950 | R10: =CD10 -> 282627 | S10: =1-Q10/R10 -> 0.88341524 | U10: =$R13*U$2 -> 195486.6 | V10: =$R14*V$2 -> 234428.4 | W10: =$R15*W$2 -> 25364.4 | X10: =$R16*X$2 -> 0 | Y10: =SUM(U10:X10) -> 455279.4 | AD10: =Y10 -> 455279.4 | AE10: =B10 -> 1956 | AF10: =U10/$Y10 -> 0.42937721 | AG10: =V10/$Y10 -> 0.51491106 | AH10: =W10/$Y10 -> 0.055711723 | AJ10: =B10 -> 1956 | AK10: =AF7*AN7+AG6*AN6+AH5*AN5 -> 282627 | AL10: =CHOOSE(umethod,S10,retroU,MAX(0,cslope*(AK10-nlim)/AK10)) -> 0.88341524 | AM10: =AK10*(1-AL10) -> 32950 | AN10: =AM10*EXP(aa-bb*AM10+J10) -> 455279.4 | AO10: =AK10-AM10 -> 249677 | AR10: 0.2 | AS10: 26591286 | AW10: Cass | AX10: 1956 | AY10: 155668 | AZ10: N/A | BA10: 61 | BB10: 0 | BC10: 0 | BD10: 72958 | BE10: 228687 | BF10: 0.87 | BG10: 32925 | BH10: 261612 | BI10: =BE10/BH10 -> 0.87414568 | BJ10: =AY10/BH10 -> 0.59503387 | BK10: =BA10/(BH10-AY10) -> 0.00057577588 | BL10: =BD10/(BH10-AY10-BA10-BC10) -> 0.68904357 | BM10: =BE10/BH10 -> 0.87414568 | BN10: =BG10*BM10/(1-BM10) -> 228687 | BP10: =BJ10/(SUM($BJ10:$BL10)) -> 0.46318638 | BQ10: =BK10/(SUM($BJ10:$BL10)) -> 0.00044819557 | BR10: =BL10/(SUM($BJ10:$BL10)) -> 0.53636543 | CB10: Grant | CC10: 1956 | CD10: 282627 | CE10: 175589 | CF10: 685 | CG10: 591 | CH10: 0 | CI10: 0 | CJ10: 72812 | CK10: 32950 | CL10: =SUM(CE10:CK10) -> 282627 | CN10: 0.883 | CO10: =CC10 -> 1956 | CP10: =(CD10-BH10)/BH10 -> 0.080328884 | CQ10: =(CK10-BG10)/BG10 -> 0.00075930144
A11: =O11 -> Grant | B11: =K11 -> 1957 | C11: =L11 -> 84630 | D11: =M11 -> 353281 | E11: =LN(D11/C11) -> 1.428975 | F11: =A11 -> Grant | G11: =Q11 -> 84655 | H11: =Y11 -> 294324.5 | I11: =LN(H11/G11) -> 1.2460987 | J11: =I11-(aa-bb*G11) -> 0.16916396 | K11: 1957 | L11: 84630 | M11: 353281 | O11: =CB11 -> Grant | P11: =CC11 -> 1957 | Q11: =CK11 -> 84655 | R11: =CD11 -> 308363 | S11: =1-Q11/R11 -> 0.72546966 | U11: =$R14*U$2 -> 117214.2 | V11: =$R15*V$2 -> 152186.4 | W11: =$R16*W$2 -> 24923.9 | X11: =$R17*X$2 -> 0 | Y11: =SUM(U11:X11) -> 294324.5 | AD11: =Y11 -> 294324.5 | AE11: =B11 -> 1957 | AF11: =U11/$Y11 -> 0.39824819 | AG11: =V11/$Y11 -> 0.5170701 | AH11: =W11/$Y11 -> 0.084681703 | AJ11: =B11 -> 1957 | AK11: =AF8*AN8+AG7*AN7+AH6*AN6 -> 308363 | AL11: =CHOOSE(umethod,S11,retroU,MAX(0,cslope*(AK11-nlim)/AK11)) -> 0.72546966 | AM11: =AK11*(1-AL11) -> 84655 | AN11: =AM11*EXP(aa-bb*AM11+J11) -> 294324.5 | AO11: =AK11-AM11 -> 223708 | AR11: 0.25 | AS11: 26591286 | AW11: Cass | AX11: 1957 | AY11: 92528 | AZ11: N/A | BA11: 123 | BB11: 0 | BC11: 48 | BD11: 124319 | BE11: 217018 | BF11: 0.72 | BG11: 84630 | BH11: 301648 | BI11: =BE11/BH11 -> 0.7194412 | BJ11: =AY11/BH11 -> 0.30674163 | BK11: =BA11/(BH11-AY11) -> 0.00058817904 | BL11: =BD11/(BH11-AY11-BA11-BC11) -> 0.59497294 | BM11: =BE11/BH11 -> 0.7194412 | BN11: =BG11*BM11/(1-BM11) -> 217018 | BP11: =BJ11/(SUM($BJ11:$BL11)) -> 0.33995423 | BQ11: =BK11/(SUM($BJ11:$BL11)) -> 0.0006518644 | BR11: =BL11/(SUM($BJ11:$BL11)) -> 0.65939391 | CB11: Grant | CC11: 1957 | CD11: 308363 | CE11: 97399 | CF11: 600 | CG11: 1444 | CH11: 0 | CI11: 0 | CJ11: 124265 | CK11: 84655 | CL11: =SUM(CE11:CK11) -> 308363 | CN11: 0.725 | CO11: =CC11 -> 1957 | CP11: =(CD11-BH11)/BH11 -> 0.022261046 | CQ11: =(CK11-BG11)/BG11 -> 0.00029540352
A12: =O12 -> Grant | B12: =K12 -> 1958 | C12: =L12 -> 89375 | D12: =M12 -> 302174 | E12: =LN(D12/C12) -> 1.218162 | F12: =A12 -> Grant | G12: =Q12 -> 89400 | H12: =Y12 -> 259625 | I12: =LN(H12/G12) -> 1.0661176 | J12: =I12-(aa-bb*G12) -> -0.0078958852 | K12: 1958 | L12: 89375 | M12: 302174 | O12: =CB12 -> Grant | P12: =CC12 -> 1958 | Q12: =CK12 -> 89400 | R12: =CD12 -> 559829 | S12: =1-Q12/R12 -> 0.84030838 | U12: =$R15*U$2 -> 76093.2 | V12: =$R16*V$2 -> 149543.4 | W12: =$R17*W$2 -> 33988.4 | X12: =$R18*X$2 -> 0 | Y12: =SUM(U12:X12) -> 259625 | AD12: =Y12 -> 259625 | AE12: =B12 -> 1958 | AF12: =U12/$Y12 -> 0.29308888 | AG12: =V12/$Y12 -> 0.57599769 | AH12: =W12/$Y12 -> 0.13091343 | AJ12: =B12 -> 1958 | AK12: =AF9*AN9+AG8*AN8+AH7*AN7 -> 544065.93 | AL12: =CHOOSE(umethod,S12,retroU,MAX(0,cslope*(AK12-nlim)/AK12)) -> 0.84030838 | AM12: =AK12*(1-AL12) -> 86882.77 | AN12: =AM12*EXP(aa-bb*AM12+J12) -> 252706.08 | AO12: =AK12-AM12 -> 457183.16 | AR12: 0.3 | AS12: 26591286 | AW12: Cass | AX12: 1958 | AY12: 252287 | AZ12: N/A | BA12: 1178 | BB12: 0 | BC12: 690 | BD12: 202075 | BE12: 456230 | BF12: 0.84 | BG12: 89375 | BH12: 545605 | BI12: =BE12/BH12 -> 0.83619102 | BJ12: =AY12/BH12 -> 0.46239862 | BK12: =BA12/(BH12-AY12) -> 0.004016119 | BL12: =BD12/(BH12-AY12-BA12-BC12) -> 0.69334363 | BM12: =BE12/BH12 -> 0.83619102 | BN12: =BG12*BM12/(1-BM12) -> 456230 | BP12: =BJ12/(SUM($BJ12:$BL12)) -> 0.39870255 | BQ12: =BK12/(SUM($BJ12:$BL12)) -> 0.0034628929 | BR12: =BL12/(SUM($BJ12:$BL12)) -> 0.59783455 | CB12: Grant | CC12: 1958 | CD12: 559829 | CE12: 247648 | CF12: 8879 | CG12: 11935 | CH12: 0 | CI12: 0 | CJ12: 201968 | CK12: 89400 | CL12: =SUM(CE12:CK12) -> 559830 | CN12: 0.84 | CO12: =CC12 -> 1958 | CP12: =(CD12-BH12)/BH12 -> 0.026070142 | CQ12: =(CK12-BG12)/BG12 -> 0.00027972028
A13: =O13 -> Grant | B13: =K13 -> 1959 | C13: =L13 -> 152300 | D13: =M13 -> 361837 | E13: =LN(D13/C13) -> 0.86534157 | F13: =A13 -> Grant | G13: =Q13 -> 152300 | H13: =Y13 -> 315857.7 | I13: =LN(H13/G13) -> 0.72943954 | J13: =I13-(aa-bb*G13) -> -0.30584931 | K13: 1959 | L13: 152300 | M13: 361837 | O13: =CB13 -> Grant | P13: =CC13 -> 1959 | Q13: =CK13 -> 152300 | R13: =CD13 -> 651622 | S13: =1-Q13/R13 -> 0.76627554 | U13: =$R16*U$2 -> 74771.7 | V13: =$R17*V$2 -> 203930.4 | W13: =$R18*W$2 -> 37155.6 | X13: =$R19*X$2 -> 0 | Y13: =SUM(U13:X13) -> 315857.7 | AD13: =Y13 -> 315857.7 | AE13: =B13 -> 1959 | AF13: =U13/$Y13 -> 0.23672591 | AG13: =V13/$Y13 -> 0.64564011 | AH13: =W13/$Y13 -> 0.11763399 | AJ13: =B13 -> 1959 | AK13: =AF10*AN10+AG9*AN9+AH8*AN8 -> 614926.64 | AL13: =CHOOSE(umethod,S13,retroU,MAX(0,cslope*(AK13-nlim)/AK13)) -> 0.76627554 | AM13: =AK13*(1-AL13) -> 143723.4 | AN13: =AM13*EXP(aa-bb*AM13+J13) -> 299648.57 | AO13: =AK13-AM13 -> 471203.25 | AR13: 0.35 | AS13: 26591286 | AW13: Cass | AX13: 1959 | AY13: 218898 | AZ13: N/A | BA13: 1448 | BB13: 0 | BC13: 996 | BD13: 237091 | BE13: 458433 | BF13: 0.75 | BG13: 152300 | BH13: 610733 | BI13: =BE13/BH13 -> 0.75062752 | BJ13: =AY13/BH13 -> 0.35841849 | BK13: =BA13/(BH13-AY13) -> 0.003695433 | BL13: =BD13/(BH13-AY13-BA13-BC13) -> 0.60887642 | BM13: =BE13/BH13 -> 0.75062752 | BN13: =BG13*BM13/(1-BM13) -> 458433 | BP13: =BJ13/(SUM($BJ13:$BL13)) -> 0.36912673 | BQ13: =BK13/(SUM($BJ13:$BL13)) -> 0.0038058391 | BR13: =BL13/(SUM($BJ13:$BL13)) -> 0.62706743 | CB13: Grant | CC13: 1959 | CD13: 651622 | CE13: 241353 | CF13: 5430 | CG13: 15632 | CH13: 0 | CI13: 0 | CJ13: 236907 | CK13: 152300 | CL13: =SUM(CE13:CK13) -> 651622 | CN13: 0.766 | CO13: =CC13 -> 1959 | CP13: =(CD13-BH13)/BH13 -> 0.066950697 | CQ13: =(CK13-BG13)/BG13 -> 0
A14: =O14 -> Grant | B14: =K14 -> 1960 | C14: =L14 -> 263700 | D14: =M14 -> 416907 | E14: =LN(D14/C14) -> 0.45805108 | F14: =A14 -> Grant | G14: =Q14 -> 144782 | H14: =Y14 -> 341946 | I14: =LN(H14/G14) -> 0.85942367 | J14: =I14-(aa-bb*G14) -> -0.18049366 | K14: 1960 | L14: 263700 | M14: 416907 | O14: =CB14 -> Grant | P14: =CC14 -> 1960 | Q14: =CK14 -> 144782 | R14: =CD14 -> 390714 | S14: =1-Q14/R14 -> 0.62944251 | U14: =$R17*U$2 -> 101965.2 | V14: =$R18*V$2 -> 222933.6 | W14: =$R19*W$2 -> 17047.2 | X14: =$R20*X$2 -> 0 | Y14: =SUM(U14:X14) -> 341946 | AD14: =Y14 -> 341946 | AE14: =B14 -> 1960 | AF14: =U14/$Y14 -> 0.29819094 | AG14: =V14/$Y14 -> 0.65195557 | AH14: =W14/$Y14 -> 0.049853486 | AJ14: =B14 -> 1960 | AK14: =AF11*AN11+AG10*AN10+AH9*AN9 -> 387046.9 | AL14: =CHOOSE(umethod,S14,retroU,MAX(0,cslope*(AK14-nlim)/AK14)) -> 0.62944251 | AM14: =AK14*(1-AL14) -> 143423.13 | AN14: =AM14*EXP(aa-bb*AM14+J14) -> 339020.12 | AO14: =AK14-AM14 -> 243623.77 | AR14: 0.4 | AS14: 26591286 | AW14: Cass | AX14: 1960 | AY14: 146889 | AZ14: N/A | BA14: 4618 | BB14: 21523 | BC14: 185 | BD14: 77262 | BE14: 250476 | BF14: 0.49 | BG14: 263700 | BH14: 514176 | BI14: =BE14/BH14 -> 0.48714059 | BJ14: =AY14/BH14 -> 0.28567844 | BK14: =BA14/(BH14-AY14) -> 0.012573274 | BL14: =BD14/(BH14-AY14-BA14-BC14) -> 0.21314596 | BM14: =BE14/BH14 -> 0.48714059 | BN14: =BG14*BM14/(1-BM14) -> 250476 | BP14: =BJ14/(SUM($BJ14:$BL14)) -> 0.55862288 | BQ14: =BK14/(SUM($BJ14:$BL14)) -> 0.024586099 | BR14: =BL14/(SUM($BJ14:$BL14)) -> 0.41679102 | CB14: Grant | CC14: 1960 | CD14: 390714 | CE14: 141635 | CF14: 1189 | CG14: 4310 | CH14: 21523 | CI14: 185 | CJ14: 77090 | CK14: 144782 | CL14: =SUM(CE14:CK14) -> 390714 | CN14: 0.629 | CO14: =CC14 -> 1960 | CP14: =(CD14-BH14)/BH14 -> -0.24011622 | CQ14: =(CK14-BG14)/BG14 -> -0.45095942
A15: =O15 -> Grant | B15: =K15 -> 1961 | C15: =L15 -> 172700 | D15: =M15 -> 288161 | E15: =LN(D15/C15) -> 0.51196337 | F15: =A15 -> Grant | G15: =Q15 -> 103920 | H15: =Y15 -> 255725.9 | I15: =LN(H15/G15) -> 0.9004848 | J15: =I15-(aa-bb*G15) -> -0.16458939 | K15: 1961 | L15: 172700 | M15: 288161 | O15: =CB15 -> Grant | P15: =CC15 -> 1961 | Q15: =CK15 -> 103920 | R15: =CD15 -> 253644 | S15: =1-Q15/R15 -> 0.59029191 | U15: =$R18*U$2 -> 111466.8 | V15: =$R19*V$2 -> 102283.2 | W15: =$R20*W$2 -> 41975.9 | X15: =$R21*X$2 -> 0 | Y15: =SUM(U15:X15) -> 255725.9 | AD15: =Y15 -> 255725.9 | AE15: =B15 -> 1961 | AF15: =U15/$Y15 -> 0.43588389 | AG15: =V15/$Y15 -> 0.399972 | AH15: =W15/$Y15 -> 0.16414411 | AJ15: =B15 -> 1961 | AK15: =AF12*AN12+AG11*AN11+AH10*AN10 -> 251616.14 | AL15: =CHOOSE(umethod,S15,retroU,MAX(0,cslope*(AK15-nlim)/AK15)) -> 0.59029191 | AM15: =AK15*(1-AL15) -> 103089.17 | AN15: =AM15*EXP(aa-bb*AM15+J15) -> 253811.19 | AO15: =AK15-AM15 -> 148526.97 | AR15: 0.45 | AS15: 26591286 | AW15: Cass | AX15: 1961 | AY15: 65963 | AZ15: N/A | BA15: 5894 | BB15: 15803 | BC15: 20 | BD15: 57545 | BE15: 145224 | BF15: 0.46 | BG15: 172700 | BH15: 317924 | BI15: =BE15/BH15 -> 0.45678841 | BJ15: =AY15/BH15 -> 0.2074804 | BK15: =BA15/(BH15-AY15) -> 0.023392509 | BL15: =BD15/(BH15-AY15-BA15-BC15) -> 0.23387808 | BM15: =BE15/BH15 -> 0.45678841 | BN15: =BG15*BM15/(1-BM15) -> 145224 | BP15: =BJ15/(SUM($BJ15:$BL15)) -> 0.44643348 | BQ15: =BK15/(SUM($BJ15:$BL15)) -> 0.050333425 | BR15: =BL15/(SUM($BJ15:$BL15)) -> 0.50323309 | CB15: Grant | CC15: 1961 | CD15: 253644 | CE15: 69640 | CF15: 1131 | CG15: 5676 | CH15: 15803 | CI15: 20 | CJ15: 57454 | CK15: 103920 | CL15: =SUM(CE15:CK15) -> 253644 | CN15: 0.59 | CO15: =CC15 -> 1961 | CP15: =(CD15-BH15)/BH15 -> -0.20218669 | CQ15: =(CK15-BG15)/BG15 -> -0.39826288
A16: =O16 -> Grant | B16: =K16 -> 1962 | C16: =L16 -> 180200 | D16: =M16 -> 423280 | E16: =LN(D16/C16) -> 0.85396655 | F16: =A16 -> Grant | G16: =Q16 -> 130357 | H16: =Y16 -> 335297.3 | I16: =LN(H16/G16) -> 0.94474076 | J16: =I16-(aa-bb*G16) -> -0.10405738 | K16: 1962 | L16: 180200 | M16: 423280 | O16: =CB16 -> Grant | P16: =CC16 -> 1962 | Q16: =CK16 -> 130357 | R16: =CD16 -> 249239 | S16: =1-Q16/R16 -> 0.47697993 | U16: =$R19*U$2 -> 51141.6 | V16: =$R20*V$2 -> 251855.4 | W16: =$R21*W$2 -> 32300.3 | X16: =$R22*X$2 -> 0 | Y16: =SUM(U16:X16) -> 335297.3 | AD16: =Y16 -> 335297.3 | AE16: =B16 -> 1962 | AF16: =U16/$Y16 -> 0.15252613 | AG16: =V16/$Y16 -> 0.75114055 | AH16: =W16/$Y16 -> 0.096333314 | AJ16: =B16 -> 1962 | AK16: =AF13*AN13+AG12*AN12+AH11*AN11 -> 241416.6 | AL16: =CHOOSE(umethod,S16,retroU,MAX(0,cslope*(AK16-nlim)/AK16)) -> 0.47697993 | AM16: =AK16*(1-AL16) -> 126265.73 | AN16: =AM16*EXP(aa-bb*AM16+J16) -> 325593.02 | AO16: =AK16-AM16 -> 115150.87 | AR16: 0.5 | AS16: 26591286 | AW16: Cass | AX16: 1962 | AY16: 36568 | AZ16: N/A | BA16: 8034 | BB16: 8741 | BC16: 33 | BD16: 58870 | BE16: 112245 | BF16: 0.38 | BG16: 180200 | BH16: 292445 | BI16: =BE16/BH16 -> 0.38381576 | BJ16: =AY16/BH16 -> 0.12504232 | BK16: =BA16/(BH16-AY16) -> 0.031397898 | BL16: =BD16/(BH16-AY16-BA16-BC16) -> 0.23756103 | BM16: =BE16/BH16 -> 0.38381576 | BN16: =BG16*BM16/(1-BM16) -> 112245 | BP16: =BJ16/(SUM($BJ16:$BL16)) -> 0.31736528 | BQ16: =BK16/(SUM($BJ16:$BL16)) -> 0.079689844 | BR16: =BL16/(SUM($BJ16:$BL16)) -> 0.60294488 | CB16: Grant | CC16: 1962 | CD16: 249239 | CE16: 42750 | CF16: 1338 | CG16: 7155 | CH16: 8741 | CI16: 33 | CJ16: 58866 | CK16: 130357 | CL16: =SUM(CE16:CK16) -> 249240 | CN16: 0.477 | CO16: =CC16 -> 1962 | CP16: =(CD16-BH16)/BH16 -> -0.1477406 | CQ16: =(CK16-BG16)/BG16 -> -0.27659822
A17: =O17 -> Grant | B17: =K17 -> 1963 | C17: =L17 -> 214200 | D17: =M17 -> 430785 | E17: =LN(D17/C17) -> 0.69869897 | F17: =A17 -> Grant | G17: =Q17 -> 192245 | H17: =Y17 -> 435055.2 | I17: =LN(H17/G17) -> 0.81670232 | J17: =I17-(aa-bb*G17) -> -0.19399422 | K17: 1963 | L17: 214200 | M17: 430785 | O17: =CB17 -> Grant | P17: =CC17 -> 1963 | Q17: =CK17 -> 192245 | R17: =CD17 -> 339884 | S17: =1-Q17/R17 -> 0.43438055 | U17: =$R20*U$2 -> 125927.7 | V17: =$R21*V$2 -> 193801.8 | W17: =$R22*W$2 -> 115325.7 | X17: =$R23*X$2 -> 0 | Y17: =SUM(U17:X17) -> 435055.2 | AD17: =Y17 -> 435055.2 | AE17: =B17 -> 1963 | AF17: =U17/$Y17 -> 0.28945224 | AG17: =V17/$Y17 -> 0.44546485 | AH17: =W17/$Y17 -> 0.26508291 | AJ17: =B17 -> 1963 | AK17: =AF14*AN14+AG13*AN13+AH12*AN12 -> 327640.49 | AL17: =CHOOSE(umethod,S17,retroU,MAX(0,cslope*(AK17-nlim)/AK17)) -> 0.43438055 | AM17: =AK17*(1-AL17) -> 185319.83 | AN17: =AM17*EXP(aa-bb*AM17+J17) -> 421175.23 | AO17: =AK17-AM17 -> 142320.66 | AR17: 0.55 | AS17: 26591286 | AW17: Cass | AX17: 1963 | AY17: 75293 | AZ17: N/A | BA17: 9163 | BB17: 9807 | BC17: 360 | BD17: 64548 | BE17: 159172 | BF17: 0.43 | BG17: 214200 | BH17: 373372 | BI17: =BE17/BH17 -> 0.42630942 | BJ17: =AY17/BH17 -> 0.20165679 | BK17: =BA17/(BH17-AY17) -> 0.030740173 | BL17: =BD17/(BH17-AY17-BA17-BC17) -> 0.22369315 | BM17: =BE17/BH17 -> 0.42630942 | BN17: =BG17*BM17/(1-BM17) -> 159172 | BP17: =BJ17/(SUM($BJ17:$BL17)) -> 0.44214243 | BQ17: =BK17/(SUM($BJ17:$BL17)) -> 0.067399341 | BR17: =BL17/(SUM($BJ17:$BL17)) -> 0.49045823 | CB17: Grant | CC17: 1963 | CD17: 339884 | CE17: 65476 | CF17: 0 | CG17: 7567 | CH17: 9807 | CI17: 360 | CJ17: 64428 | CK17: 192245 | CL17: =SUM(CE17:CK17) -> 339883 | CN17: 0.434 | CO17: =CC17 -> 1963 | CP17: =(CD17-BH17)/BH17 -> -0.089690711 | CQ17: =(CK17-BG17)/BG17 -> -0.10249767
A18: =O18 -> Grant | B18: =K18 -> 1964 | C18: =L18 -> 325400 | D18: =M18 -> 1165723 | E18: =LN(D18/C18) -> 1.2760416 | F18: =A18 -> Grant | G18: =Q18 -> 246741 | H18: =Y18 -> 846704.4 | I18: =LN(H18/G18) -> 1.2330124 | J18: =I18-(aa-bb*G18) -> 0.25586658 | K18: 1964 | L18: 325400 | M18: 1165723 | O18: =CB18 -> Grant | P18: =CC18 -> 1964 | Q18: =CK18 -> 246741 | R18: =CD18 -> 371556 | S18: =1-Q18/R18 -> 0.33592514 | U18: =$R21*U$2 -> 96900.9 | V18: =$R22*V$2 -> 691954.2 | W18: =$R23*W$2 -> 57849.3 | X18: =$R24*X$2 -> 0 | Y18: =SUM(U18:X18) -> 846704.4 | AD18: =Y18 -> 846704.4 | AE18: =B18 -> 1964 | AF18: =U18/$Y18 -> 0.11444478 | AG18: =V18/$Y18 -> 0.81723232 | AH18: =W18/$Y18 -> 0.0683229 | AJ18: =B18 -> 1964 | AK18: =AF15*AN15+AG14*AN14+AH13*AN13 -> 366907.12 | AL18: =CHOOSE(umethod,S18,retroU,MAX(0,cslope*(AK18-nlim)/AK18)) -> 0.33592514 | AM18: =AK18*(1-AL18) -> 243653.8 | AN18: =AM18*EXP(aa-bb*AM18+J18) -> 837701.17 | AO18: =AK18-AM18 -> 123253.32 | AR18: 0.6 | AS18: 26591286 | AW18: Cass | AX18: 1964 | AY18: 27470 | AZ18: N/A | BA18: 9025 | BB18: 11350 | BC18: 437 | BD18: 73031 | BE18: 121313 | BF18: 0.27 | BG18: 325400 | BH18: 446713 | BI18: =BE18/BH18 -> 0.2715681 | BJ18: =AY18/BH18 -> 0.061493621 | BK18: =BA18/(BH18-AY18) -> 0.021526895 | BL18: =BD18/(BH18-AY18-BA18-BC18) -> 0.17821959 | BM18: =BE18/BH18 -> 0.2715681 | BN18: =BG18*BM18/(1-BM18) -> 121313 | BP18: =BJ18/(SUM($BJ18:$BL18)) -> 0.2353912 | BQ18: =BK18/(SUM($BJ18:$BL18)) -> 0.08240272 | BR18: =BL18/(SUM($BJ18:$BL18)) -> 0.68220608 | CB18: Grant | CC18: 1964 | CD18: 371556 | CE18: 31979 | CF18: 0 | CG18: 8372 | CH18: 11350 | CI18: 437 | CJ18: 72677 | CK18: 246741 | CL18: =SUM(CE18:CK18) -> 371556 | CN18: 0.336 | CO18: =CC18 -> 1964 | CP18: =(CD18-BH18)/BH18 -> -0.16824449 | CQ18: =(CK18-BG18)/BG18 -> -0.24173018
A19: =O19 -> Grant | B19: =K19 -> 1965 | C19: =L19 -> 184800 | D19: =M19 -> 851349 | E19: =LN(D19/C19) -> 1.527548 | F19: =A19 -> Grant | G19: =Q19 -> 129459 | H19: =Y19 -> 767008.4 | I19: =LN(H19/G19) -> 1.7791335 | J19: =I19-(aa-bb*G19) -> 0.72978253 | K19: 1965 | L19: 184800 | M19: 851349 | O19: =CB19 -> Grant | P19: =CC19 -> 1965 | Q19: =CK19 -> 129459 | R19: =CD19 -> 170472 | S19: =1-Q19/R19 -> 0.24058496 | U19: =$R22*U$2 -> 345977.1 | V19: =$R23*V$2 -> 347095.8 | W19: =$R24*W$2 -> 73935.5 | X19: =$R25*X$2 -> 0 | Y19: =SUM(U19:X19) -> 767008.4 | AD19: =Y19 -> 767008.4 | AE19: =B19 -> 1965 | AF19: =U19/$Y19 -> 0.45107342 | AG19: =V19/$Y19 -> 0.45253194 | AH19: =W19/$Y19 -> 0.096394642 | AJ19: =B19 -> 1965 | AK19: =AF16*AN16+AG15*AN15+AH14*AN14 -> 168080.15 | AL19: =CHOOSE(umethod,S19,retroU,MAX(0,cslope*(AK19-nlim)/AK19)) -> 0.24058496 | AM19: =AK19*(1-AL19) -> 127642.59 | AN19: =AM19*EXP(aa-bb*AM19+J19) -> 757092.86 | AO19: =AK19-AM19 -> 40437.556 | AR19: 0.65 | AS19: 26591286 | AW19: Cass | AX19: 1965 | AY19: 4270 | AZ19: N/A | BA19: 8713 | BB19: 5595 | BC19: 203 | BD19: 19329 | BE19: 38110 | BF19: 0.17 | BG19: 184800 | BH19: 222910 | BI19: =BE19/BH19 -> 0.17096586 | BJ19: =AY19/BH19 -> 0.019155713 | BK19: =BA19/(BH19-AY19) -> 0.039850896 | BL19: =BD19/(BH19-AY19-BA19-BC19) -> 0.092163987 | BM19: =BE19/BH19 -> 0.17096586 | BN19: =BG19*BM19/(1-BM19) -> 38110 | BP19: =BJ19/(SUM($BJ19:$BL19)) -> 0.12671587 | BQ19: =BK19/(SUM($BJ19:$BL19)) -> 0.26361539 | BR19: =BL19/(SUM($BJ19:$BL19)) -> 0.60966874 | CB19: Grant | CC19: 1965 | CD19: 170472 | CE19: 8447 | CF19: 0 | CG19: 7566 | CH19: 5595 | CI19: 203 | CJ19: 19202 | CK19: 129459 | CL19: =SUM(CE19:CK19) -> 170472 | CN19: 0.241 | CO19: =CC19 -> 1965 | CP19: =(CD19-BH19)/BH19 -> -0.23524292 | CQ19: =(CK19-BG19)/BG19 -> -0.29946429
A20: =O20 -> Grant | B20: =K20 -> 1966 | C20: =L20 -> 429700 | D20: =M20 -> 719419 | E20: =LN(D20/C20) -> 0.51535665 | F20: =A20 -> Grant | G20: =Q20 -> 360810 | H20: =Y20 -> 654797.3 | I20: =LN(H20/G20) -> 0.59597422 | J20: =I20-(aa-bb*G20) -> -0.31094458 | K20: 1966 | L20: 429700 | M20: 719419 | O20: =CB20 -> Grant | P20: =CC20 -> 1966 | Q20: =CK20 -> 360810 | R20: =CD20 -> 419759 | S20: =1-Q20/R20 -> 0.14043535 | U20: =$R23*U$2 -> 173547.9 | V20: =$R24*V$2 -> 443613 | W20: =$R25*W$2 -> 37636.4 | X20: =$R26*X$2 -> 0 | Y20: =SUM(U20:X20) -> 654797.3 | AD20: =Y20 -> 654797.3 | AE20: =B20 -> 1966 | AF20: =U20/$Y20 -> 0.26504065 | AG20: =V20/$Y20 -> 0.67748141 | AH20: =W20/$Y20 -> 0.05747794 | AJ20: =B20 -> 1966 | AK20: =AF17*AN17+AG16*AN16+AH15*AN15 -> 408137.85 | AL20: =CHOOSE(umethod,S20,retroU,MAX(0,cslope*(AK20-nlim)/AK20)) -> 0.14043535 | AM20: =AK20*(1-AL20) -> 350820.87 | AN20: =AM20*EXP(aa-bb*AM20+J20) -> 640596.53 | AO20: =AK20-AM20 -> 57316.979 | AW20: Cass | AX20: 1966 | AY20: 8860 | AZ20: N/A | BA20: 8219 | BB20: 10083 | BC20: 216 | BD20: 26054 | BE20: 53432 | BF20: 0.11 | BG20: 429700 | BH20: 483132 | BI20: =BE20/BH20 -> 0.11059503 | BJ20: =AY20/BH20 -> 0.018338673 | BK20: =BA20/(BH20-AY20) -> 0.017329718 | BL20: =BD20/(BH20-AY20-BA20-BC20) -> 0.055929435 | BM20: =BE20/BH20 -> 0.11059503 | BN20: =BG20*BM20/(1-BM20) -> 53432 | BP20: =BJ20/(SUM($BJ20:$BL20)) -> 0.20020861 | BQ20: =BK20/(SUM($BJ20:$BL20)) -> 0.18919355 | BR20: =BL20/(SUM($BJ20:$BL20)) -> 0.61059784 | CB20: Grant | CC20: 1966 | CD20: 419759 | CE20: 15213 | CF20: 0 | CG20: 7402 | CH20: 10083 | CI20: 216 | CJ20: 26035 | CK20: 360810 | CL20: =SUM(CE20:CK20) -> 419759 | CN20: 0.14 | CO20: =CC20 -> 1966 | CP20: =(CD20-BH20)/BH20 -> -0.13117119 | CQ20: =(CK20-BG20)/BG20 -> -0.16032115
A21: =O21 -> Grant | B21: =K21 -> 1967 | C21: =L21 -> 213873 | D21: =M21 -> 526762 | E21: =LN(D21/C21) -> 0.90136645 | F21: =A21 -> Grant | G21: =Q21 -> 213873 | H21: =Y21 -> 582606.9 | I21: =LN(H21/G21) -> 1.0021303 | J21: =I21-(aa-bb*G21) -> 0.0047491372 | K21: 1967 | L21: 213873 | M21: 526762 | O21: =CB21 -> Grant | P21: =CC21 -> 1967 | Q21: =CK21 -> 213873 | R21: =CD21 -> 323003 | S21: =1-Q21/R21 -> 0.33786064 | U21: =$R24*U$2 -> 221806.5 | V21: =$R25*V$2 -> 225818.4 | W21: =$R26*W$2 -> 134982 | X21: =$R27*X$2 -> 0 | Y21: =SUM(U21:X21) -> 582606.9 | AD21: =Y21 -> 582606.9 | AE21: =B21 -> 1967 | AF21: =U21/$Y21 -> 0.38071382 | AG21: =V21/$Y21 -> 0.38759994 | AH21: =W21/$Y21 -> 0.23168624 | AJ21: =B21 -> 1967 | AK21: =AF18*AN18+AG17*AN17+AH16*AN16 -> 314854.74 | AL21: =CHOOSE(umethod,S21,retroU,MAX(0,cslope*(AK21-nlim)/AK21)) -> 0.33786064 | AM21: =AK21*(1-AL21) -> 208477.72 | AN21: =AM21*EXP(aa-bb*AM21+J21) -> 569799.25 | AO21: =AK21-AM21 -> 106377.02 | AW21: Cass | AX21: 1967 | AY21: 36432 | AZ21: N/A | BA21: 11948 | BB21: 9206 | BC21: 688 | BD21: 55457 | BE21: 113731 | BF21: 0.35 | BG21: 213873 | BH21: 327604 | BI21: =BE21/BH21 -> 0.34715999 | BJ21: =AY21/BH21 -> 0.11120743 | BK21: =BA21/(BH21-AY21) -> 0.041034165 | BL21: =BD21/(BH21-AY21-BA21-BC21) -> 0.19910173 | BM21: =BE21/BH21 -> 0.34715999 | BN21: =BG21*BM21/(1-BM21) -> 113731 | BP21: =BJ21/(SUM($BJ21:$BL21)) -> 0.31652069 | BQ21: =BK21/(SUM($BJ21:$BL21)) -> 0.11679221 | BR21: =BL21/(SUM($BJ21:$BL21)) -> 0.5666871 | CB21: Grant | CC21: 1967 | CD21: 323003 | CE21: 35962 | CF21: 0 | CG21: 7824 | CH21: 9206 | CI21: 688 | CJ21: 55450 | CK21: 213873 | CL21: =SUM(CE21:CK21) -> 323003 | CN21: 0.338 | CO21: =CC21 -> 1967 | CP21: =(CD21-BH21)/BH21 -> -0.014044395 | CQ21: =(CK21-BG21)/BG21 -> 0
A22: =O22 -> Grant | B22: =K22 -> 1968 | C22: =L22 -> 822200 | D22: =M22 -> 1219850 | E22: =LN(D22/C22) -> 0.3944995 | F22: =A22 -> Grant | G22: =Q22 -> 670328 | H22: =Y22 -> 1073497.2 | I22: =LN(H22/G22) -> 0.47090986 | J22: =I22-(aa-bb*G22) -> -0.2454529 | K22: 1968 | L22: 822200 | M22: 1219850 | O22: =CB22 -> Grant | P22: =CC22 -> 1968 | Q22: =CK22 -> 670328 | R22: =CD22 -> 1153257 | S22: =1-Q22/R22 -> 0.41875228 | U22: =$R25*U$2 -> 112909.2 | V22: =$R26*V$2 -> 809892 | W22: =$R27*W$2 -> 150696 | X22: =$R28*X$2 -> 0 | Y22: =SUM(U22:X22) -> 1073497.2 | AD22: =Y22 -> 1073497.2 | AE22: =B22 -> 1968 | AF22: =U22/$Y22 -> 0.10517885 | AG22: =V22/$Y22 -> 0.75444258 | AH22: =W22/$Y22 -> 0.14037857 | AJ22: =B22 -> 1968 | AK22: =AF19*AN19+AG18*AN18+AH17*AN17 -> 1137747.3 | AL22: =CHOOSE(umethod,S22,retroU,MAX(0,cslope*(AK22-nlim)/AK22)) -> 0.41875228 | AM22: =AK22*(1-AL22) -> 661313.01 | AN22: =AM22*EXP(aa-bb*AM22+J22) -> 1064954.4 | AO22: =AK22-AM22 -> 476434.27 | AW22: Cass | AX22: 1968 | AY22: 298253 | AZ22: N/A | BA22: 12960 | BB22: 77467 | BC22: 863 | BD22: 214264 | BE22: 603807 | BF22: 0.42 | BG22: 822200 | BH22: 1426007 | BI22: =BE22/BH22 -> 0.42342499 | BJ22: =AY22/BH22 -> 0.20915255 | BK22: =BA22/(BH22-AY22) -> 0.011491868 | BL22: =BD22/(BH22-AY22-BA22-BC22) -> 0.19234944 | BM22: =BE22/BH22 -> 0.42342499 | BN22: =BG22*BM22/(1-BM22) -> 603807 | BP22: =BJ22/(SUM($BJ22:$BL22)) -> 0.50643017 | BQ22: =BK22/(SUM($BJ22:$BL22)) -> 0.02782576 | BR22: =BL22/(SUM($BJ22:$BL22)) -> 0.46574406 | CB22: Grant | CC22: 1968 | CD22: 1153257 | CE22: 179004 | CF22: 0 | CG22: 11578 | CH22: 77467 | CI22: 863 | CJ22: 214017 | CK22: 670328 | CL22: =SUM(CE22:CK22) -> 1153257 | CN22: 0.419 | CO22: =CC22 -> 1968 | CP22: =(CD22-BH22)/BH22 -> -0.19126835 | CQ22: =(CK22-BG22)/BG22 -> -0.18471418
A23: =O23 -> Grant | B23: =K23 -> 1969 | C23: =L23 -> 390100 | D23: =M23 -> 1312868 | E23: =LN(D23/C23) -> 1.2135662 | F23: =A23 -> Grant | G23: =Q23 -> 309220 | H23: =Y23 -> 1380907.4 | I23: =LN(H23/G23) -> 1.4964431 | J23: =I23-(aa-bb*G23) -> 0.5577627 | K23: 1969 | L23: 390100 | M23: 1312868 | O23: =CB23 -> Grant | P23: =CC23 -> 1969 | Q23: =CK23 -> 309220 | R23: =CD23 -> 578493 | S23: =1-Q23/R23 -> 0.46547322 | U23: =$R26*U$2 -> 404946 | V23: =$R27*V$2 -> 904176 | W23: =$R28*W$2 -> 71785.4 | X23: =$R29*X$2 -> 0 | Y23: =SUM(U23:X23) -> 1380907.4 | AD23: =Y23 -> 1380907.4 | AE23: =B23 -> 1969 | AF23: =U23/$Y23 -> 0.29324631 | AG23: =V23/$Y23 -> 0.65476947 | AH23: =W23/$Y23 -> 0.051984224 | AJ23: =B23 -> 1969 | AK23: =AF20*AN20+AG19*AN19+AH18*AN18 -> 569626.99 | AL23: =CHOOSE(umethod,S23,retroU,MAX(0,cslope*(AK23-nlim)/AK23)) -> 0.46547322 | AM23: =AK23*(1-AL23) -> 304480.88 | AN23: =AM23*EXP(aa-bb*AM23+J23) -> 1363716.6 | AO23: =AK23-AM23 -> 265146.11 | AW23: Cass | AX23: 1969 | AY23: 183798 | AZ23: N/A | BA23: 6816 | BB23: 39026 | BC23: 735 | BD23: 93245 | BE23: 323620 | BF23: 0.45 | BG23: 390100 | BH23: 713720 | BI23: =BE23/BH23 -> 0.45342711 | BJ23: =AY23/BH23 -> 0.25752116 | BK23: =BA23/(BH23-AY23) -> 0.01286227 | BL23: =BD23/(BH23-AY23-BA23-BC23) -> 0.1785034 | BM23: =BE23/BH23 -> 0.45342711 | BN23: =BG23*BM23/(1-BM23) -> 323620 | BP23: =BJ23/(SUM($BJ23:$BL23)) -> 0.57368838 | BQ23: =BK23/(SUM($BJ23:$BL23)) -> 0.028653704 | BR23: =BL23/(SUM($BJ23:$BL23)) -> 0.39765792 | CB23: Grant | CC23: 1969 | CD23: 578493 | CE23: 129729 | CF23: 0 | CG23: 6331 | CH23: 39026 | CI23: 735 | CJ23: 93453 | CK23: 309220 | CL23: =SUM(CE23:CK23) -> 578494 | CN23: 0.465 | CO23: =CC23 -> 1969 | CP23: =(CD23-BH23)/BH23 -> -0.18946786 | CQ23: =(CK23-BG23)/BG23 -> -0.20733145
A24: =O24 -> Grant | B24: =K24 -> 1970 | C24: =L24 -> 287250 | D24: =M24 -> 832641 | E24: =LN(D24/C24) -> 1.0642497 | F24: =A24 -> Grant | G24: =Q24 -> 284250 | H24: =Y24 -> 931420.3 | I24: =LN(H24/G24) -> 1.1868565 | J24: =I24-(aa-bb*G24) -> 0.23280321 | K24: 1970 | L24: 287250 | M24: 832641 | O24: =CB24 -> Grant | P24: =CC24 -> 1970 | Q24: =CK24 -> 284250 | R24: =CD24 -> 739355 | S24: =1-Q24/R24 -> 0.61554328 | U24: =$R27*U$2 -> 452088 | V24: =$R28*V$2 -> 430712.4 | W24: =$R29*W$2 -> 48619.9 | X24: =$R30*X$2 -> 0 | Y24: =SUM(U24:X24) -> 931420.3 | AD24: =Y24 -> 931420.3 | AE24: =B24 -> 1970 | AF24: =U24/$Y24 -> 0.48537486 | AG24: =V24/$Y24 -> 0.46242539 | AH24: =W24/$Y24 -> 0.052199743 | AJ24: =B24 -> 1970 | AK24: =AF21*AN21+AG20*AN20+AH19*AN19 -> 723902.38 | AL24: =CHOOSE(umethod,S24,retroU,MAX(0,cslope*(AK24-nlim)/AK24)) -> 0.61554328 | AM24: =AK24*(1-AL24) -> 278309.14 | AN24: =AM24*EXP(aa-bb*AM24+J24) -> 915295.09 | AO24: =AK24-AM24 -> 445593.25 | AW24: Cass | AX24: 1970 | AY24: 209072 | AZ24: N/A | BA24: 11867 | BB24: 61134 | BC24: 332 | BD24: 184381 | BE24: 468787 | BF24: 0.62 | BG24: 287250 | BH24: 754037 | BI24: =BE24/BH24 -> 0.62170291 | BJ24: =AY24/BH24 -> 0.27727021 | BK24: =BA24/(BH24-AY24) -> 0.02177571 | BL24: =BD24/(BH24-AY24-BA24-BC24) -> 0.34608252 | BM24: =BE24/BH24 -> 0.62170291 | BN24: =BG24*BM24/(1-BM24) -> 472073.85 | BP24: =BJ24/(SUM($BJ24:$BL24)) -> 0.42979071 | BQ24: =BK24/(SUM($BJ24:$BL24)) -> 0.03375407 | BR24: =BL24/(SUM($BJ24:$BL24)) -> 0.53645522 | CB24: Grant | CC24: 1970 | CD24: 739355 | CE24: 197753 | CF24: 675 | CG24: 10345 | CH24: 61134 | CI24: 0 | CJ24: 185198 | CK24: 284250 | CL24: =SUM(CE24:CK24) -> 739355 | CN24: 0.616 | CO24: =CC24 -> 1970 | CP24: =(CD24-BH24)/BH24 -> -0.019471193 | CQ24: =(CK24-BG24)/BG24 -> -0.010443864
A25: =O25 -> Grant | B25: =K25 -> 1971 | C25: =L25 -> 290150 | D25: =M25 -> 589068 | E25: =LN(D25/C25) -> 0.7081436 | F25: =A25 -> Grant | G25: =Q25 -> 290125 | H25: =Y25 -> 607447.8 | I25: =LN(H25/G25) -> 0.73895438 | J25: =I25-(aa-bb*G25) -> -0.21148193 | K25: 1971 | L25: 290150 | M25: 589068 | O25: =CB25 -> Grant | P25: =CC25 -> 1971 | Q25: =CK25 -> 290125 | R25: =CD25 -> 376364 | S25: =1-Q25/R25 -> 0.22913722 | U25: =$R28*U$2 -> 215356.2 | V25: =$R29*V$2 -> 291719.4 | W25: =$R30*W$2 -> 100372.2 | X25: =$R31*X$2 -> 0 | Y25: =SUM(U25:X25) -> 607447.8 | AD25: =Y25 -> 607447.8 | AE25: =B25 -> 1971 | AF25: =U25/$Y25 -> 0.35452627 | AG25: =V25/$Y25 -> 0.48023781 | AH25: =W25/$Y25 -> 0.16523593 | AJ25: =B25 -> 1971 | AK25: =AF22*AN22+AG21*AN21+AH20*AN20 -> 369685 | AL25: =CHOOSE(umethod,S25,retroU,MAX(0,cslope*(AK25-nlim)/AK25)) -> 0.22913722 | AM25: =AK25*(1-AL25) -> 284976.41 | AN25: =AM25*EXP(aa-bb*AM25+J25) -> 598562.25 | AO25: =AK25-AM25 -> 84708.593 | AW25: Cass | AX25: 1971 | AY25: 40206 | AZ25: N/A | BA25: 9162 | BB25: 19848 | BC25: 193 | BD25: 25716 | BE25: 95125 | BF25: 0.25 | BG25: 290150 | BH25: 385275 | BI25: =BE25/BH25 -> 0.24690156 | BJ25: =AY25/BH25 -> 0.10435663 | BK25: =BA25/(BH25-AY25) -> 0.026551211 | BL25: =BD25/(BH25-AY25-BA25-BC25) -> 0.076600916 | BM25: =BE25/BH25 -> 0.24690156 | BN25: =BG25*BM25/(1-BM25) -> 95125 | BP25: =BJ25/(SUM($BJ25:$BL25)) -> 0.50290229 | BQ25: =BK25/(SUM($BJ25:$BL25)) -> 0.12795225 | BR25: =BL25/(SUM($BJ25:$BL25)) -> 0.36914546 | CB25: Grant | CC25: 1971 | CD25: 376364 | CE25: 33093 | CF25: 0 | CG25: 7502 | CH25: 19850 | CI25: 0 | CJ25: 25794 | CK25: 290125 | CL25: =SUM(CE25:CK25) -> 376364 | CN25: 0.229 | CO25: =CC25 -> 1971 | CP25: =(CD25-BH25)/BH25 -> -0.023128934 | CQ25: =(CK25-BG25)/BG25 -> -8.616233e-05
A26: =O26 -> Grant | B26: =K26 -> 1972 | C26: =L26 -> 423290 | D26: =M26 -> 965520 | E26: =LN(D26/C26) -> 0.82460929 | F26: =A26 -> Grant | G26: =Q26 -> 423290 | H26: =Y26 -> 820346.5 | I26: =LN(H26/G26) -> 0.66166929 | J26: =I26-(aa-bb*G26) -> -0.20678344 | K26: 1972 | L26: 423290 | M26: 965520 | O26: =CB26 -> Grant | P26: =CC26 -> 1972 | Q26: =CK26 -> 423290 | R26: =CD26 -> 1349820 | S26: =1-Q26/R26 -> 0.68641004 | U26: =$R29*U$2 -> 145859.7 | V26: =$R30*V$2 -> 602233.2 | W26: =$R31*W$2 -> 72253.6 | X26: =$R32*X$2 -> 0 | Y26: =SUM(U26:X26) -> 820346.5 | AD26: =Y26 -> 820346.5 | AE26: =B26 -> 1972 | AF26: =U26/$Y26 -> 0.17780255 | AG26: =V26/$Y26 -> 0.73412052 | AH26: =W26/$Y26 -> 0.088076928 | AJ26: =B26 -> 1972 | AK26: =AF23*AN23+AG22*AN22+AH21*AN21 -> 1335366.4 | AL26: =CHOOSE(umethod,S26,retroU,MAX(0,cslope*(AK26-nlim)/AK26)) -> 0.68641004 | AM26: =AK26*(1-AL26) -> 418757.51 | AN26: =AM26*EXP(aa-bb*AM26+J26) -> 813830.21 | AO26: =AK26-AM26 -> 916608.94 | AW26: Cass | AX26: 1972 | AY26: 444705 | AZ26: N/A | BA26: 40334 | BB26: 252043 | BC26: 600 | BD26: 262836 | BE26: 1000517 | BF26: 0.7 | BG26: 423290 | BH26: 1423807 | BI26: =BE26/BH26 -> 0.70270549 | BJ26: =AY26/BH26 -> 0.31233517 | BK26: =BA26/(BH26-AY26) -> 0.041194891 | BL26: =BD26/(BH26-AY26-BA26-BC26) -> 0.28015878 | BM26: =BE26/BH26 -> 0.70270549 | BN26: =BG26*BM26/(1-BM26) -> 1000517 | BP26: =BJ26/(SUM($BJ26:$BL26)) -> 0.49288413 | BQ26: =BK26/(SUM($BJ26:$BL26)) -> 0.065008074 | BR26: =BL26/(SUM($BJ26:$BL26)) -> 0.4421078 | CB26: Grant | CC26: 1972 | CD26: 1349820 | CE26: 358496 | CF26: 15952 | CG26: 37276 | CH26: 252043 | CI26: 0 | CJ26: 262763 | CK26: 423290 | CL26: =SUM(CE26:CK26) -> 1349820 | CN26: 0.686 | CO26: =CC26 -> 1972 | CP26: =(CD26-BH26)/BH26 -> -0.051964206 | CQ26: =(CK26-BG26)/BG26 -> 0
A27: =O27 -> Grant | B27: =K27 -> 1973 | C27: =L27 -> 267105 | D27: =M27 -> 826929 | E27: =LN(D27/C27) -> 1.130077 | F27: =A27 -> Grant | G27: =Q27 -> 267080 | H27: =Y27 -> 853160.5 | I27: =LN(H27/G27) -> 1.1613995 | J27: =I27-(aa-bb*G27) -> 0.19677539 | K27: 1973 | L27: 267105 | M27: 826929 | O27: =CB27 -> Grant | P27: =CC27 -> 1973 | Q27: =CK27 -> 267080 | R27: =CD27 -> 1506960 | S27: =1-Q27/R27 -> 0.82276902 | U27: =$R30*U$2 -> 301116.6 | V27: =$R31*V$2 -> 433521.6 | W27: =$R32*W$2 -> 118522.3 | X27: =$R33*X$2 -> 0 | Y27: =SUM(U27:X27) -> 853160.5 | AD27: =Y27 -> 853160.5 | AE27: =B27 -> 1973 | AF27: =U27/$Y27 -> 0.3529425 | AG27: =V27/$Y27 -> 0.50813604 | AH27: =W27/$Y27 -> 0.13892146 | AJ27: =B27 -> 1973 | AK27: =AF24*AN24+AG23*AN23+AH22*AN22 -> 1486678 | AL27: =CHOOSE(umethod,S27,retroU,MAX(0,cslope*(AK27-nlim)/AK27)) -> 0.82276902 | AM27: =AK27*(1-AL27) -> 263485.4 | AN27: =AM27*EXP(aa-bb*AM27+J27) -> 843542.63 | AO27: =AK27-AM27 -> 1223192.6 | AW27: Cass | AX27: 1973 | AY27: 590246 | AZ27: N/A | BA27: 80727 | BB27: 200744 | BC27: 643 | BD27: 201278 | BE27: 1073638 | BF27: 0.8 | BG27: 267105 | BH27: 1340743 | BI27: =BE27/BH27 -> 0.80077837 | BJ27: =AY27/BH27 -> 0.44023799 | BK27: =BA27/(BH27-AY27) -> 0.10756472 | BL27: =BD27/(BH27-AY27-BA27-BC27) -> 0.30080687 | BM27: =BE27/BH27 -> 0.80077837 | BN27: =BG27*BM27/(1-BM27) -> 1073638 | BP27: =BJ27/(SUM($BJ27:$BL27)) -> 0.51877565 | BQ27: =BK27/(SUM($BJ27:$BL27)) -> 0.12675407 | BR27: =BL27/(SUM($BJ27:$BL27)) -> 0.35447028 | CB27: Grant | CC27: 1973 | CD27: 1506960 | CE27: 742948 | CF27: 17553 | CG27: 77828 | CH27: 200744 | CI27: 0 | CJ27: 200807 | CK27: 267080 | CL27: =SUM(CE27:CK27) -> 1506960 | CN27: 0.823 | CO27: =CC27 -> 1973 | CP27: =(CD27-BH27)/BH27 -> 0.1239738 | CQ27: =(CK27-BG27)/BG27 -> -9.3596151e-05
A28: =O28 -> Grant | B28: =K28 -> 1974 | C28: =L28 -> 350390 | D28: =M28 -> 1107885 | E28: =LN(D28/C28) -> 1.1511613 | F28: =A28 -> Grant | G28: =Q28 -> 350315 | H28: =Y28 -> 958767.8 | I28: =LN(H28/G28) -> 1.0068162 | J28: =I28-(aa-bb*G28) -> 0.093436078 | K28: 1974 | L28: 350390 | M28: 1107885 | O28: =CB28 -> Grant | P28: =CC28 -> 1974 | Q28: =CK28 -> 350315 | R28: =CD28 -> 717854 | S28: =1-Q28/R28 -> 0.51199687 | U28: =$R31*U$2 -> 216760.8 | V28: =$R32*V$2 -> 711133.8 | W28: =$R33*W$2 -> 30873.2 | X28: =$R34*X$2 -> 0 | Y28: =SUM(U28:X28) -> 958767.8 | AD28: =Y28 -> 958767.8 | AE28: =B28 -> 1974 | AF28: =U28/$Y28 -> 0.22608269 | AG28: =V28/$Y28 -> 0.7417164 | AH28: =W28/$Y28 -> 0.032200915 | AJ28: =B28 -> 1974 | AK28: =AF25*AN25+AG24*AN24+AH23*AN23 -> 706353.48 | AL28: =CHOOSE(umethod,S28,retroU,MAX(0,cslope*(AK28-nlim)/AK28)) -> 0.51199687 | AM28: =AK28*(1-AL28) -> 344702.71 | AN28: =AM28*EXP(aa-bb*AM28+J28) -> 946673 | AO28: =AK28-AM28 -> 361650.77 | AW28: Cass | AX28: 1974 | AY28: 101667 | AZ28: N/A | BA28: 28013 | BB28: 145411 | BC28: 1279 | BD28: 108257 | BE28: 384627 | BF28: 0.52 | BG28: 350390 | BH28: 735017 | BI28: =BE28/BH28 -> 0.52328994 | BJ28: =AY28/BH28 -> 0.13831925 | BK28: =BA28/(BH28-AY28) -> 0.044229889 | BL28: =BD28/(BH28-AY28-BA28-BC28) -> 0.17921623 | BM28: =BE28/BH28 -> 0.52328994 | BN28: =BG28*BM28/(1-BM28) -> 384627 | BP28: =BJ28/(SUM($BJ28:$BL28)) -> 0.38234519 | BQ28: =BK28/(SUM($BJ28:$BL28)) -> 0.12226126 | BR28: =BL28/(SUM($BJ28:$BL28)) -> 0.49539356 | CB28: Grant | CC28: 1974 | CD28: 717854 | CE28: 87421 | CF28: 1151 | CG28: 25560 | CH28: 145411 | CI28: 0 | CJ28: 107996 | CK28: 350315 | CL28: =SUM(CE28:CK28) -> 717854 | CN28: 0.512 | CO28: =CC28 -> 1974 | CP28: =(CD28-BH28)/BH28 -> -0.02335048 | CQ28: =(CK28-BG28)/BG28 -> -0.0002140472
A29: =O29 -> Grant | B29: =K29 -> 1975 | C29: =L29 -> 191445 | D29: =M29 -> 527760 | E29: =LN(D29/C29) -> 1.0140411 | F29: =A29 -> Grant | G29: =Q29 -> 191420 | H29: =Y29 -> 631741.4 | I29: =LN(H29/G29) -> 1.1940102 | J29: =I29-(aa-bb*G29) -> 0.18280571 | K29: 1975 | L29: 191445 | M29: 527760 | O29: =CB29 -> Grant | P29: =CC29 -> 1975 | Q29: =CK29 -> 191420 | R29: =CD29 -> 486199 | S29: =1-Q29/R29 -> 0.6062929 | U29: =$R32*U$2 -> 355566.9 | V29: =$R33*V$2 -> 185239.2 | W29: =$R34*W$2 -> 90935.3 | X29: =$R35*X$2 -> 0 | Y29: =SUM(U29:X29) -> 631741.4 | AD29: =Y29 -> 631741.4 | AE29: =B29 -> 1975 | AF29: =U29/$Y29 -> 0.56283615 | AG29: =V29/$Y29 -> 0.29321998 | AH29: =W29/$Y29 -> 0.14394387 | AJ29: =B29 -> 1975 | AK29: =AF26*AN26+AG25*AN25+AH24*AN24 -> 479931.48 | AL29: =CHOOSE(umethod,S29,retroU,MAX(0,cslope*(AK29-nlim)/AK29)) -> 0.6062929 | AM29: =AK29*(1-AL29) -> 188952.43 | AN29: =AM29*EXP(aa-bb*AM29+J29) -> 624545.78 | AO29: =AK29-AM29 -> 290979.05 | AW29: Cass | AX29: 1975 | AY29: 144527 | AZ29: N/A | BA29: 17876 | BB29: 69307 | BC29: 262 | BD29: 80560 | BE29: 312533 | BF29: 0.62 | BG29: 191445 | BH29: 503978 | BI29: =BE29/BH29 -> 0.62013223 | BJ29: =AY29/BH29 -> 0.28677244 | BK29: =BA29/(BH29-AY29) -> 0.049731396 | BL29: =BD29/(BH29-AY29-BA29-BC29) -> 0.23602969 | BM29: =BE29/BH29 -> 0.62013223 | BN29: =BG29*BM29/(1-BM29) -> 312533 | BP29: =BJ29/(SUM($BJ29:$BL29)) -> 0.50088323 | BQ29: =BK29/(SUM($BJ29:$BL29)) -> 0.086861981 | BR29: =BL29/(SUM($BJ29:$BL29)) -> 0.41225479 | CB29: Grant | CC29: 1975 | CD29: 486199 | CE29: 124247 | CF29: 3950 | CG29: 16433 | CH29: 69307 | CI29: 0 | CJ29: 80842 | CK29: 191420 | CL29: =SUM(CE29:CK29) -> 486199 | CN29: 0.606 | CO29: =CC29 -> 1975 | CP29: =(CD29-BH29)/BH29 -> -0.035277334 | CQ29: =(CK29-BG29)/BG29 -> -0.00013058581
A30: =O30 -> Grant | B30: =K30 -> 1976 | C30: =L30 -> 340467 | D30: =M30 -> 761292 | E30: =LN(D30/C30) -> 0.80469879 | F30: =A30 -> Grant | G30: =Q30 -> 340517 | H30: =Y30 -> 688258.5 | I30: =LN(H30/G30) -> 0.70369944 | J30: =I30-(aa-bb*G30) -> -0.21571283 | K30: 1976 | L30: 340467 | M30: 761292 | O30: =CB30 -> Grant | P30: =CC30 -> 1976 | Q30: =CK30 -> 340517 | R30: =CD30 -> 1003722 | S30: =1-Q30/R30 -> 0.6607457 | U30: =$R33*U$2 -> 92619.6 | V30: =$R34*V$2 -> 545611.8 | W30: =$R35*W$2 -> 50027.1 | X30: =$R36*X$2 -> 0 | Y30: =SUM(U30:X30) -> 688258.5 | AD30: =Y30 -> 688258.5 | AE30: =B30 -> 1976 | AF30: =U30/$Y30 -> 0.13457095 | AG30: =V30/$Y30 -> 0.79274255 | AH30: =W30/$Y30 -> 0.072686498 | AJ30: =B30 -> 1976 | AK30: =AF27*AN27+AG26*AN26+AH25*AN25 -> 994075.49 | AL30: =CHOOSE(umethod,S30,retroU,MAX(0,cslope*(AK30-nlim)/AK30)) -> 0.6607457 | AM30: =AK30*(1-AL30) -> 337244.38 | AN30: =AM30*EXP(aa-bb*AM30+J30) -> 683018.59 | AO30: =AK30-AM30 -> 656831.11 | AS30: Approx. | AT30: Approx. | AU30: Approx. | AW30: Cass | AX30: 1976 | AY30: 343629 | AZ30: N/A | BA30: 49645 | BB30: 191507 | BC30: 1126 | BD30: 187661 | BE30: 773568 | BF30: 0.69 | BG30: 340467 | BH30: 1114035 | BI30: =BE30/BH30 -> 0.69438393 | BJ30: =AY30/BH30 -> 0.3084544 | BK30: =BA30/(BH30-AY30) -> 0.064440048 | BL30: =BD30/(BH30-AY30-BA30-BC30) -> 0.26077247 | BM30: =BE30/BH30 -> 0.69438393 | BN30: =BG30*BM30/(1-BM30) -> 773568 | BP30: =BJ30/(SUM($BJ30:$BL30)) -> 0.48677687 | BQ30: =BK30/(SUM($BJ30:$BL30)) -> 0.10169388 | BR30: =BL30/(SUM($BJ30:$BL30)) -> 0.41152925 | CB30: Grant | CC30: 1976 | CD30: 1003722 | CE30: 237524 | CF30: 4559 | CG30: 43244 | CH30: 191507 | CI30: 0 | CJ30: 186371 | CK30: 340517 | CL30: =SUM(CE30:CK30) -> 1003722 | CN30: 0.661 | CO30: =CC30 -> 1976 | CP30: =(CD30-BH30)/BH30 -> -0.099021126 | CQ30: =(CK30-BG30)/BG30 -> 0.00014685711
A31: =O31 -> Grant | B31: =K31 -> 1977 | C31: =L31 -> 599371 | D31: =M31 -> 583647 | E31: =LN(D31/C31) -> -0.026584424 | F31: =A31 -> Grant | G31: =Q31 -> 599341 | H31: =Y31 -> 645369.6 | I31: =LN(H31/G31) -> 0.073992458 | J31: =I31-(aa-bb*G31) -> -0.68607375 | K31: 1977 | L31: 599371 | M31: 583647 | O31: =CB31 -> Grant | P31: =CC31 -> 1977 | Q31: =CK31 -> 599341 | R31: =CD31 -> 722536 | S31: =1-Q31/R31 -> 0.17050362 | U31: =$R34*U$2 -> 272805.9 | V31: =$R35*V$2 -> 300162.6 | W31: =$R36*W$2 -> 72401.1 | X31: =$R37*X$2 -> 0 | Y31: =SUM(U31:X31) -> 645369.6 | AD31: =Y31 -> 645369.6 | AE31: =B31 -> 1977 | AF31: =U31/$Y31 -> 0.42271266 | AG31: =V31/$Y31 -> 0.46510186 | AH31: =W31/$Y31 -> 0.11218548 | AJ31: =B31 -> 1977 | AK31: =AF28*AN28+AG27*AN27+AH26*AN26 -> 714340.45 | AL31: =CHOOSE(umethod,S31,retroU,MAX(0,cslope*(AK31-nlim)/AK31)) -> 0.17050362 | AM31: =AK31*(1-AL31) -> 592542.82 | AN31: =AM31*EXP(aa-bb*AM31+J31) -> 640725.37 | AO31: =AK31-AM31 -> 121797.63 | AP31: Source | AR31: Fraser R | AS31: Fraser R | AT31: Total HR | AU31: total return | AV31: %dif with Grant | AW31: Cass | AX31: 1977 | AY31: 42066 | AZ31: N/A | BA31: 8228 | BB31: 38846 | BC31: 626 | BD31: 23728 | BE31: 113494 | BF31: 0.16 | BG31: 599371 | BH31: 712865 | BI31: =BE31/BH31 -> 0.15920827 | BJ31: =AY31/BH31 -> 0.05900977 | BK31: =BA31/(BH31-AY31) -> 0.012265969 | BL31: =BD31/(BH31-AY31-BA31-BC31) -> 0.035845878 | BM31: =BE31/BH31 -> 0.15920827 | BN31: =BG31*BM31/(1-BM31) -> 113494 | BP31: =BJ31/(SUM($BJ31:$BL31)) -> 0.55086706 | BQ31: =BK31/(SUM($BJ31:$BL31)) -> 0.11450508 | BR31: =BL31/(SUM($BJ31:$BL31)) -> 0.33462787 | CB31: Grant | CC31: 1977 | CD31: 722536 | CE31: 54997 | CF31: 0 | CG31: 6358 | CH31: 36660 | CI31: 0 | CJ31: 25180 | CK31: 599341 | CL31: =SUM(CE31:CK31) -> 722536 | CN31: 0.171 | CO31: =CC31 -> 1977 | CP31: =(CD31-BH31)/BH31 -> 0.013566384 | CQ31: =(CK31-BG31)/BG31 -> -5.0052472e-05
A32: =O32 -> Grant | B32: =K32 -> 1978 | C32: =L32 -> 359065 | D32: =M32 -> 635560 | E32: =LN(D32/C32) -> 0.57100307 | F32: =A32 -> Grant | G32: =Q32 -> 358990 | H32: =Y32 -> 631498 | I32: =LN(H32/G32) -> 0.56480024 | J32: =I32-(aa-bb*G32) -> -0.34323905 | K32: 1978 | L32: 359065 | M32: 635560 | O32: =CB32 -> Grant | P32: =CC32 -> 1978 | Q32: =CK32 -> 358990 | R32: =CD32 -> 1185223 | S32: =1-Q32/R32 -> 0.69711185 | U32: =$R35*U$2 -> 150081.3 | V32: =$R36*V$2 -> 434406.6 | W32: =$R37*W$2 -> 47010.1 | X32: =$R38*X$2 -> 0 | Y32: =SUM(U32:X32) -> 631498 | AD32: =Y32 -> 631498 | AE32: =B32 -> 1978 | AF32: =U32/$Y32 -> 0.23765918 | AG32: =V32/$Y32 -> 0.68789862 | AH32: =W32/$Y32 -> 0.074442199 | AJ32: =B32 -> 1978 | AK32: =AF29*AN29+AG28*AN28+AH27*AN27 -> 1170866 | AL32: =CHOOSE(umethod,S32,retroU,MAX(0,cslope*(AK32-nlim)/AK32)) -> 0.69711185 | AM32: =AK32*(1-AL32) -> 354641.44 | AN32: =AM32*EXP(aa-bb*AM32+J32) -> 625520.87 | AO32: =AK32-AM32 -> 816224.57 | AQ32: broodyear | AR32: spawners | AS32: total catch | AT32: HR | AW32: Cass | AX32: 1978 | AY32: 485439 | AZ32: N/A | BA32: 12318 | BB32: 295733 | BC32: 277 | BD32: 134260 | BE32: 928027 | BF32: 0.72 | BG32: 359065 | BH32: 1287092 | BI32: =BE32/BH32 -> 0.72102616 | BJ32: =AY32/BH32 -> 0.37715952 | BK32: =BA32/(BH32-AY32) -> 0.015365751 | BL32: =BD32/(BH32-AY32-BA32-BC32) -> 0.17015226 | BM32: =BE32/BH32 -> 0.72102616 | BN32: =BG32*BM32/(1-BM32) -> 928027 | BP32: =BJ32/(SUM($BJ32:$BL32)) -> 0.67029426 | BQ32: =BK32/(SUM($BJ32:$BL32)) -> 0.027308271 | BR32: =BL32/(SUM($BJ32:$BL32)) -> 0.30239746 | CB32: Grant | CC32: 1978 | CD32: 1185223 | CE32: 405890 | CF32: 729 | CG32: 11113 | CH32: 273516 | CI32: 0 | CJ32: 134985 | CK32: 358990 | CL32: =SUM(CE32:CK32) -> 1185223 | CN32: 0.697 | CO32: =CC32 -> 1978 | CP32: =(CD32-BH32)/BH32 -> -0.079146634 | CQ32: =(CK32-BG32)/BG32 -> -0.00020887583 | CT32: broodyear | CU32: spawners | CV32: recruits | CW32: %dif Spa | CX32: %dif Rec
A33: =O33 -> Grant | B33: =K33 -> 1979 | C33: =L33 -> 255634 | D33: =M33 -> 510199 | E33: =LN(D33/C33) -> 0.69105411 | F33: =A33 -> Grant | G33: =Q33 -> 255634 | H33: =Y33 -> 560544.2 | I33: =LN(H33/G33) -> 0.78516136 | J33: =I33-(aa-bb*G33) -> -0.18650947 | K33: 1979 | L33: 255634 | M33: 510199 | O33: =CB33 -> Grant | P33: =CC33 -> 1979 | Q33: =CK33 -> 255634 | R33: =CD33 -> 308732 | S33: =1-Q33/R33 -> 0.17198735 | U33: =$R36*U$2 -> 217203.3 | V33: =$R37*V$2 -> 282060.6 | W33: =$R38*W$2 -> 61280.3 | X33: =$R39*X$2 -> 0 | Y33: =SUM(U33:X33) -> 560544.2 | AD33: =Y33 -> 560544.2 | AE33: =B33 -> 1979 | AF33: =U33/$Y33 -> 0.38748648 | AG33: =V33/$Y33 -> 0.50319065 | AH33: =W33/$Y33 -> 0.10932287 | AJ33: =B33 -> 1979 | AK33: =AF30*AN30+AG29*AN29+AH28*AN28 -> 305527.5 | AL33: =CHOOSE(umethod,S33,retroU,MAX(0,cslope*(AK33-nlim)/AK33)) -> 0.17198735 | AM33: =AK33*(1-AL33) -> 252980.63 | AN33: =AM33*EXP(aa-bb*AM33+J33) -> 555632.92 | AO33: =AK33-AM33 -> 52546.866 | AP33: Cass | AQ33: 1979 | AR33: 255634 | AS33: =BE33 -> 42262 | AT33: =AS33/(AR33+AS33) -> 0.1418683 | AU33: =AR33+AS33 -> 297896 | AV33: =(AU33-CD33)/CD33 -> -0.035098402 | AW33: Cass | AX33: 1979 | AY33: 20326 | AZ33: N/A | BA33: 2105 | BB33: 3455 | BC33: 403 | BD33: 15973 | BE33: 42262 | BF33: 0.14 | BG33: 255634 | BH33: 297896 | BI33: =BE33/BH33 -> 0.1418683 | BJ33: =AY33/BH33 -> 0.068231866 | BK33: =BA33/(BH33-AY33) -> 0.0075836726 | BL33: =BD33/(BH33-AY33-BA33-BC33) -> 0.058070544 | BM33: =BE33/BH33 -> 0.1418683 | BN33: =BG33*BM33/(1-BM33) -> 42262 | BO33: Harvest Rate | BP33: =BJ33/(SUM($BJ33:$BL33)) -> 0.50962628 | BQ33: =BK33/(SUM($BJ33:$BL33)) -> 0.056642725 | BR33: =BL33/(SUM($BJ33:$BL33)) -> 0.433731 | BT33: Year | BU33: Spawners | BV33: Harvest | BW33: Harvest Rate d2 | BX33: Returns | BZ33: Harvest Rate d1 | CB33: Grant | CC33: 1979 | CD33: 308732 | CE33: 31093 | CF33: 0 | CG33: 1381 | CH33: 3321 | CI33: 0 | CJ33: 17304 | CK33: 255634 | CL33: =SUM(CE33:CK33) -> 308733 | CN33: 0.172 | CO33: =CC33 -> 1979 | CP33: =(CD33-BH33)/BH33 -> 0.036375111 | CQ33: =(CK33-BG33)/BG33 -> 0 | CT33: 1979 | CU33: 255634 | CV33: 510199 | CW33: =(CU33-Q33)/Q33 -> 0 | CX33: =(CV33-AD33)/AD33 -> -0.089814862
A34: =O34 -> Grant | B34: =K34 -> 1980 | C34: =L34 -> 312182 | D34: =M34 -> 655505 | E34: =LN(D34/C34) -> 0.74181958 | F34: =A34 -> Grant | G34: =Q34 -> 314011 | H34: =Y34 -> 692616.5 | I34: =LN(H34/G34) -> 0.79104844 | J34: =I34-(aa-bb*G34) -> -0.14468236 | K34: 1980 | L34: 312182 | M34: 655505 | O34: =CB34 -> Grant | P34: =CC34 -> 1980 | Q34: =CK34 -> 314011 | R34: =CD34 -> 909353 | S34: =1-Q34/R34 -> 0.65468745 | U34: =$R37*U$2 -> 141030.3 | V34: =$R38*V$2 -> 367681.8 | W34: =$R39*W$2 -> 183904.4 | X34: =$R40*X$2 -> 0 | Y34: =SUM(U34:X34) -> 692616.5 | AD34: =Y34 -> 692616.5 | AE34: =B34 -> 1980 | AF34: =U34/$Y34 -> 0.20361961 | AG34: =V34/$Y34 -> 0.53085914 | AH34: =W34/$Y34 -> 0.26552125 | AJ34: =B34 -> 1980 | AK34: =AF31*AN31+AG30*AN30+AH29*AN29 -> 902200.16 | AL34: =CHOOSE(umethod,S34,retroU,MAX(0,cslope*(AK34-nlim)/AK34)) -> 0.65468745 | AM34: =AK34*(1-AL34) -> 311541.04 | AN34: =AM34*EXP(aa-bb*AM34+J34) -> 688214.21 | AO34: =AK34-AM34 -> 590659.13 | AP34: Cass | AQ34: 1980 | AR34: 312182 | AS34: =BE34 -> 594711 | AT34: =AS34/(AR34+AS34) -> 0.65576755 | AU34: =AR34+AS34 -> 906893 | AV34: =(AU34-CD34)/CD34 -> -0.0027052201 | AW34: Cass | AX34: 1980 | AY34: 243146 | AZ34: N/A | BA34: 13550 | BB34: 245019 | BC34: 3666 | BD34: 89330 | BE34: 594711 | BF34: =BE34/BH34 -> 0.65576755 | BG34: 312182 | BH34: 906893 | BI34: =BE34/BH34 -> 0.65576755 | BJ34: =AY34/BH34 -> 0.26810881 | BK34: =BA34/(BH34-AY34) -> 0.020414405 | BL34: =BD34/(BH34-AY34-BA34-BC34) -> 0.13816816 | BM34: =BE34/BH34 -> 0.65576755 | BN34: =BG34*BM34/(1-BM34) -> 594711 | BO34: 0.51937603 | BP34: =BJ34/(SUM($BJ34:$BL34)) -> 0.62834363 | BQ34: =BK34/(SUM($BJ34:$BL34)) -> 0.047843491 | BR34: =BL34/(SUM($BJ34:$BL34)) -> 0.32381288 | BT34: 1980 | BU34: 1373377 | BV34: 1162099.8 | BW34: 0.45833581 | BX34: 2535476.8 | BZ34: =BF34 -> 0.65576755 | CB34: Grant | CC34: 1980 | CD34: 909353 | CE34: 242556 | CF34: 8546 | CG34: 12026 | CH34: 241835 | CI34: 0 | CJ34: 90380 | CK34: 314011 | CL34: =SUM(CE34:CK34) -> 909354 | CN34: 0.655 | CO34: =CC34 -> 1980 | CP34: =(CD34-BH34)/BH34 -> 0.0027125582 | CQ34: =(CK34-BG34)/BG34 -> 0.0058587619 | CT34: 1980 | CU34: 312182 | CV34: 655505 | CW34: =(CU34-Q34)/Q34 -> -0.0058246367 | CX34: =(CV34-AD34)/AD34 -> -0.0535816
A35: =O35 -> Grant | B35: =K35 -> 1981 | C35: =L35 -> 435345 | D35: =M35 -> 1492293 | E35: =LN(D35/C35) -> 1.2319303 | F35: =A35 -> Grant | G35: =Q35 -> 436996 | H35: =Y35 -> 1445354.1 | I35: =LN(H35/G35) -> 1.1961856 | J35: =I35-(aa-bb*G35) -> 0.33617101 | K35: 1981 | L35: 435345 | M35: 1492293 | O35: =CB35 -> Grant | P35: =CC35 -> 1981 | Q35: =CK35 -> 436996 | R35: =CD35 -> 500271 | S35: =1-Q35/R35 -> 0.12648145 | U35: =$R38*U$2 -> 183840.9 | V35: =$R39*V$2 -> 1103426.4 | W35: =$R40*W$2 -> 158086.8 | X35: =$R41*X$2 -> 0 | Y35: =SUM(U35:X35) -> 1445354.1 | AD35: =Y35 -> 1445354.1 | AE35: =B35 -> 1981 | AF35: =U35/$Y35 -> 0.12719437 | AG35: =V35/$Y35 -> 0.76342981 | AH35: =W35/$Y35 -> 0.10937583 | AJ35: =B35 -> 1981 | AK35: =AF32*AN32+AG31*AN31+AH30*AN30 -> 496309.57 | AL35: =CHOOSE(umethod,S35,retroU,MAX(0,cslope*(AK35-nlim)/AK35)) -> 0.12648145 | AM35: =AK35*(1-AL35) -> 433535.62 | AN35: =AM35*EXP(aa-bb*AM35+J35) -> 1436967 | AO35: =AK35-AM35 -> 62773.953 | AP35: Cass | AQ35: 1981 | AR35: 435345 | AS35: =BE35 -> 56270 | AT35: =AS35/(AR35+AS35) -> 0.11445949 | AU35: =AR35+AS35 -> 491615 | AV35: =(AU35-CD35)/CD35 -> -0.017302622 | AW35: Cass | AX35: 1981 | AY35: 26519 | AZ35: N/A | BA35: 3205 | BB35: 5814 | BC35: 771 | BD35: 19961 | BE35: 56270 | BF35: =BE35/BH35 -> 0.11445949 | BG35: 435345 | BH35: 491615 | BI35: =BE35/BH35 -> 0.11445949 | BJ35: =AY35/BH35 -> 0.053942618 | BK35: =BA35/(BH35-AY35) -> 0.0068910504 | BL35: =BD35/(BH35-AY35-BA35-BC35) -> 0.043288081 | BM35: =BE35/BH35 -> 0.11445949 | BN35: =BG35*BM35/(1-BM35) -> 56270 | BO35: 0.1414136 | BP35: =BJ35/(SUM($BJ35:$BL35)) -> 0.51807253 | BQ35: =BK35/(SUM($BJ35:$BL35)) -> 0.066182623 | BR35: =BL35/(SUM($BJ35:$BL35)) -> 0.41574485 | BT35: 1981 | BU35: 1302540 | BV35: 185726.45 | BW35: 0.12479381 | BX35: 1488266.4 | BZ35: =BF35 -> 0.11445949 | CB35: Grant | CC35: 1981 | CD35: 500271 | CE35: 30394 | CF35: 3370 | CG35: 2288 | CH35: 5814 | CI35: 0 | CJ35: 21408 | CK35: 436996 | CL35: =SUM(CE35:CK35) -> 500270 | CN35: 0.126 | CO35: =CC35 -> 1981 | CP35: =(CD35-BH35)/BH35 -> 0.017607274 | CQ35: =(CK35-BG35)/BG35 -> 0.0037923945 | CT35: 1981 | CU35: 435345 | CV35: 1492293 | CW35: =(CU35-Q35)/Q35 -> -0.0037780666 | CX35: =(CV35-AD35)/AD35 -> 0.03247571
